2025-05-30 13:39:13,626 INFO    MainThread:19848 [wandb_setup.py:_flush():70] Current SDK version is 0.19.11
2025-05-30 13:39:13,626 INFO    MainThread:19848 [wandb_setup.py:_flush():70] Configure stats pid to 19848
2025-05-30 13:39:13,627 INFO    MainThread:19848 [wandb_setup.py:_flush():70] Loading settings from /Users/juliankleutgens/.config/wandb/settings
2025-05-30 13:39:13,627 INFO    MainThread:19848 [wandb_setup.py:_flush():70] Loading settings from /Users/juliankleutgens/PycharmProjects/ratio_estimation_synthetic/wandb/settings
2025-05-30 13:39:13,627 INFO    MainThread:19848 [wandb_setup.py:_flush():70] Loading settings from environment variables
2025-05-30 13:39:13,627 INFO    MainThread:19848 [wandb_init.py:setup_run_log_directory():724] Logging user logs to /Users/juliankleutgens/PycharmProjects/ratio_estimation_synthetic/wandb/run-20250530_133913-6t2tuv36/logs/debug.log
2025-05-30 13:39:13,627 INFO    MainThread:19848 [wandb_init.py:setup_run_log_directory():725] Logging internal logs to /Users/juliankleutgens/PycharmProjects/ratio_estimation_synthetic/wandb/run-20250530_133913-6t2tuv36/logs/debug-internal.log
2025-05-30 13:39:13,627 INFO    MainThread:19848 [wandb_init.py:init():852] calling init triggers
2025-05-30 13:39:13,627 INFO    MainThread:19848 [wandb_init.py:init():857] wandb.init called with sweep_config: {}
config: {'data_type': 'point_forms', 'unguided_sampling': False, 'skip_ratio_estimator_on_clean_data': True, 'test_run': False, 'seed': 100, 'len_seqs': 10, 'vocab_size': 5, 'number_of_source_samples': 10000, 'number_of_target_samples': 1000, 'dimension_gaussian': 2, 'num_mixtures': 2, 'grid_size': 1.5, 'quantization_step': 0.01, 'source_form': '2spirals', 'target_form': 'swissroll', 'source_dist': 'uniform', 'target_dist': 'gaussian', 'distance': 0, 'grid_size_discrete': 10, 'type_of_T_matrix': 'diagonal', 'extra_target_tokens': 1, 'dirichlet_alpha': 4.0, 'batch_size': 256, 'device': device(type='mps'), 'train_classifier_epochs': 30, 'train_ratio_estimator_epochs': 30, 'train_denoiser_epochs': 40, 'denoiser_dim': 256, 'denoiser_heads': 4, 'denoiser_layers': 4, 'sample_batch_size': 1024, 'sample_gammas': [0, 0.5, 1, 2], 'sample_size': 16384, 'denoising_steps': 100, 'use_plg': True, 'eta': 1.0, 'stochastic_sampling_jitter_mask': 0.3, 'stochastic_sampling_eps_noise': 0.0, '_wandb': {}}
2025-05-30 13:39:13,627 INFO    MainThread:19848 [wandb_init.py:init():893] starting backend
2025-05-30 13:39:13,627 INFO    MainThread:19848 [wandb_init.py:init():897] sending inform_init request
2025-05-30 13:39:13,662 INFO    MainThread:19848 [backend.py:_multiprocessing_setup():101] multiprocessing start_methods=spawn,fork,forkserver, using: spawn
2025-05-30 13:39:13,662 INFO    MainThread:19848 [wandb_init.py:init():907] backend started and connected
2025-05-30 13:39:13,666 INFO    MainThread:19848 [wandb_init.py:init():1005] updated telemetry
2025-05-30 13:39:13,667 INFO    MainThread:19848 [wandb_init.py:init():1029] communicating run to backend with 90.0 second timeout
2025-05-30 13:39:14,059 INFO    MainThread:19848 [wandb_init.py:init():1104] starting run threads in backend
2025-05-30 13:39:14,155 INFO    MainThread:19848 [wandb_run.py:_console_start():2573] atexit reg
2025-05-30 13:39:14,156 INFO    MainThread:19848 [wandb_run.py:_redirect():2421] redirect: wrap_raw
2025-05-30 13:39:14,156 INFO    MainThread:19848 [wandb_run.py:_redirect():2490] Wrapping output streams.
2025-05-30 13:39:14,156 INFO    MainThread:19848 [wandb_run.py:_redirect():2513] Redirects installed.
2025-05-30 13:39:14,159 INFO    MainThread:19848 [wandb_init.py:init():1150] run started, returning control to user process
2025-05-30 13:39:14,159 INFO    MainThread:19848 [wandb_run.py:_config_callback():1436] config_cb None None {'data_type': 'point_forms', 'unguided_sampling': False, 'skip_ratio_estimator_on_clean_data': True, 'test_run': False, 'seed': 100, 'len_seqs': 10, 'vocab_size': 5, 'number_of_source_samples': 10000, 'number_of_target_samples': 1000, 'dimension_gaussian': 2, 'num_mixtures': 2, 'grid_size': 1.5, 'quantization_step': 0.01, 'source_form': '2spirals', 'target_form': 'swissroll', 'source_dist': 'uniform', 'target_dist': 'gaussian', 'distance': 0, 'grid_size_discrete': 10, 'type_of_T_matrix': 'diagonal', 'extra_target_tokens': 1, 'dirichlet_alpha': 4.0, 'batch_size': 256, 'device': 'mps', 'train_classifier_epochs': 30, 'train_ratio_estimator_epochs': 30, 'train_denoiser_epochs': 40, 'denoiser_dim': 256, 'denoiser_heads': 4, 'denoiser_layers': 4, 'sample_batch_size': 1024, 'sample_gammas': [0, 0.5, 1, 2], 'sample_size': 16384, 'denoising_steps': 100, 'use_plg': True, 'eta': 1.0, 'stochastic_sampling_jitter_mask': 0.3, 'stochastic_sampling_eps_noise': 0.0}
2025-05-30 13:40:23,725 WARNING MsgRouterThr:19848 [router.py:message_loop():63] [no run ID] message_loop has been closed
Traceback (most recent call last):
  File "/Users/juliankleutgens/opt/anaconda3/envs/tgdp/lib/python3.9/site-packages/wandb/sdk/interface/router_sock.py", line 27, in _read_message
    return self._sock_client.read_server_response(timeout=1)
  File "/Users/juliankleutgens/opt/anaconda3/envs/tgdp/lib/python3.9/site-packages/wandb/sdk/lib/sock_client.py", line 235, in read_server_response
    data = self._read_packet_bytes(timeout=timeout)
  File "/Users/juliankleutgens/opt/anaconda3/envs/tgdp/lib/python3.9/site-packages/wandb/sdk/lib/sock_client.py", line 220, in _read_packet_bytes
    raise SockClientClosedError
wandb.sdk.lib.sock_client.SockClientClosedError

The above exception was the direct cause of the following exception:

Traceback (most recent call last):
  File "/Users/juliankleutgens/opt/anaconda3/envs/tgdp/lib/python3.9/site-packages/wandb/sdk/interface/router.py", line 56, in message_loop
    msg = self._read_message()
  File "/Users/juliankleutgens/opt/anaconda3/envs/tgdp/lib/python3.9/site-packages/wandb/sdk/interface/router_sock.py", line 29, in _read_message
    raise MessageRouterClosedError from e
wandb.sdk.interface.router.MessageRouterClosedError
2025-05-30 13:40:23,726 INFO    MsgRouterThr:19848 [mailbox.py:close():129] [no run ID] Closing mailbox, abandoning 1 handles.
2025-05-30 13:40:23,726 ERROR   MainThread:19848 [redirect.py:_on_write():664] [no run ID] error in stderr callback
Traceback (most recent call last):
  File "/Users/juliankleutgens/PycharmProjects/ratio_estimation_synthetic/main2.py", line 577, in <module>
    main()
  File "/Users/juliankleutgens/PycharmProjects/ratio_estimation_synthetic/main2.py", line 283, in main
    denoiser_source = train_denoiser(
  File "/Users/juliankleutgens/PycharmProjects/ratio_estimation_synthetic/training.py", line 334, in train_denoiser
    x_t, move_mask_t = corrupt(x0=x0, sigma=sigma_t,
  File "/Users/juliankleutgens/PycharmProjects/ratio_estimation_synthetic/training.py", line 75, in corrupt
    x_t[move_mask] = mask_idx
KeyboardInterrupt

During handling of the above exception, another exception occurred:

Traceback (most recent call last):
  File "/Users/juliankleutgens/opt/anaconda3/envs/tgdp/lib/python3.9/site-packages/wandb/sdk/lib/redirect.py", line 662, in _on_write
    cb(written_data)
  File "/Users/juliankleutgens/opt/anaconda3/envs/tgdp/lib/python3.9/site-packages/wandb/sdk/wandb_run.py", line 2500, in <lambda>
    lambda data: self._console_raw_callback("stderr", data),
  File "/Users/juliankleutgens/opt/anaconda3/envs/tgdp/lib/python3.9/site-packages/wandb/sdk/wandb_run.py", line 406, in wrapper
    return func(self, *args, **kwargs)
  File "/Users/juliankleutgens/opt/anaconda3/envs/tgdp/lib/python3.9/site-packages/wandb/sdk/wandb_run.py", line 464, in wrapper_fn
    return func(self, *args, **kwargs)
  File "/Users/juliankleutgens/opt/anaconda3/envs/tgdp/lib/python3.9/site-packages/wandb/sdk/wandb_run.py", line 1639, in _console_raw_callback
    self._backend.interface.publish_output_raw(name, data)
  File "/Users/juliankleutgens/opt/anaconda3/envs/tgdp/lib/python3.9/site-packages/wandb/sdk/interface/interface.py", line 762, in publish_output_raw
    self._publish_output_raw(o)
  File "/Users/juliankleutgens/opt/anaconda3/envs/tgdp/lib/python3.9/site-packages/wandb/sdk/interface/interface_shared.py", line 38, in _publish_output_raw
    self._publish(rec)
  File "/Users/juliankleutgens/opt/anaconda3/envs/tgdp/lib/python3.9/site-packages/wandb/sdk/interface/interface_sock.py", line 39, in _publish
    self._sock_client.send_record_publish(record)
  File "/Users/juliankleutgens/opt/anaconda3/envs/tgdp/lib/python3.9/site-packages/wandb/sdk/lib/sock_client.py", line 174, in send_record_publish
    self.send_server_request(server_req)
  File "/Users/juliankleutgens/opt/anaconda3/envs/tgdp/lib/python3.9/site-packages/wandb/sdk/lib/sock_client.py", line 154, in send_server_request
    self._send_message(msg)
  File "/Users/juliankleutgens/opt/anaconda3/envs/tgdp/lib/python3.9/site-packages/wandb/sdk/lib/sock_client.py", line 151, in _send_message
    self._sendall_with_error_handle(header + data)
  File "/Users/juliankleutgens/opt/anaconda3/envs/tgdp/lib/python3.9/site-packages/wandb/sdk/lib/sock_client.py", line 130, in _sendall_with_error_handle
    sent = self._sock.send(data)
BrokenPipeError: [Errno 32] Broken pipe
2025-05-30 13:40:23,729 ERROR   MainThread:19848 [redirect.py:_on_write():664] [no run ID] error in stderr callback
Traceback (most recent call last):
  File "/Users/juliankleutgens/PycharmProjects/ratio_estimation_synthetic/main2.py", line 577, in <module>
    main()
  File "/Users/juliankleutgens/PycharmProjects/ratio_estimation_synthetic/main2.py", line 283, in main
    denoiser_source = train_denoiser(
  File "/Users/juliankleutgens/PycharmProjects/ratio_estimation_synthetic/training.py", line 334, in train_denoiser
    x_t, move_mask_t = corrupt(x0=x0, sigma=sigma_t,
  File "/Users/juliankleutgens/PycharmProjects/ratio_estimation_synthetic/training.py", line 75, in corrupt
    x_t[move_mask] = mask_idx
KeyboardInterrupt

During handling of the above exception, another exception occurred:

Traceback (most recent call last):
  File "/Users/juliankleutgens/opt/anaconda3/envs/tgdp/lib/python3.9/site-packages/wandb/sdk/lib/redirect.py", line 662, in _on_write
    cb(written_data)
  File "/Users/juliankleutgens/opt/anaconda3/envs/tgdp/lib/python3.9/site-packages/wandb/sdk/wandb_run.py", line 2500, in <lambda>
    lambda data: self._console_raw_callback("stderr", data),
  File "/Users/juliankleutgens/opt/anaconda3/envs/tgdp/lib/python3.9/site-packages/wandb/sdk/wandb_run.py", line 406, in wrapper
    return func(self, *args, **kwargs)
  File "/Users/juliankleutgens/opt/anaconda3/envs/tgdp/lib/python3.9/site-packages/wandb/sdk/wandb_run.py", line 464, in wrapper_fn
    return func(self, *args, **kwargs)
  File "/Users/juliankleutgens/opt/anaconda3/envs/tgdp/lib/python3.9/site-packages/wandb/sdk/wandb_run.py", line 1639, in _console_raw_callback
    self._backend.interface.publish_output_raw(name, data)
  File "/Users/juliankleutgens/opt/anaconda3/envs/tgdp/lib/python3.9/site-packages/wandb/sdk/interface/interface.py", line 762, in publish_output_raw
    self._publish_output_raw(o)
  File "/Users/juliankleutgens/opt/anaconda3/envs/tgdp/lib/python3.9/site-packages/wandb/sdk/interface/interface_shared.py", line 38, in _publish_output_raw
    self._publish(rec)
  File "/Users/juliankleutgens/opt/anaconda3/envs/tgdp/lib/python3.9/site-packages/wandb/sdk/interface/interface_sock.py", line 39, in _publish
    self._sock_client.send_record_publish(record)
  File "/Users/juliankleutgens/opt/anaconda3/envs/tgdp/lib/python3.9/site-packages/wandb/sdk/lib/sock_client.py", line 174, in send_record_publish
    self.send_server_request(server_req)
  File "/Users/juliankleutgens/opt/anaconda3/envs/tgdp/lib/python3.9/site-packages/wandb/sdk/lib/sock_client.py", line 154, in send_server_request
    self._send_message(msg)
  File "/Users/juliankleutgens/opt/anaconda3/envs/tgdp/lib/python3.9/site-packages/wandb/sdk/lib/sock_client.py", line 151, in _send_message
    self._sendall_with_error_handle(header + data)
  File "/Users/juliankleutgens/opt/anaconda3/envs/tgdp/lib/python3.9/site-packages/wandb/sdk/lib/sock_client.py", line 130, in _sendall_with_error_handle
    sent = self._sock.send(data)
BrokenPipeError: [Errno 32] Broken pipe
2025-05-30 13:40:23,729 ERROR   MainThread:19848 [redirect.py:_on_write():664] [no run ID] error in stderr callback
Traceback (most recent call last):
  File "/Users/juliankleutgens/PycharmProjects/ratio_estimation_synthetic/main2.py", line 577, in <module>
    main()
  File "/Users/juliankleutgens/PycharmProjects/ratio_estimation_synthetic/main2.py", line 283, in main
    denoiser_source = train_denoiser(
  File "/Users/juliankleutgens/PycharmProjects/ratio_estimation_synthetic/training.py", line 334, in train_denoiser
    x_t, move_mask_t = corrupt(x0=x0, sigma=sigma_t,
  File "/Users/juliankleutgens/PycharmProjects/ratio_estimation_synthetic/training.py", line 75, in corrupt
    x_t[move_mask] = mask_idx
KeyboardInterrupt

During handling of the above exception, another exception occurred:

Traceback (most recent call last):
  File "/Users/juliankleutgens/opt/anaconda3/envs/tgdp/lib/python3.9/site-packages/wandb/sdk/lib/redirect.py", line 662, in _on_write
    cb(written_data)
  File "/Users/juliankleutgens/opt/anaconda3/envs/tgdp/lib/python3.9/site-packages/wandb/sdk/wandb_run.py", line 2500, in <lambda>
    lambda data: self._console_raw_callback("stderr", data),
  File "/Users/juliankleutgens/opt/anaconda3/envs/tgdp/lib/python3.9/site-packages/wandb/sdk/wandb_run.py", line 406, in wrapper
    return func(self, *args, **kwargs)
  File "/Users/juliankleutgens/opt/anaconda3/envs/tgdp/lib/python3.9/site-packages/wandb/sdk/wandb_run.py", line 464, in wrapper_fn
    return func(self, *args, **kwargs)
  File "/Users/juliankleutgens/opt/anaconda3/envs/tgdp/lib/python3.9/site-packages/wandb/sdk/wandb_run.py", line 1639, in _console_raw_callback
    self._backend.interface.publish_output_raw(name, data)
  File "/Users/juliankleutgens/opt/anaconda3/envs/tgdp/lib/python3.9/site-packages/wandb/sdk/interface/interface.py", line 762, in publish_output_raw
    self._publish_output_raw(o)
  File "/Users/juliankleutgens/opt/anaconda3/envs/tgdp/lib/python3.9/site-packages/wandb/sdk/interface/interface_shared.py", line 38, in _publish_output_raw
    self._publish(rec)
  File "/Users/juliankleutgens/opt/anaconda3/envs/tgdp/lib/python3.9/site-packages/wandb/sdk/interface/interface_sock.py", line 39, in _publish
    self._sock_client.send_record_publish(record)
  File "/Users/juliankleutgens/opt/anaconda3/envs/tgdp/lib/python3.9/site-packages/wandb/sdk/lib/sock_client.py", line 174, in send_record_publish
    self.send_server_request(server_req)
  File "/Users/juliankleutgens/opt/anaconda3/envs/tgdp/lib/python3.9/site-packages/wandb/sdk/lib/sock_client.py", line 154, in send_server_request
    self._send_message(msg)
  File "/Users/juliankleutgens/opt/anaconda3/envs/tgdp/lib/python3.9/site-packages/wandb/sdk/lib/sock_client.py", line 151, in _send_message
    self._sendall_with_error_handle(header + data)
  File "/Users/juliankleutgens/opt/anaconda3/envs/tgdp/lib/python3.9/site-packages/wandb/sdk/lib/sock_client.py", line 130, in _sendall_with_error_handle
    sent = self._sock.send(data)
BrokenPipeError: [Errno 32] Broken pipe
2025-05-30 13:40:23,730 ERROR   MainThread:19848 [redirect.py:_on_write():664] [no run ID] error in stderr callback
Traceback (most recent call last):
  File "/Users/juliankleutgens/PycharmProjects/ratio_estimation_synthetic/main2.py", line 577, in <module>
    main()
  File "/Users/juliankleutgens/PycharmProjects/ratio_estimation_synthetic/main2.py", line 283, in main
    denoiser_source = train_denoiser(
  File "/Users/juliankleutgens/PycharmProjects/ratio_estimation_synthetic/training.py", line 334, in train_denoiser
    x_t, move_mask_t = corrupt(x0=x0, sigma=sigma_t,
  File "/Users/juliankleutgens/PycharmProjects/ratio_estimation_synthetic/training.py", line 75, in corrupt
    x_t[move_mask] = mask_idx
KeyboardInterrupt

During handling of the above exception, another exception occurred:

Traceback (most recent call last):
  File "/Users/juliankleutgens/opt/anaconda3/envs/tgdp/lib/python3.9/site-packages/wandb/sdk/lib/redirect.py", line 662, in _on_write
    cb(written_data)
  File "/Users/juliankleutgens/opt/anaconda3/envs/tgdp/lib/python3.9/site-packages/wandb/sdk/wandb_run.py", line 2500, in <lambda>
    lambda data: self._console_raw_callback("stderr", data),
  File "/Users/juliankleutgens/opt/anaconda3/envs/tgdp/lib/python3.9/site-packages/wandb/sdk/wandb_run.py", line 406, in wrapper
    return func(self, *args, **kwargs)
  File "/Users/juliankleutgens/opt/anaconda3/envs/tgdp/lib/python3.9/site-packages/wandb/sdk/wandb_run.py", line 464, in wrapper_fn
    return func(self, *args, **kwargs)
  File "/Users/juliankleutgens/opt/anaconda3/envs/tgdp/lib/python3.9/site-packages/wandb/sdk/wandb_run.py", line 1639, in _console_raw_callback
    self._backend.interface.publish_output_raw(name, data)
  File "/Users/juliankleutgens/opt/anaconda3/envs/tgdp/lib/python3.9/site-packages/wandb/sdk/interface/interface.py", line 762, in publish_output_raw
    self._publish_output_raw(o)
  File "/Users/juliankleutgens/opt/anaconda3/envs/tgdp/lib/python3.9/site-packages/wandb/sdk/interface/interface_shared.py", line 38, in _publish_output_raw
    self._publish(rec)
  File "/Users/juliankleutgens/opt/anaconda3/envs/tgdp/lib/python3.9/site-packages/wandb/sdk/interface/interface_sock.py", line 39, in _publish
    self._sock_client.send_record_publish(record)
  File "/Users/juliankleutgens/opt/anaconda3/envs/tgdp/lib/python3.9/site-packages/wandb/sdk/lib/sock_client.py", line 174, in send_record_publish
    self.send_server_request(server_req)
  File "/Users/juliankleutgens/opt/anaconda3/envs/tgdp/lib/python3.9/site-packages/wandb/sdk/lib/sock_client.py", line 154, in send_server_request
    self._send_message(msg)
  File "/Users/juliankleutgens/opt/anaconda3/envs/tgdp/lib/python3.9/site-packages/wandb/sdk/lib/sock_client.py", line 151, in _send_message
    self._sendall_with_error_handle(header + data)
  File "/Users/juliankleutgens/opt/anaconda3/envs/tgdp/lib/python3.9/site-packages/wandb/sdk/lib/sock_client.py", line 130, in _sendall_with_error_handle
    sent = self._sock.send(data)
BrokenPipeError: [Errno 32] Broken pipe
2025-05-30 13:40:23,730 ERROR   MainThread:19848 [redirect.py:_on_write():664] [no run ID] error in stderr callback
Traceback (most recent call last):
  File "/Users/juliankleutgens/PycharmProjects/ratio_estimation_synthetic/main2.py", line 577, in <module>
    main()
  File "/Users/juliankleutgens/PycharmProjects/ratio_estimation_synthetic/main2.py", line 283, in main
    denoiser_source = train_denoiser(
  File "/Users/juliankleutgens/PycharmProjects/ratio_estimation_synthetic/training.py", line 334, in train_denoiser
    x_t, move_mask_t = corrupt(x0=x0, sigma=sigma_t,
  File "/Users/juliankleutgens/PycharmProjects/ratio_estimation_synthetic/training.py", line 75, in corrupt
    x_t[move_mask] = mask_idx
KeyboardInterrupt

During handling of the above exception, another exception occurred:

Traceback (most recent call last):
  File "/Users/juliankleutgens/opt/anaconda3/envs/tgdp/lib/python3.9/site-packages/wandb/sdk/lib/redirect.py", line 662, in _on_write
    cb(written_data)
  File "/Users/juliankleutgens/opt/anaconda3/envs/tgdp/lib/python3.9/site-packages/wandb/sdk/wandb_run.py", line 2500, in <lambda>
    lambda data: self._console_raw_callback("stderr", data),
  File "/Users/juliankleutgens/opt/anaconda3/envs/tgdp/lib/python3.9/site-packages/wandb/sdk/wandb_run.py", line 406, in wrapper
    return func(self, *args, **kwargs)
  File "/Users/juliankleutgens/opt/anaconda3/envs/tgdp/lib/python3.9/site-packages/wandb/sdk/wandb_run.py", line 464, in wrapper_fn
    return func(self, *args, **kwargs)
  File "/Users/juliankleutgens/opt/anaconda3/envs/tgdp/lib/python3.9/site-packages/wandb/sdk/wandb_run.py", line 1639, in _console_raw_callback
    self._backend.interface.publish_output_raw(name, data)
  File "/Users/juliankleutgens/opt/anaconda3/envs/tgdp/lib/python3.9/site-packages/wandb/sdk/interface/interface.py", line 762, in publish_output_raw
    self._publish_output_raw(o)
  File "/Users/juliankleutgens/opt/anaconda3/envs/tgdp/lib/python3.9/site-packages/wandb/sdk/interface/interface_shared.py", line 38, in _publish_output_raw
    self._publish(rec)
  File "/Users/juliankleutgens/opt/anaconda3/envs/tgdp/lib/python3.9/site-packages/wandb/sdk/interface/interface_sock.py", line 39, in _publish
    self._sock_client.send_record_publish(record)
  File "/Users/juliankleutgens/opt/anaconda3/envs/tgdp/lib/python3.9/site-packages/wandb/sdk/lib/sock_client.py", line 174, in send_record_publish
    self.send_server_request(server_req)
  File "/Users/juliankleutgens/opt/anaconda3/envs/tgdp/lib/python3.9/site-packages/wandb/sdk/lib/sock_client.py", line 154, in send_server_request
    self._send_message(msg)
  File "/Users/juliankleutgens/opt/anaconda3/envs/tgdp/lib/python3.9/site-packages/wandb/sdk/lib/sock_client.py", line 151, in _send_message
    self._sendall_with_error_handle(header + data)
  File "/Users/juliankleutgens/opt/anaconda3/envs/tgdp/lib/python3.9/site-packages/wandb/sdk/lib/sock_client.py", line 130, in _sendall_with_error_handle
    sent = self._sock.send(data)
BrokenPipeError: [Errno 32] Broken pipe
2025-05-30 13:40:23,730 ERROR   MainThread:19848 [redirect.py:_on_write():664] [no run ID] error in stderr callback
Traceback (most recent call last):
  File "/Users/juliankleutgens/PycharmProjects/ratio_estimation_synthetic/main2.py", line 577, in <module>
    main()
  File "/Users/juliankleutgens/PycharmProjects/ratio_estimation_synthetic/main2.py", line 283, in main
    denoiser_source = train_denoiser(
  File "/Users/juliankleutgens/PycharmProjects/ratio_estimation_synthetic/training.py", line 334, in train_denoiser
    x_t, move_mask_t = corrupt(x0=x0, sigma=sigma_t,
  File "/Users/juliankleutgens/PycharmProjects/ratio_estimation_synthetic/training.py", line 75, in corrupt
    x_t[move_mask] = mask_idx
KeyboardInterrupt

During handling of the above exception, another exception occurred:

Traceback (most recent call last):
  File "/Users/juliankleutgens/opt/anaconda3/envs/tgdp/lib/python3.9/site-packages/wandb/sdk/lib/redirect.py", line 662, in _on_write
    cb(written_data)
  File "/Users/juliankleutgens/opt/anaconda3/envs/tgdp/lib/python3.9/site-packages/wandb/sdk/wandb_run.py", line 2500, in <lambda>
    lambda data: self._console_raw_callback("stderr", data),
  File "/Users/juliankleutgens/opt/anaconda3/envs/tgdp/lib/python3.9/site-packages/wandb/sdk/wandb_run.py", line 406, in wrapper
    return func(self, *args, **kwargs)
  File "/Users/juliankleutgens/opt/anaconda3/envs/tgdp/lib/python3.9/site-packages/wandb/sdk/wandb_run.py", line 464, in wrapper_fn
    return func(self, *args, **kwargs)
  File "/Users/juliankleutgens/opt/anaconda3/envs/tgdp/lib/python3.9/site-packages/wandb/sdk/wandb_run.py", line 1639, in _console_raw_callback
    self._backend.interface.publish_output_raw(name, data)
  File "/Users/juliankleutgens/opt/anaconda3/envs/tgdp/lib/python3.9/site-packages/wandb/sdk/interface/interface.py", line 762, in publish_output_raw
    self._publish_output_raw(o)
  File "/Users/juliankleutgens/opt/anaconda3/envs/tgdp/lib/python3.9/site-packages/wandb/sdk/interface/interface_shared.py", line 38, in _publish_output_raw
    self._publish(rec)
  File "/Users/juliankleutgens/opt/anaconda3/envs/tgdp/lib/python3.9/site-packages/wandb/sdk/interface/interface_sock.py", line 39, in _publish
    self._sock_client.send_record_publish(record)
  File "/Users/juliankleutgens/opt/anaconda3/envs/tgdp/lib/python3.9/site-packages/wandb/sdk/lib/sock_client.py", line 174, in send_record_publish
    self.send_server_request(server_req)
  File "/Users/juliankleutgens/opt/anaconda3/envs/tgdp/lib/python3.9/site-packages/wandb/sdk/lib/sock_client.py", line 154, in send_server_request
    self._send_message(msg)
  File "/Users/juliankleutgens/opt/anaconda3/envs/tgdp/lib/python3.9/site-packages/wandb/sdk/lib/sock_client.py", line 151, in _send_message
    self._sendall_with_error_handle(header + data)
  File "/Users/juliankleutgens/opt/anaconda3/envs/tgdp/lib/python3.9/site-packages/wandb/sdk/lib/sock_client.py", line 130, in _sendall_with_error_handle
    sent = self._sock.send(data)
BrokenPipeError: [Errno 32] Broken pipe
2025-05-30 13:40:23,730 ERROR   MainThread:19848 [redirect.py:_on_write():664] [no run ID] error in stderr callback
Traceback (most recent call last):
  File "/Users/juliankleutgens/PycharmProjects/ratio_estimation_synthetic/main2.py", line 577, in <module>
    main()
  File "/Users/juliankleutgens/PycharmProjects/ratio_estimation_synthetic/main2.py", line 283, in main
    denoiser_source = train_denoiser(
  File "/Users/juliankleutgens/PycharmProjects/ratio_estimation_synthetic/training.py", line 334, in train_denoiser
    x_t, move_mask_t = corrupt(x0=x0, sigma=sigma_t,
  File "/Users/juliankleutgens/PycharmProjects/ratio_estimation_synthetic/training.py", line 75, in corrupt
    x_t[move_mask] = mask_idx
KeyboardInterrupt

During handling of the above exception, another exception occurred:

Traceback (most recent call last):
  File "/Users/juliankleutgens/opt/anaconda3/envs/tgdp/lib/python3.9/site-packages/wandb/sdk/lib/redirect.py", line 662, in _on_write
    cb(written_data)
  File "/Users/juliankleutgens/opt/anaconda3/envs/tgdp/lib/python3.9/site-packages/wandb/sdk/wandb_run.py", line 2500, in <lambda>
    lambda data: self._console_raw_callback("stderr", data),
  File "/Users/juliankleutgens/opt/anaconda3/envs/tgdp/lib/python3.9/site-packages/wandb/sdk/wandb_run.py", line 406, in wrapper
    return func(self, *args, **kwargs)
  File "/Users/juliankleutgens/opt/anaconda3/envs/tgdp/lib/python3.9/site-packages/wandb/sdk/wandb_run.py", line 464, in wrapper_fn
    return func(self, *args, **kwargs)
  File "/Users/juliankleutgens/opt/anaconda3/envs/tgdp/lib/python3.9/site-packages/wandb/sdk/wandb_run.py", line 1639, in _console_raw_callback
    self._backend.interface.publish_output_raw(name, data)
  File "/Users/juliankleutgens/opt/anaconda3/envs/tgdp/lib/python3.9/site-packages/wandb/sdk/interface/interface.py", line 762, in publish_output_raw
    self._publish_output_raw(o)
  File "/Users/juliankleutgens/opt/anaconda3/envs/tgdp/lib/python3.9/site-packages/wandb/sdk/interface/interface_shared.py", line 38, in _publish_output_raw
    self._publish(rec)
  File "/Users/juliankleutgens/opt/anaconda3/envs/tgdp/lib/python3.9/site-packages/wandb/sdk/interface/interface_sock.py", line 39, in _publish
    self._sock_client.send_record_publish(record)
  File "/Users/juliankleutgens/opt/anaconda3/envs/tgdp/lib/python3.9/site-packages/wandb/sdk/lib/sock_client.py", line 174, in send_record_publish
    self.send_server_request(server_req)
  File "/Users/juliankleutgens/opt/anaconda3/envs/tgdp/lib/python3.9/site-packages/wandb/sdk/lib/sock_client.py", line 154, in send_server_request
    self._send_message(msg)
  File "/Users/juliankleutgens/opt/anaconda3/envs/tgdp/lib/python3.9/site-packages/wandb/sdk/lib/sock_client.py", line 151, in _send_message
    self._sendall_with_error_handle(header + data)
  File "/Users/juliankleutgens/opt/anaconda3/envs/tgdp/lib/python3.9/site-packages/wandb/sdk/lib/sock_client.py", line 130, in _sendall_with_error_handle
    sent = self._sock.send(data)
BrokenPipeError: [Errno 32] Broken pipe
2025-05-30 13:40:23,730 ERROR   MainThread:19848 [redirect.py:_on_write():664] [no run ID] error in stderr callback
Traceback (most recent call last):
  File "/Users/juliankleutgens/PycharmProjects/ratio_estimation_synthetic/main2.py", line 577, in <module>
    main()
  File "/Users/juliankleutgens/PycharmProjects/ratio_estimation_synthetic/main2.py", line 283, in main
    denoiser_source = train_denoiser(
  File "/Users/juliankleutgens/PycharmProjects/ratio_estimation_synthetic/training.py", line 334, in train_denoiser
    x_t, move_mask_t = corrupt(x0=x0, sigma=sigma_t,
  File "/Users/juliankleutgens/PycharmProjects/ratio_estimation_synthetic/training.py", line 75, in corrupt
    x_t[move_mask] = mask_idx
KeyboardInterrupt

During handling of the above exception, another exception occurred:

Traceback (most recent call last):
  File "/Users/juliankleutgens/opt/anaconda3/envs/tgdp/lib/python3.9/site-packages/wandb/sdk/lib/redirect.py", line 662, in _on_write
    cb(written_data)
  File "/Users/juliankleutgens/opt/anaconda3/envs/tgdp/lib/python3.9/site-packages/wandb/sdk/wandb_run.py", line 2500, in <lambda>
    lambda data: self._console_raw_callback("stderr", data),
  File "/Users/juliankleutgens/opt/anaconda3/envs/tgdp/lib/python3.9/site-packages/wandb/sdk/wandb_run.py", line 406, in wrapper
    return func(self, *args, **kwargs)
  File "/Users/juliankleutgens/opt/anaconda3/envs/tgdp/lib/python3.9/site-packages/wandb/sdk/wandb_run.py", line 464, in wrapper_fn
    return func(self, *args, **kwargs)
  File "/Users/juliankleutgens/opt/anaconda3/envs/tgdp/lib/python3.9/site-packages/wandb/sdk/wandb_run.py", line 1639, in _console_raw_callback
    self._backend.interface.publish_output_raw(name, data)
  File "/Users/juliankleutgens/opt/anaconda3/envs/tgdp/lib/python3.9/site-packages/wandb/sdk/interface/interface.py", line 762, in publish_output_raw
    self._publish_output_raw(o)
  File "/Users/juliankleutgens/opt/anaconda3/envs/tgdp/lib/python3.9/site-packages/wandb/sdk/interface/interface_shared.py", line 38, in _publish_output_raw
    self._publish(rec)
  File "/Users/juliankleutgens/opt/anaconda3/envs/tgdp/lib/python3.9/site-packages/wandb/sdk/interface/interface_sock.py", line 39, in _publish
    self._sock_client.send_record_publish(record)
  File "/Users/juliankleutgens/opt/anaconda3/envs/tgdp/lib/python3.9/site-packages/wandb/sdk/lib/sock_client.py", line 174, in send_record_publish
    self.send_server_request(server_req)
  File "/Users/juliankleutgens/opt/anaconda3/envs/tgdp/lib/python3.9/site-packages/wandb/sdk/lib/sock_client.py", line 154, in send_server_request
    self._send_message(msg)
  File "/Users/juliankleutgens/opt/anaconda3/envs/tgdp/lib/python3.9/site-packages/wandb/sdk/lib/sock_client.py", line 151, in _send_message
    self._sendall_with_error_handle(header + data)
  File "/Users/juliankleutgens/opt/anaconda3/envs/tgdp/lib/python3.9/site-packages/wandb/sdk/lib/sock_client.py", line 130, in _sendall_with_error_handle
    sent = self._sock.send(data)
BrokenPipeError: [Errno 32] Broken pipe
2025-05-30 13:40:23,731 ERROR   MainThread:19848 [redirect.py:_on_write():664] [no run ID] error in stderr callback
Traceback (most recent call last):
  File "/Users/juliankleutgens/PycharmProjects/ratio_estimation_synthetic/main2.py", line 577, in <module>
    main()
  File "/Users/juliankleutgens/PycharmProjects/ratio_estimation_synthetic/main2.py", line 283, in main
    denoiser_source = train_denoiser(
  File "/Users/juliankleutgens/PycharmProjects/ratio_estimation_synthetic/training.py", line 334, in train_denoiser
    x_t, move_mask_t = corrupt(x0=x0, sigma=sigma_t,
  File "/Users/juliankleutgens/PycharmProjects/ratio_estimation_synthetic/training.py", line 75, in corrupt
    x_t[move_mask] = mask_idx
KeyboardInterrupt

During handling of the above exception, another exception occurred:

Traceback (most recent call last):
  File "/Users/juliankleutgens/opt/anaconda3/envs/tgdp/lib/python3.9/site-packages/wandb/sdk/lib/redirect.py", line 662, in _on_write
    cb(written_data)
  File "/Users/juliankleutgens/opt/anaconda3/envs/tgdp/lib/python3.9/site-packages/wandb/sdk/wandb_run.py", line 2500, in <lambda>
    lambda data: self._console_raw_callback("stderr", data),
  File "/Users/juliankleutgens/opt/anaconda3/envs/tgdp/lib/python3.9/site-packages/wandb/sdk/wandb_run.py", line 406, in wrapper
    return func(self, *args, **kwargs)
  File "/Users/juliankleutgens/opt/anaconda3/envs/tgdp/lib/python3.9/site-packages/wandb/sdk/wandb_run.py", line 464, in wrapper_fn
    return func(self, *args, **kwargs)
  File "/Users/juliankleutgens/opt/anaconda3/envs/tgdp/lib/python3.9/site-packages/wandb/sdk/wandb_run.py", line 1639, in _console_raw_callback
    self._backend.interface.publish_output_raw(name, data)
  File "/Users/juliankleutgens/opt/anaconda3/envs/tgdp/lib/python3.9/site-packages/wandb/sdk/interface/interface.py", line 762, in publish_output_raw
    self._publish_output_raw(o)
  File "/Users/juliankleutgens/opt/anaconda3/envs/tgdp/lib/python3.9/site-packages/wandb/sdk/interface/interface_shared.py", line 38, in _publish_output_raw
    self._publish(rec)
  File "/Users/juliankleutgens/opt/anaconda3/envs/tgdp/lib/python3.9/site-packages/wandb/sdk/interface/interface_sock.py", line 39, in _publish
    self._sock_client.send_record_publish(record)
  File "/Users/juliankleutgens/opt/anaconda3/envs/tgdp/lib/python3.9/site-packages/wandb/sdk/lib/sock_client.py", line 174, in send_record_publish
    self.send_server_request(server_req)
  File "/Users/juliankleutgens/opt/anaconda3/envs/tgdp/lib/python3.9/site-packages/wandb/sdk/lib/sock_client.py", line 154, in send_server_request
    self._send_message(msg)
  File "/Users/juliankleutgens/opt/anaconda3/envs/tgdp/lib/python3.9/site-packages/wandb/sdk/lib/sock_client.py", line 151, in _send_message
    self._sendall_with_error_handle(header + data)
  File "/Users/juliankleutgens/opt/anaconda3/envs/tgdp/lib/python3.9/site-packages/wandb/sdk/lib/sock_client.py", line 130, in _sendall_with_error_handle
    sent = self._sock.send(data)
BrokenPipeError: [Errno 32] Broken pipe
2025-05-30 13:40:23,731 ERROR   MainThread:19848 [redirect.py:_on_write():664] [no run ID] error in stderr callback
Traceback (most recent call last):
  File "/Users/juliankleutgens/PycharmProjects/ratio_estimation_synthetic/main2.py", line 577, in <module>
    main()
  File "/Users/juliankleutgens/PycharmProjects/ratio_estimation_synthetic/main2.py", line 283, in main
    denoiser_source = train_denoiser(
  File "/Users/juliankleutgens/PycharmProjects/ratio_estimation_synthetic/training.py", line 334, in train_denoiser
    x_t, move_mask_t = corrupt(x0=x0, sigma=sigma_t,
  File "/Users/juliankleutgens/PycharmProjects/ratio_estimation_synthetic/training.py", line 75, in corrupt
    x_t[move_mask] = mask_idx
KeyboardInterrupt

During handling of the above exception, another exception occurred:

Traceback (most recent call last):
  File "/Users/juliankleutgens/opt/anaconda3/envs/tgdp/lib/python3.9/site-packages/wandb/sdk/lib/redirect.py", line 662, in _on_write
    cb(written_data)
  File "/Users/juliankleutgens/opt/anaconda3/envs/tgdp/lib/python3.9/site-packages/wandb/sdk/wandb_run.py", line 2500, in <lambda>
    lambda data: self._console_raw_callback("stderr", data),
  File "/Users/juliankleutgens/opt/anaconda3/envs/tgdp/lib/python3.9/site-packages/wandb/sdk/wandb_run.py", line 406, in wrapper
    return func(self, *args, **kwargs)
  File "/Users/juliankleutgens/opt/anaconda3/envs/tgdp/lib/python3.9/site-packages/wandb/sdk/wandb_run.py", line 464, in wrapper_fn
    return func(self, *args, **kwargs)
  File "/Users/juliankleutgens/opt/anaconda3/envs/tgdp/lib/python3.9/site-packages/wandb/sdk/wandb_run.py", line 1639, in _console_raw_callback
    self._backend.interface.publish_output_raw(name, data)
  File "/Users/juliankleutgens/opt/anaconda3/envs/tgdp/lib/python3.9/site-packages/wandb/sdk/interface/interface.py", line 762, in publish_output_raw
    self._publish_output_raw(o)
  File "/Users/juliankleutgens/opt/anaconda3/envs/tgdp/lib/python3.9/site-packages/wandb/sdk/interface/interface_shared.py", line 38, in _publish_output_raw
    self._publish(rec)
  File "/Users/juliankleutgens/opt/anaconda3/envs/tgdp/lib/python3.9/site-packages/wandb/sdk/interface/interface_sock.py", line 39, in _publish
    self._sock_client.send_record_publish(record)
  File "/Users/juliankleutgens/opt/anaconda3/envs/tgdp/lib/python3.9/site-packages/wandb/sdk/lib/sock_client.py", line 174, in send_record_publish
    self.send_server_request(server_req)
  File "/Users/juliankleutgens/opt/anaconda3/envs/tgdp/lib/python3.9/site-packages/wandb/sdk/lib/sock_client.py", line 154, in send_server_request
    self._send_message(msg)
  File "/Users/juliankleutgens/opt/anaconda3/envs/tgdp/lib/python3.9/site-packages/wandb/sdk/lib/sock_client.py", line 151, in _send_message
    self._sendall_with_error_handle(header + data)
  File "/Users/juliankleutgens/opt/anaconda3/envs/tgdp/lib/python3.9/site-packages/wandb/sdk/lib/sock_client.py", line 130, in _sendall_with_error_handle
    sent = self._sock.send(data)
BrokenPipeError: [Errno 32] Broken pipe
2025-05-30 13:40:23,731 ERROR   MainThread:19848 [redirect.py:_on_write():664] [no run ID] error in stderr callback
Traceback (most recent call last):
  File "/Users/juliankleutgens/PycharmProjects/ratio_estimation_synthetic/main2.py", line 577, in <module>
    main()
  File "/Users/juliankleutgens/PycharmProjects/ratio_estimation_synthetic/main2.py", line 283, in main
    denoiser_source = train_denoiser(
  File "/Users/juliankleutgens/PycharmProjects/ratio_estimation_synthetic/training.py", line 334, in train_denoiser
    x_t, move_mask_t = corrupt(x0=x0, sigma=sigma_t,
  File "/Users/juliankleutgens/PycharmProjects/ratio_estimation_synthetic/training.py", line 75, in corrupt
    x_t[move_mask] = mask_idx
KeyboardInterrupt

During handling of the above exception, another exception occurred:

Traceback (most recent call last):
  File "/Users/juliankleutgens/opt/anaconda3/envs/tgdp/lib/python3.9/site-packages/wandb/sdk/lib/redirect.py", line 662, in _on_write
    cb(written_data)
  File "/Users/juliankleutgens/opt/anaconda3/envs/tgdp/lib/python3.9/site-packages/wandb/sdk/wandb_run.py", line 2500, in <lambda>
    lambda data: self._console_raw_callback("stderr", data),
  File "/Users/juliankleutgens/opt/anaconda3/envs/tgdp/lib/python3.9/site-packages/wandb/sdk/wandb_run.py", line 406, in wrapper
    return func(self, *args, **kwargs)
  File "/Users/juliankleutgens/opt/anaconda3/envs/tgdp/lib/python3.9/site-packages/wandb/sdk/wandb_run.py", line 464, in wrapper_fn
    return func(self, *args, **kwargs)
  File "/Users/juliankleutgens/opt/anaconda3/envs/tgdp/lib/python3.9/site-packages/wandb/sdk/wandb_run.py", line 1639, in _console_raw_callback
    self._backend.interface.publish_output_raw(name, data)
  File "/Users/juliankleutgens/opt/anaconda3/envs/tgdp/lib/python3.9/site-packages/wandb/sdk/interface/interface.py", line 762, in publish_output_raw
    self._publish_output_raw(o)
  File "/Users/juliankleutgens/opt/anaconda3/envs/tgdp/lib/python3.9/site-packages/wandb/sdk/interface/interface_shared.py", line 38, in _publish_output_raw
    self._publish(rec)
  File "/Users/juliankleutgens/opt/anaconda3/envs/tgdp/lib/python3.9/site-packages/wandb/sdk/interface/interface_sock.py", line 39, in _publish
    self._sock_client.send_record_publish(record)
  File "/Users/juliankleutgens/opt/anaconda3/envs/tgdp/lib/python3.9/site-packages/wandb/sdk/lib/sock_client.py", line 174, in send_record_publish
    self.send_server_request(server_req)
  File "/Users/juliankleutgens/opt/anaconda3/envs/tgdp/lib/python3.9/site-packages/wandb/sdk/lib/sock_client.py", line 154, in send_server_request
    self._send_message(msg)
  File "/Users/juliankleutgens/opt/anaconda3/envs/tgdp/lib/python3.9/site-packages/wandb/sdk/lib/sock_client.py", line 151, in _send_message
    self._sendall_with_error_handle(header + data)
  File "/Users/juliankleutgens/opt/anaconda3/envs/tgdp/lib/python3.9/site-packages/wandb/sdk/lib/sock_client.py", line 130, in _sendall_with_error_handle
    sent = self._sock.send(data)
BrokenPipeError: [Errno 32] Broken pipe
2025-05-30 13:40:23,732 ERROR   MainThread:19848 [redirect.py:_on_write():664] [no run ID] error in stderr callback
Traceback (most recent call last):
  File "/Users/juliankleutgens/opt/anaconda3/envs/tgdp/lib/python3.9/site-packages/wandb/sdk/lib/redirect.py", line 662, in _on_write
    cb(written_data)
  File "/Users/juliankleutgens/opt/anaconda3/envs/tgdp/lib/python3.9/site-packages/wandb/sdk/wandb_run.py", line 2500, in <lambda>
    lambda data: self._console_raw_callback("stderr", data),
  File "/Users/juliankleutgens/opt/anaconda3/envs/tgdp/lib/python3.9/site-packages/wandb/sdk/wandb_run.py", line 406, in wrapper
    return func(self, *args, **kwargs)
  File "/Users/juliankleutgens/opt/anaconda3/envs/tgdp/lib/python3.9/site-packages/wandb/sdk/wandb_run.py", line 464, in wrapper_fn
    return func(self, *args, **kwargs)
  File "/Users/juliankleutgens/opt/anaconda3/envs/tgdp/lib/python3.9/site-packages/wandb/sdk/wandb_run.py", line 1639, in _console_raw_callback
    self._backend.interface.publish_output_raw(name, data)
  File "/Users/juliankleutgens/opt/anaconda3/envs/tgdp/lib/python3.9/site-packages/wandb/sdk/interface/interface.py", line 762, in publish_output_raw
    self._publish_output_raw(o)
  File "/Users/juliankleutgens/opt/anaconda3/envs/tgdp/lib/python3.9/site-packages/wandb/sdk/interface/interface_shared.py", line 38, in _publish_output_raw
    self._publish(rec)
  File "/Users/juliankleutgens/opt/anaconda3/envs/tgdp/lib/python3.9/site-packages/wandb/sdk/interface/interface_sock.py", line 39, in _publish
    self._sock_client.send_record_publish(record)
  File "/Users/juliankleutgens/opt/anaconda3/envs/tgdp/lib/python3.9/site-packages/wandb/sdk/lib/sock_client.py", line 174, in send_record_publish
    self.send_server_request(server_req)
  File "/Users/juliankleutgens/opt/anaconda3/envs/tgdp/lib/python3.9/site-packages/wandb/sdk/lib/sock_client.py", line 154, in send_server_request
    self._send_message(msg)
  File "/Users/juliankleutgens/opt/anaconda3/envs/tgdp/lib/python3.9/site-packages/wandb/sdk/lib/sock_client.py", line 151, in _send_message
    self._sendall_with_error_handle(header + data)
  File "/Users/juliankleutgens/opt/anaconda3/envs/tgdp/lib/python3.9/site-packages/wandb/sdk/lib/sock_client.py", line 130, in _sendall_with_error_handle
    sent = self._sock.send(data)
BrokenPipeError: [Errno 32] Broken pipe
2025-05-30 13:40:23,732 ERROR   MainThread:19848 [redirect.py:_on_write():664] [no run ID] error in stderr callback
Traceback (most recent call last):
  File "/Users/juliankleutgens/opt/anaconda3/envs/tgdp/lib/python3.9/site-packages/wandb/sdk/lib/redirect.py", line 662, in _on_write
    cb(written_data)
  File "/Users/juliankleutgens/opt/anaconda3/envs/tgdp/lib/python3.9/site-packages/wandb/sdk/wandb_run.py", line 2500, in <lambda>
    lambda data: self._console_raw_callback("stderr", data),
  File "/Users/juliankleutgens/opt/anaconda3/envs/tgdp/lib/python3.9/site-packages/wandb/sdk/wandb_run.py", line 406, in wrapper
    return func(self, *args, **kwargs)
  File "/Users/juliankleutgens/opt/anaconda3/envs/tgdp/lib/python3.9/site-packages/wandb/sdk/wandb_run.py", line 464, in wrapper_fn
    return func(self, *args, **kwargs)
  File "/Users/juliankleutgens/opt/anaconda3/envs/tgdp/lib/python3.9/site-packages/wandb/sdk/wandb_run.py", line 1639, in _console_raw_callback
    self._backend.interface.publish_output_raw(name, data)
  File "/Users/juliankleutgens/opt/anaconda3/envs/tgdp/lib/python3.9/site-packages/wandb/sdk/interface/interface.py", line 762, in publish_output_raw
    self._publish_output_raw(o)
  File "/Users/juliankleutgens/opt/anaconda3/envs/tgdp/lib/python3.9/site-packages/wandb/sdk/interface/interface_shared.py", line 38, in _publish_output_raw
    self._publish(rec)
  File "/Users/juliankleutgens/opt/anaconda3/envs/tgdp/lib/python3.9/site-packages/wandb/sdk/interface/interface_sock.py", line 39, in _publish
    self._sock_client.send_record_publish(record)
  File "/Users/juliankleutgens/opt/anaconda3/envs/tgdp/lib/python3.9/site-packages/wandb/sdk/lib/sock_client.py", line 174, in send_record_publish
    self.send_server_request(server_req)
  File "/Users/juliankleutgens/opt/anaconda3/envs/tgdp/lib/python3.9/site-packages/wandb/sdk/lib/sock_client.py", line 154, in send_server_request
    self._send_message(msg)
  File "/Users/juliankleutgens/opt/anaconda3/envs/tgdp/lib/python3.9/site-packages/wandb/sdk/lib/sock_client.py", line 151, in _send_message
    self._sendall_with_error_handle(header + data)
  File "/Users/juliankleutgens/opt/anaconda3/envs/tgdp/lib/python3.9/site-packages/wandb/sdk/lib/sock_client.py", line 130, in _sendall_with_error_handle
    sent = self._sock.send(data)
BrokenPipeError: [Errno 32] Broken pipe
2025-05-30 13:40:23,732 ERROR   MainThread:19848 [redirect.py:_on_write():664] [no run ID] error in stderr callback
Traceback (most recent call last):
  File "/Users/juliankleutgens/opt/anaconda3/envs/tgdp/lib/python3.9/site-packages/wandb/sdk/lib/redirect.py", line 662, in _on_write
    cb(written_data)
  File "/Users/juliankleutgens/opt/anaconda3/envs/tgdp/lib/python3.9/site-packages/wandb/sdk/wandb_run.py", line 2500, in <lambda>
    lambda data: self._console_raw_callback("stderr", data),
  File "/Users/juliankleutgens/opt/anaconda3/envs/tgdp/lib/python3.9/site-packages/wandb/sdk/wandb_run.py", line 406, in wrapper
    return func(self, *args, **kwargs)
  File "/Users/juliankleutgens/opt/anaconda3/envs/tgdp/lib/python3.9/site-packages/wandb/sdk/wandb_run.py", line 464, in wrapper_fn
    return func(self, *args, **kwargs)
  File "/Users/juliankleutgens/opt/anaconda3/envs/tgdp/lib/python3.9/site-packages/wandb/sdk/wandb_run.py", line 1639, in _console_raw_callback
    self._backend.interface.publish_output_raw(name, data)
  File "/Users/juliankleutgens/opt/anaconda3/envs/tgdp/lib/python3.9/site-packages/wandb/sdk/interface/interface.py", line 762, in publish_output_raw
    self._publish_output_raw(o)
  File "/Users/juliankleutgens/opt/anaconda3/envs/tgdp/lib/python3.9/site-packages/wandb/sdk/interface/interface_shared.py", line 38, in _publish_output_raw
    self._publish(rec)
  File "/Users/juliankleutgens/opt/anaconda3/envs/tgdp/lib/python3.9/site-packages/wandb/sdk/interface/interface_sock.py", line 39, in _publish
    self._sock_client.send_record_publish(record)
  File "/Users/juliankleutgens/opt/anaconda3/envs/tgdp/lib/python3.9/site-packages/wandb/sdk/lib/sock_client.py", line 174, in send_record_publish
    self.send_server_request(server_req)
  File "/Users/juliankleutgens/opt/anaconda3/envs/tgdp/lib/python3.9/site-packages/wandb/sdk/lib/sock_client.py", line 154, in send_server_request
    self._send_message(msg)
  File "/Users/juliankleutgens/opt/anaconda3/envs/tgdp/lib/python3.9/site-packages/wandb/sdk/lib/sock_client.py", line 151, in _send_message
    self._sendall_with_error_handle(header + data)
  File "/Users/juliankleutgens/opt/anaconda3/envs/tgdp/lib/python3.9/site-packages/wandb/sdk/lib/sock_client.py", line 130, in _sendall_with_error_handle
    sent = self._sock.send(data)
BrokenPipeError: [Errno 32] Broken pipe
2025-05-30 13:40:23,732 ERROR   MainThread:19848 [redirect.py:_on_write():664] [no run ID] error in stderr callback
Traceback (most recent call last):
  File "/Users/juliankleutgens/opt/anaconda3/envs/tgdp/lib/python3.9/site-packages/wandb/sdk/lib/redirect.py", line 662, in _on_write
    cb(written_data)
  File "/Users/juliankleutgens/opt/anaconda3/envs/tgdp/lib/python3.9/site-packages/wandb/sdk/wandb_run.py", line 2500, in <lambda>
    lambda data: self._console_raw_callback("stderr", data),
  File "/Users/juliankleutgens/opt/anaconda3/envs/tgdp/lib/python3.9/site-packages/wandb/sdk/wandb_run.py", line 406, in wrapper
    return func(self, *args, **kwargs)
  File "/Users/juliankleutgens/opt/anaconda3/envs/tgdp/lib/python3.9/site-packages/wandb/sdk/wandb_run.py", line 464, in wrapper_fn
    return func(self, *args, **kwargs)
  File "/Users/juliankleutgens/opt/anaconda3/envs/tgdp/lib/python3.9/site-packages/wandb/sdk/wandb_run.py", line 1639, in _console_raw_callback
    self._backend.interface.publish_output_raw(name, data)
  File "/Users/juliankleutgens/opt/anaconda3/envs/tgdp/lib/python3.9/site-packages/wandb/sdk/interface/interface.py", line 762, in publish_output_raw
    self._publish_output_raw(o)
  File "/Users/juliankleutgens/opt/anaconda3/envs/tgdp/lib/python3.9/site-packages/wandb/sdk/interface/interface_shared.py", line 38, in _publish_output_raw
    self._publish(rec)
  File "/Users/juliankleutgens/opt/anaconda3/envs/tgdp/lib/python3.9/site-packages/wandb/sdk/interface/interface_sock.py", line 39, in _publish
    self._sock_client.send_record_publish(record)
  File "/Users/juliankleutgens/opt/anaconda3/envs/tgdp/lib/python3.9/site-packages/wandb/sdk/lib/sock_client.py", line 174, in send_record_publish
    self.send_server_request(server_req)
  File "/Users/juliankleutgens/opt/anaconda3/envs/tgdp/lib/python3.9/site-packages/wandb/sdk/lib/sock_client.py", line 154, in send_server_request
    self._send_message(msg)
  File "/Users/juliankleutgens/opt/anaconda3/envs/tgdp/lib/python3.9/site-packages/wandb/sdk/lib/sock_client.py", line 151, in _send_message
    self._sendall_with_error_handle(header + data)
  File "/Users/juliankleutgens/opt/anaconda3/envs/tgdp/lib/python3.9/site-packages/wandb/sdk/lib/sock_client.py", line 130, in _sendall_with_error_handle
    sent = self._sock.send(data)
BrokenPipeError: [Errno 32] Broken pipe
2025-05-30 13:40:23,733 ERROR   MainThread:19848 [redirect.py:_on_write():664] [no run ID] error in stderr callback
Traceback (most recent call last):
  File "/Users/juliankleutgens/opt/anaconda3/envs/tgdp/lib/python3.9/site-packages/wandb/sdk/lib/redirect.py", line 662, in _on_write
    cb(written_data)
  File "/Users/juliankleutgens/opt/anaconda3/envs/tgdp/lib/python3.9/site-packages/wandb/sdk/wandb_run.py", line 2500, in <lambda>
    lambda data: self._console_raw_callback("stderr", data),
  File "/Users/juliankleutgens/opt/anaconda3/envs/tgdp/lib/python3.9/site-packages/wandb/sdk/wandb_run.py", line 406, in wrapper
    return func(self, *args, **kwargs)
  File "/Users/juliankleutgens/opt/anaconda3/envs/tgdp/lib/python3.9/site-packages/wandb/sdk/wandb_run.py", line 464, in wrapper_fn
    return func(self, *args, **kwargs)
  File "/Users/juliankleutgens/opt/anaconda3/envs/tgdp/lib/python3.9/site-packages/wandb/sdk/wandb_run.py", line 1639, in _console_raw_callback
    self._backend.interface.publish_output_raw(name, data)
  File "/Users/juliankleutgens/opt/anaconda3/envs/tgdp/lib/python3.9/site-packages/wandb/sdk/interface/interface.py", line 762, in publish_output_raw
    self._publish_output_raw(o)
  File "/Users/juliankleutgens/opt/anaconda3/envs/tgdp/lib/python3.9/site-packages/wandb/sdk/interface/interface_shared.py", line 38, in _publish_output_raw
    self._publish(rec)
  File "/Users/juliankleutgens/opt/anaconda3/envs/tgdp/lib/python3.9/site-packages/wandb/sdk/interface/interface_sock.py", line 39, in _publish
    self._sock_client.send_record_publish(record)
  File "/Users/juliankleutgens/opt/anaconda3/envs/tgdp/lib/python3.9/site-packages/wandb/sdk/lib/sock_client.py", line 174, in send_record_publish
    self.send_server_request(server_req)
  File "/Users/juliankleutgens/opt/anaconda3/envs/tgdp/lib/python3.9/site-packages/wandb/sdk/lib/sock_client.py", line 154, in send_server_request
    self._send_message(msg)
  File "/Users/juliankleutgens/opt/anaconda3/envs/tgdp/lib/python3.9/site-packages/wandb/sdk/lib/sock_client.py", line 151, in _send_message
    self._sendall_with_error_handle(header + data)
  File "/Users/juliankleutgens/opt/anaconda3/envs/tgdp/lib/python3.9/site-packages/wandb/sdk/lib/sock_client.py", line 130, in _sendall_with_error_handle
    sent = self._sock.send(data)
BrokenPipeError: [Errno 32] Broken pipe
2025-05-30 13:40:23,733 ERROR   MainThread:19848 [redirect.py:_on_write():664] [no run ID] error in stderr callback
Traceback (most recent call last):
  File "/Users/juliankleutgens/opt/anaconda3/envs/tgdp/lib/python3.9/site-packages/wandb/sdk/lib/redirect.py", line 662, in _on_write
    cb(written_data)
  File "/Users/juliankleutgens/opt/anaconda3/envs/tgdp/lib/python3.9/site-packages/wandb/sdk/wandb_run.py", line 2500, in <lambda>
    lambda data: self._console_raw_callback("stderr", data),
  File "/Users/juliankleutgens/opt/anaconda3/envs/tgdp/lib/python3.9/site-packages/wandb/sdk/wandb_run.py", line 406, in wrapper
    return func(self, *args, **kwargs)
  File "/Users/juliankleutgens/opt/anaconda3/envs/tgdp/lib/python3.9/site-packages/wandb/sdk/wandb_run.py", line 464, in wrapper_fn
    return func(self, *args, **kwargs)
  File "/Users/juliankleutgens/opt/anaconda3/envs/tgdp/lib/python3.9/site-packages/wandb/sdk/wandb_run.py", line 1639, in _console_raw_callback
    self._backend.interface.publish_output_raw(name, data)
  File "/Users/juliankleutgens/opt/anaconda3/envs/tgdp/lib/python3.9/site-packages/wandb/sdk/interface/interface.py", line 762, in publish_output_raw
    self._publish_output_raw(o)
  File "/Users/juliankleutgens/opt/anaconda3/envs/tgdp/lib/python3.9/site-packages/wandb/sdk/interface/interface_shared.py", line 38, in _publish_output_raw
    self._publish(rec)
  File "/Users/juliankleutgens/opt/anaconda3/envs/tgdp/lib/python3.9/site-packages/wandb/sdk/interface/interface_sock.py", line 39, in _publish
    self._sock_client.send_record_publish(record)
  File "/Users/juliankleutgens/opt/anaconda3/envs/tgdp/lib/python3.9/site-packages/wandb/sdk/lib/sock_client.py", line 174, in send_record_publish
    self.send_server_request(server_req)
  File "/Users/juliankleutgens/opt/anaconda3/envs/tgdp/lib/python3.9/site-packages/wandb/sdk/lib/sock_client.py", line 154, in send_server_request
    self._send_message(msg)
  File "/Users/juliankleutgens/opt/anaconda3/envs/tgdp/lib/python3.9/site-packages/wandb/sdk/lib/sock_client.py", line 151, in _send_message
    self._sendall_with_error_handle(header + data)
  File "/Users/juliankleutgens/opt/anaconda3/envs/tgdp/lib/python3.9/site-packages/wandb/sdk/lib/sock_client.py", line 130, in _sendall_with_error_handle
    sent = self._sock.send(data)
BrokenPipeError: [Errno 32] Broken pipe
2025-05-30 13:40:23,733 ERROR   MainThread:19848 [redirect.py:_on_write():664] [no run ID] error in stderr callback
Traceback (most recent call last):
  File "/Users/juliankleutgens/opt/anaconda3/envs/tgdp/lib/python3.9/site-packages/wandb/sdk/lib/redirect.py", line 662, in _on_write
    cb(written_data)
  File "/Users/juliankleutgens/opt/anaconda3/envs/tgdp/lib/python3.9/site-packages/wandb/sdk/wandb_run.py", line 2500, in <lambda>
    lambda data: self._console_raw_callback("stderr", data),
  File "/Users/juliankleutgens/opt/anaconda3/envs/tgdp/lib/python3.9/site-packages/wandb/sdk/wandb_run.py", line 406, in wrapper
    return func(self, *args, **kwargs)
  File "/Users/juliankleutgens/opt/anaconda3/envs/tgdp/lib/python3.9/site-packages/wandb/sdk/wandb_run.py", line 464, in wrapper_fn
    return func(self, *args, **kwargs)
  File "/Users/juliankleutgens/opt/anaconda3/envs/tgdp/lib/python3.9/site-packages/wandb/sdk/wandb_run.py", line 1639, in _console_raw_callback
    self._backend.interface.publish_output_raw(name, data)
  File "/Users/juliankleutgens/opt/anaconda3/envs/tgdp/lib/python3.9/site-packages/wandb/sdk/interface/interface.py", line 762, in publish_output_raw
    self._publish_output_raw(o)
  File "/Users/juliankleutgens/opt/anaconda3/envs/tgdp/lib/python3.9/site-packages/wandb/sdk/interface/interface_shared.py", line 38, in _publish_output_raw
    self._publish(rec)
  File "/Users/juliankleutgens/opt/anaconda3/envs/tgdp/lib/python3.9/site-packages/wandb/sdk/interface/interface_sock.py", line 39, in _publish
    self._sock_client.send_record_publish(record)
  File "/Users/juliankleutgens/opt/anaconda3/envs/tgdp/lib/python3.9/site-packages/wandb/sdk/lib/sock_client.py", line 174, in send_record_publish
    self.send_server_request(server_req)
  File "/Users/juliankleutgens/opt/anaconda3/envs/tgdp/lib/python3.9/site-packages/wandb/sdk/lib/sock_client.py", line 154, in send_server_request
    self._send_message(msg)
  File "/Users/juliankleutgens/opt/anaconda3/envs/tgdp/lib/python3.9/site-packages/wandb/sdk/lib/sock_client.py", line 151, in _send_message
    self._sendall_with_error_handle(header + data)
  File "/Users/juliankleutgens/opt/anaconda3/envs/tgdp/lib/python3.9/site-packages/wandb/sdk/lib/sock_client.py", line 130, in _sendall_with_error_handle
    sent = self._sock.send(data)
BrokenPipeError: [Errno 32] Broken pipe
2025-05-30 13:40:23,733 ERROR   MainThread:19848 [redirect.py:_on_write():664] [no run ID] error in stderr callback
Traceback (most recent call last):
  File "/Users/juliankleutgens/opt/anaconda3/envs/tgdp/lib/python3.9/site-packages/wandb/sdk/lib/redirect.py", line 662, in _on_write
    cb(written_data)
  File "/Users/juliankleutgens/opt/anaconda3/envs/tgdp/lib/python3.9/site-packages/wandb/sdk/wandb_run.py", line 2500, in <lambda>
    lambda data: self._console_raw_callback("stderr", data),
  File "/Users/juliankleutgens/opt/anaconda3/envs/tgdp/lib/python3.9/site-packages/wandb/sdk/wandb_run.py", line 406, in wrapper
    return func(self, *args, **kwargs)
  File "/Users/juliankleutgens/opt/anaconda3/envs/tgdp/lib/python3.9/site-packages/wandb/sdk/wandb_run.py", line 464, in wrapper_fn
    return func(self, *args, **kwargs)
  File "/Users/juliankleutgens/opt/anaconda3/envs/tgdp/lib/python3.9/site-packages/wandb/sdk/wandb_run.py", line 1639, in _console_raw_callback
    self._backend.interface.publish_output_raw(name, data)
  File "/Users/juliankleutgens/opt/anaconda3/envs/tgdp/lib/python3.9/site-packages/wandb/sdk/interface/interface.py", line 762, in publish_output_raw
    self._publish_output_raw(o)
  File "/Users/juliankleutgens/opt/anaconda3/envs/tgdp/lib/python3.9/site-packages/wandb/sdk/interface/interface_shared.py", line 38, in _publish_output_raw
    self._publish(rec)
  File "/Users/juliankleutgens/opt/anaconda3/envs/tgdp/lib/python3.9/site-packages/wandb/sdk/interface/interface_sock.py", line 39, in _publish
    self._sock_client.send_record_publish(record)
  File "/Users/juliankleutgens/opt/anaconda3/envs/tgdp/lib/python3.9/site-packages/wandb/sdk/lib/sock_client.py", line 174, in send_record_publish
    self.send_server_request(server_req)
  File "/Users/juliankleutgens/opt/anaconda3/envs/tgdp/lib/python3.9/site-packages/wandb/sdk/lib/sock_client.py", line 154, in send_server_request
    self._send_message(msg)
  File "/Users/juliankleutgens/opt/anaconda3/envs/tgdp/lib/python3.9/site-packages/wandb/sdk/lib/sock_client.py", line 151, in _send_message
    self._sendall_with_error_handle(header + data)
  File "/Users/juliankleutgens/opt/anaconda3/envs/tgdp/lib/python3.9/site-packages/wandb/sdk/lib/sock_client.py", line 130, in _sendall_with_error_handle
    sent = self._sock.send(data)
BrokenPipeError: [Errno 32] Broken pipe
2025-05-30 13:40:23,733 ERROR   MainThread:19848 [redirect.py:_on_write():664] [no run ID] error in stderr callback
Traceback (most recent call last):
  File "/Users/juliankleutgens/opt/anaconda3/envs/tgdp/lib/python3.9/site-packages/wandb/sdk/lib/redirect.py", line 662, in _on_write
    cb(written_data)
  File "/Users/juliankleutgens/opt/anaconda3/envs/tgdp/lib/python3.9/site-packages/wandb/sdk/wandb_run.py", line 2500, in <lambda>
    lambda data: self._console_raw_callback("stderr", data),
  File "/Users/juliankleutgens/opt/anaconda3/envs/tgdp/lib/python3.9/site-packages/wandb/sdk/wandb_run.py", line 406, in wrapper
    return func(self, *args, **kwargs)
  File "/Users/juliankleutgens/opt/anaconda3/envs/tgdp/lib/python3.9/site-packages/wandb/sdk/wandb_run.py", line 464, in wrapper_fn
    return func(self, *args, **kwargs)
  File "/Users/juliankleutgens/opt/anaconda3/envs/tgdp/lib/python3.9/site-packages/wandb/sdk/wandb_run.py", line 1639, in _console_raw_callback
    self._backend.interface.publish_output_raw(name, data)
  File "/Users/juliankleutgens/opt/anaconda3/envs/tgdp/lib/python3.9/site-packages/wandb/sdk/interface/interface.py", line 762, in publish_output_raw
    self._publish_output_raw(o)
  File "/Users/juliankleutgens/opt/anaconda3/envs/tgdp/lib/python3.9/site-packages/wandb/sdk/interface/interface_shared.py", line 38, in _publish_output_raw
    self._publish(rec)
  File "/Users/juliankleutgens/opt/anaconda3/envs/tgdp/lib/python3.9/site-packages/wandb/sdk/interface/interface_sock.py", line 39, in _publish
    self._sock_client.send_record_publish(record)
  File "/Users/juliankleutgens/opt/anaconda3/envs/tgdp/lib/python3.9/site-packages/wandb/sdk/lib/sock_client.py", line 174, in send_record_publish
    self.send_server_request(server_req)
  File "/Users/juliankleutgens/opt/anaconda3/envs/tgdp/lib/python3.9/site-packages/wandb/sdk/lib/sock_client.py", line 154, in send_server_request
    self._send_message(msg)
  File "/Users/juliankleutgens/opt/anaconda3/envs/tgdp/lib/python3.9/site-packages/wandb/sdk/lib/sock_client.py", line 151, in _send_message
    self._sendall_with_error_handle(header + data)
  File "/Users/juliankleutgens/opt/anaconda3/envs/tgdp/lib/python3.9/site-packages/wandb/sdk/lib/sock_client.py", line 130, in _sendall_with_error_handle
    sent = self._sock.send(data)
BrokenPipeError: [Errno 32] Broken pipe
2025-05-30 13:40:23,733 ERROR   MainThread:19848 [redirect.py:_on_write():664] [no run ID] error in stderr callback
Traceback (most recent call last):
  File "/Users/juliankleutgens/opt/anaconda3/envs/tgdp/lib/python3.9/site-packages/wandb/sdk/lib/redirect.py", line 662, in _on_write
    cb(written_data)
  File "/Users/juliankleutgens/opt/anaconda3/envs/tgdp/lib/python3.9/site-packages/wandb/sdk/wandb_run.py", line 2500, in <lambda>
    lambda data: self._console_raw_callback("stderr", data),
  File "/Users/juliankleutgens/opt/anaconda3/envs/tgdp/lib/python3.9/site-packages/wandb/sdk/wandb_run.py", line 406, in wrapper
    return func(self, *args, **kwargs)
  File "/Users/juliankleutgens/opt/anaconda3/envs/tgdp/lib/python3.9/site-packages/wandb/sdk/wandb_run.py", line 464, in wrapper_fn
    return func(self, *args, **kwargs)
  File "/Users/juliankleutgens/opt/anaconda3/envs/tgdp/lib/python3.9/site-packages/wandb/sdk/wandb_run.py", line 1639, in _console_raw_callback
    self._backend.interface.publish_output_raw(name, data)
  File "/Users/juliankleutgens/opt/anaconda3/envs/tgdp/lib/python3.9/site-packages/wandb/sdk/interface/interface.py", line 762, in publish_output_raw
    self._publish_output_raw(o)
  File "/Users/juliankleutgens/opt/anaconda3/envs/tgdp/lib/python3.9/site-packages/wandb/sdk/interface/interface_shared.py", line 38, in _publish_output_raw
    self._publish(rec)
  File "/Users/juliankleutgens/opt/anaconda3/envs/tgdp/lib/python3.9/site-packages/wandb/sdk/interface/interface_sock.py", line 39, in _publish
    self._sock_client.send_record_publish(record)
  File "/Users/juliankleutgens/opt/anaconda3/envs/tgdp/lib/python3.9/site-packages/wandb/sdk/lib/sock_client.py", line 174, in send_record_publish
    self.send_server_request(server_req)
  File "/Users/juliankleutgens/opt/anaconda3/envs/tgdp/lib/python3.9/site-packages/wandb/sdk/lib/sock_client.py", line 154, in send_server_request
    self._send_message(msg)
  File "/Users/juliankleutgens/opt/anaconda3/envs/tgdp/lib/python3.9/site-packages/wandb/sdk/lib/sock_client.py", line 151, in _send_message
    self._sendall_with_error_handle(header + data)
  File "/Users/juliankleutgens/opt/anaconda3/envs/tgdp/lib/python3.9/site-packages/wandb/sdk/lib/sock_client.py", line 130, in _sendall_with_error_handle
    sent = self._sock.send(data)
BrokenPipeError: [Errno 32] Broken pipe
2025-05-30 13:40:23,733 ERROR   MainThread:19848 [redirect.py:_on_write():664] [no run ID] error in stderr callback
Traceback (most recent call last):
  File "/Users/juliankleutgens/opt/anaconda3/envs/tgdp/lib/python3.9/site-packages/wandb/sdk/lib/redirect.py", line 662, in _on_write
    cb(written_data)
  File "/Users/juliankleutgens/opt/anaconda3/envs/tgdp/lib/python3.9/site-packages/wandb/sdk/wandb_run.py", line 2500, in <lambda>
    lambda data: self._console_raw_callback("stderr", data),
  File "/Users/juliankleutgens/opt/anaconda3/envs/tgdp/lib/python3.9/site-packages/wandb/sdk/wandb_run.py", line 406, in wrapper
    return func(self, *args, **kwargs)
  File "/Users/juliankleutgens/opt/anaconda3/envs/tgdp/lib/python3.9/site-packages/wandb/sdk/wandb_run.py", line 464, in wrapper_fn
    return func(self, *args, **kwargs)
  File "/Users/juliankleutgens/opt/anaconda3/envs/tgdp/lib/python3.9/site-packages/wandb/sdk/wandb_run.py", line 1639, in _console_raw_callback
    self._backend.interface.publish_output_raw(name, data)
  File "/Users/juliankleutgens/opt/anaconda3/envs/tgdp/lib/python3.9/site-packages/wandb/sdk/interface/interface.py", line 762, in publish_output_raw
    self._publish_output_raw(o)
  File "/Users/juliankleutgens/opt/anaconda3/envs/tgdp/lib/python3.9/site-packages/wandb/sdk/interface/interface_shared.py", line 38, in _publish_output_raw
    self._publish(rec)
  File "/Users/juliankleutgens/opt/anaconda3/envs/tgdp/lib/python3.9/site-packages/wandb/sdk/interface/interface_sock.py", line 39, in _publish
    self._sock_client.send_record_publish(record)
  File "/Users/juliankleutgens/opt/anaconda3/envs/tgdp/lib/python3.9/site-packages/wandb/sdk/lib/sock_client.py", line 174, in send_record_publish
    self.send_server_request(server_req)
  File "/Users/juliankleutgens/opt/anaconda3/envs/tgdp/lib/python3.9/site-packages/wandb/sdk/lib/sock_client.py", line 154, in send_server_request
    self._send_message(msg)
  File "/Users/juliankleutgens/opt/anaconda3/envs/tgdp/lib/python3.9/site-packages/wandb/sdk/lib/sock_client.py", line 151, in _send_message
    self._sendall_with_error_handle(header + data)
  File "/Users/juliankleutgens/opt/anaconda3/envs/tgdp/lib/python3.9/site-packages/wandb/sdk/lib/sock_client.py", line 130, in _sendall_with_error_handle
    sent = self._sock.send(data)
BrokenPipeError: [Errno 32] Broken pipe
2025-05-30 13:40:23,733 ERROR   MainThread:19848 [redirect.py:_on_write():664] [no run ID] error in stderr callback
Traceback (most recent call last):
  File "/Users/juliankleutgens/opt/anaconda3/envs/tgdp/lib/python3.9/site-packages/wandb/sdk/lib/redirect.py", line 662, in _on_write
    cb(written_data)
  File "/Users/juliankleutgens/opt/anaconda3/envs/tgdp/lib/python3.9/site-packages/wandb/sdk/wandb_run.py", line 2500, in <lambda>
    lambda data: self._console_raw_callback("stderr", data),
  File "/Users/juliankleutgens/opt/anaconda3/envs/tgdp/lib/python3.9/site-packages/wandb/sdk/wandb_run.py", line 406, in wrapper
    return func(self, *args, **kwargs)
  File "/Users/juliankleutgens/opt/anaconda3/envs/tgdp/lib/python3.9/site-packages/wandb/sdk/wandb_run.py", line 464, in wrapper_fn
    return func(self, *args, **kwargs)
  File "/Users/juliankleutgens/opt/anaconda3/envs/tgdp/lib/python3.9/site-packages/wandb/sdk/wandb_run.py", line 1639, in _console_raw_callback
    self._backend.interface.publish_output_raw(name, data)
  File "/Users/juliankleutgens/opt/anaconda3/envs/tgdp/lib/python3.9/site-packages/wandb/sdk/interface/interface.py", line 762, in publish_output_raw
    self._publish_output_raw(o)
  File "/Users/juliankleutgens/opt/anaconda3/envs/tgdp/lib/python3.9/site-packages/wandb/sdk/interface/interface_shared.py", line 38, in _publish_output_raw
    self._publish(rec)
  File "/Users/juliankleutgens/opt/anaconda3/envs/tgdp/lib/python3.9/site-packages/wandb/sdk/interface/interface_sock.py", line 39, in _publish
    self._sock_client.send_record_publish(record)
  File "/Users/juliankleutgens/opt/anaconda3/envs/tgdp/lib/python3.9/site-packages/wandb/sdk/lib/sock_client.py", line 174, in send_record_publish
    self.send_server_request(server_req)
  File "/Users/juliankleutgens/opt/anaconda3/envs/tgdp/lib/python3.9/site-packages/wandb/sdk/lib/sock_client.py", line 154, in send_server_request
    self._send_message(msg)
  File "/Users/juliankleutgens/opt/anaconda3/envs/tgdp/lib/python3.9/site-packages/wandb/sdk/lib/sock_client.py", line 151, in _send_message
    self._sendall_with_error_handle(header + data)
  File "/Users/juliankleutgens/opt/anaconda3/envs/tgdp/lib/python3.9/site-packages/wandb/sdk/lib/sock_client.py", line 130, in _sendall_with_error_handle
    sent = self._sock.send(data)
BrokenPipeError: [Errno 32] Broken pipe
2025-05-30 13:40:23,733 ERROR   MainThread:19848 [redirect.py:_on_write():664] [no run ID] error in stderr callback
Traceback (most recent call last):
  File "/Users/juliankleutgens/opt/anaconda3/envs/tgdp/lib/python3.9/site-packages/wandb/sdk/lib/redirect.py", line 662, in _on_write
    cb(written_data)
  File "/Users/juliankleutgens/opt/anaconda3/envs/tgdp/lib/python3.9/site-packages/wandb/sdk/wandb_run.py", line 2500, in <lambda>
    lambda data: self._console_raw_callback("stderr", data),
  File "/Users/juliankleutgens/opt/anaconda3/envs/tgdp/lib/python3.9/site-packages/wandb/sdk/wandb_run.py", line 406, in wrapper
    return func(self, *args, **kwargs)
  File "/Users/juliankleutgens/opt/anaconda3/envs/tgdp/lib/python3.9/site-packages/wandb/sdk/wandb_run.py", line 464, in wrapper_fn
    return func(self, *args, **kwargs)
  File "/Users/juliankleutgens/opt/anaconda3/envs/tgdp/lib/python3.9/site-packages/wandb/sdk/wandb_run.py", line 1639, in _console_raw_callback
    self._backend.interface.publish_output_raw(name, data)
  File "/Users/juliankleutgens/opt/anaconda3/envs/tgdp/lib/python3.9/site-packages/wandb/sdk/interface/interface.py", line 762, in publish_output_raw
    self._publish_output_raw(o)
  File "/Users/juliankleutgens/opt/anaconda3/envs/tgdp/lib/python3.9/site-packages/wandb/sdk/interface/interface_shared.py", line 38, in _publish_output_raw
    self._publish(rec)
  File "/Users/juliankleutgens/opt/anaconda3/envs/tgdp/lib/python3.9/site-packages/wandb/sdk/interface/interface_sock.py", line 39, in _publish
    self._sock_client.send_record_publish(record)
  File "/Users/juliankleutgens/opt/anaconda3/envs/tgdp/lib/python3.9/site-packages/wandb/sdk/lib/sock_client.py", line 174, in send_record_publish
    self.send_server_request(server_req)
  File "/Users/juliankleutgens/opt/anaconda3/envs/tgdp/lib/python3.9/site-packages/wandb/sdk/lib/sock_client.py", line 154, in send_server_request
    self._send_message(msg)
  File "/Users/juliankleutgens/opt/anaconda3/envs/tgdp/lib/python3.9/site-packages/wandb/sdk/lib/sock_client.py", line 151, in _send_message
    self._sendall_with_error_handle(header + data)
  File "/Users/juliankleutgens/opt/anaconda3/envs/tgdp/lib/python3.9/site-packages/wandb/sdk/lib/sock_client.py", line 130, in _sendall_with_error_handle
    sent = self._sock.send(data)
BrokenPipeError: [Errno 32] Broken pipe
2025-05-30 13:40:23,734 ERROR   MainThread:19848 [redirect.py:_on_write():664] [no run ID] error in stderr callback
Traceback (most recent call last):
  File "/Users/juliankleutgens/opt/anaconda3/envs/tgdp/lib/python3.9/site-packages/wandb/sdk/lib/redirect.py", line 662, in _on_write
    cb(written_data)
  File "/Users/juliankleutgens/opt/anaconda3/envs/tgdp/lib/python3.9/site-packages/wandb/sdk/wandb_run.py", line 2500, in <lambda>
    lambda data: self._console_raw_callback("stderr", data),
  File "/Users/juliankleutgens/opt/anaconda3/envs/tgdp/lib/python3.9/site-packages/wandb/sdk/wandb_run.py", line 406, in wrapper
    return func(self, *args, **kwargs)
  File "/Users/juliankleutgens/opt/anaconda3/envs/tgdp/lib/python3.9/site-packages/wandb/sdk/wandb_run.py", line 464, in wrapper_fn
    return func(self, *args, **kwargs)
  File "/Users/juliankleutgens/opt/anaconda3/envs/tgdp/lib/python3.9/site-packages/wandb/sdk/wandb_run.py", line 1639, in _console_raw_callback
    self._backend.interface.publish_output_raw(name, data)
  File "/Users/juliankleutgens/opt/anaconda3/envs/tgdp/lib/python3.9/site-packages/wandb/sdk/interface/interface.py", line 762, in publish_output_raw
    self._publish_output_raw(o)
  File "/Users/juliankleutgens/opt/anaconda3/envs/tgdp/lib/python3.9/site-packages/wandb/sdk/interface/interface_shared.py", line 38, in _publish_output_raw
    self._publish(rec)
  File "/Users/juliankleutgens/opt/anaconda3/envs/tgdp/lib/python3.9/site-packages/wandb/sdk/interface/interface_sock.py", line 39, in _publish
    self._sock_client.send_record_publish(record)
  File "/Users/juliankleutgens/opt/anaconda3/envs/tgdp/lib/python3.9/site-packages/wandb/sdk/lib/sock_client.py", line 174, in send_record_publish
    self.send_server_request(server_req)
  File "/Users/juliankleutgens/opt/anaconda3/envs/tgdp/lib/python3.9/site-packages/wandb/sdk/lib/sock_client.py", line 154, in send_server_request
    self._send_message(msg)
  File "/Users/juliankleutgens/opt/anaconda3/envs/tgdp/lib/python3.9/site-packages/wandb/sdk/lib/sock_client.py", line 151, in _send_message
    self._sendall_with_error_handle(header + data)
  File "/Users/juliankleutgens/opt/anaconda3/envs/tgdp/lib/python3.9/site-packages/wandb/sdk/lib/sock_client.py", line 130, in _sendall_with_error_handle
    sent = self._sock.send(data)
BrokenPipeError: [Errno 32] Broken pipe
