2025-05-27 10:53:12,661 INFO    MainThread:63695 [wandb_setup.py:_flush():70] Current SDK version is 0.19.11
2025-05-27 10:53:12,661 INFO    MainThread:63695 [wandb_setup.py:_flush():70] Configure stats pid to 63695
2025-05-27 10:53:12,661 INFO    MainThread:63695 [wandb_setup.py:_flush():70] Loading settings from /Users/juliankleutgens/.config/wandb/settings
2025-05-27 10:53:12,661 INFO    MainThread:63695 [wandb_setup.py:_flush():70] Loading settings from /Users/juliankleutgens/PycharmProjects/ratio_estimation_synthetic/wandb/settings
2025-05-27 10:53:12,661 INFO    MainThread:63695 [wandb_setup.py:_flush():70] Loading settings from environment variables
2025-05-27 10:53:12,661 INFO    MainThread:63695 [wandb_init.py:setup_run_log_directory():724] Logging user logs to /Users/juliankleutgens/PycharmProjects/ratio_estimation_synthetic/wandb/run-20250527_105312-hy42cr9f/logs/debug.log
2025-05-27 10:53:12,661 INFO    MainThread:63695 [wandb_init.py:setup_run_log_directory():725] Logging internal logs to /Users/juliankleutgens/PycharmProjects/ratio_estimation_synthetic/wandb/run-20250527_105312-hy42cr9f/logs/debug-internal.log
2025-05-27 10:53:12,661 INFO    MainThread:63695 [wandb_init.py:init():852] calling init triggers
2025-05-27 10:53:12,661 INFO    MainThread:63695 [wandb_init.py:init():857] wandb.init called with sweep_config: {}
config: {'data_type': 'markov', 'unguided_sampling': False, 'skip_ratio_estimator_on_clean_data': True, 'test_run': False, 'seed': 100, 'len_seqs': 30, 'vocab_size': 5, 'number_of_source_samples': 20000, 'number_of_target_samples': 5000, 'dimension_gaussian': 2, 'num_mixtures': 2, 'grid_size': 1.5, 'quantization_step': 0.01, 'source_dist': 'uniform', 'target_dist': 'gaussian', 'distance': 5, 'grid_size_discrete': 14, 'type_of_T_matrix': 'random', 'extra_target_tokens': 2, 'batch_size': 256, 'device': device(type='mps'), 'train_classifier_epochs': 30, 'train_ratio_estimator_epochs': 30, 'train_denoiser_epochs': 30, 'denoiser_dim': 256, 'denoiser_heads': 4, 'denoiser_layers': 4, 'sample_batch_size': 1024, 'sample_gammas': [0, 0.5, 1, 2], 'sample_size': 2048, 'denoising_steps': 20, 'use_plg': True, 'eta': 1.0, '_wandb': {}}
2025-05-27 10:53:12,661 INFO    MainThread:63695 [wandb_init.py:init():893] starting backend
2025-05-27 10:53:12,661 INFO    MainThread:63695 [wandb_init.py:init():897] sending inform_init request
2025-05-27 10:53:12,681 INFO    MainThread:63695 [backend.py:_multiprocessing_setup():101] multiprocessing start_methods=spawn,fork,forkserver, using: spawn
2025-05-27 10:53:12,681 INFO    MainThread:63695 [wandb_init.py:init():907] backend started and connected
2025-05-27 10:53:12,684 INFO    MainThread:63695 [wandb_init.py:init():1005] updated telemetry
2025-05-27 10:53:12,684 INFO    MainThread:63695 [wandb_init.py:init():1029] communicating run to backend with 90.0 second timeout
2025-05-27 10:53:13,065 INFO    MainThread:63695 [wandb_init.py:init():1104] starting run threads in backend
2025-05-27 10:53:13,160 INFO    MainThread:63695 [wandb_run.py:_console_start():2573] atexit reg
2025-05-27 10:53:13,161 INFO    MainThread:63695 [wandb_run.py:_redirect():2421] redirect: wrap_raw
2025-05-27 10:53:13,161 INFO    MainThread:63695 [wandb_run.py:_redirect():2490] Wrapping output streams.
2025-05-27 10:53:13,161 INFO    MainThread:63695 [wandb_run.py:_redirect():2513] Redirects installed.
2025-05-27 10:53:13,163 INFO    MainThread:63695 [wandb_init.py:init():1150] run started, returning control to user process
2025-05-27 10:53:13,164 INFO    MainThread:63695 [wandb_run.py:_config_callback():1436] config_cb None None {'data_type': 'markov', 'unguided_sampling': False, 'skip_ratio_estimator_on_clean_data': True, 'test_run': False, 'seed': 100, 'len_seqs': 30, 'vocab_size': 5, 'number_of_source_samples': 20000, 'number_of_target_samples': 5000, 'dimension_gaussian': 2, 'num_mixtures': 2, 'grid_size': 1.5, 'quantization_step': 0.01, 'source_dist': 'uniform', 'target_dist': 'gaussian', 'distance': 5, 'grid_size_discrete': 14, 'type_of_T_matrix': 'random', 'extra_target_tokens': 2, 'batch_size': 256, 'device': 'mps', 'train_classifier_epochs': 30, 'train_ratio_estimator_epochs': 30, 'train_denoiser_epochs': 30, 'denoiser_dim': 256, 'denoiser_heads': 4, 'denoiser_layers': 4, 'sample_batch_size': 1024, 'sample_gammas': [0, 0.5, 1, 2], 'sample_size': 2048, 'denoising_steps': 20, 'use_plg': True, 'eta': 1.0}
2025-05-27 10:58:08,380 ERROR   MainThread:63695 [redirect.py:_on_write():664] [no run ID] error in stderr callback
Traceback (most recent call last):
  File "/Users/juliankleutgens/PycharmProjects/ratio_estimation_synthetic/main2.py", line 463, in <module>
    if __name__ == "__main__":
  File "/Users/juliankleutgens/PycharmProjects/ratio_estimation_synthetic/main2.py", line 210, in main
    if not config.skip_ratio_estimator_on_clean_data or not config.unguided_sampling:
  File "/Users/juliankleutgens/PycharmProjects/ratio_estimation_synthetic/training.py", line 111, in train_domain_classifier
    optimizer.step()
  File "/Users/juliankleutgens/opt/anaconda3/envs/tgdp/lib/python3.9/site-packages/torch/optim/optimizer.py", line 487, in wrapper
    out = func(*args, **kwargs)
  File "/Users/juliankleutgens/opt/anaconda3/envs/tgdp/lib/python3.9/site-packages/torch/optim/optimizer.py", line 91, in _use_grad
    ret = func(self, *args, **kwargs)
  File "/Users/juliankleutgens/opt/anaconda3/envs/tgdp/lib/python3.9/site-packages/torch/optim/adam.py", line 223, in step
    adam(
  File "/Users/juliankleutgens/opt/anaconda3/envs/tgdp/lib/python3.9/site-packages/torch/optim/optimizer.py", line 154, in maybe_fallback
    return func(*args, **kwargs)
  File "/Users/juliankleutgens/opt/anaconda3/envs/tgdp/lib/python3.9/site-packages/torch/optim/adam.py", line 784, in adam
    func(
  File "/Users/juliankleutgens/opt/anaconda3/envs/tgdp/lib/python3.9/site-packages/torch/optim/adam.py", line 381, in _single_tensor_adam
    if capturable or differentiable:
  File "/Users/juliankleutgens/opt/anaconda3/envs/tgdp/lib/python3.9/site-packages/torch/optim/adam.py", line 381, in _single_tensor_adam
    if capturable or differentiable:
  File "/Applications/PyCharm.app/Contents/plugins/python/helpers/pydev/_pydevd_bundle/pydevd_trace_dispatch.py", line 89, in trace_dispatch
    def trace_dispatch(py_db, frame, event, arg):
  File "_pydevd_bundle/pydevd_cython_darwin_39_64.pyx", line 1337, in _pydevd_bundle.pydevd_cython_darwin_39_64.trace_dispatch
  File "_pydevd_bundle/pydevd_cython_darwin_39_64.pyx", line 1597, in _pydevd_bundle.pydevd_cython_darwin_39_64.ThreadTracer.__call__
  File "_pydevd_bundle/pydevd_cython_darwin_39_64.pyx", line 937, in _pydevd_bundle.pydevd_cython_darwin_39_64.PyDBFrame.trace_dispatch
  File "_pydevd_bundle/pydevd_cython_darwin_39_64.pyx", line 928, in _pydevd_bundle.pydevd_cython_darwin_39_64.PyDBFrame.trace_dispatch
  File "_pydevd_bundle/pydevd_cython_darwin_39_64.pyx", line 585, in _pydevd_bundle.pydevd_cython_darwin_39_64.PyDBFrame.do_wait_suspend
  File "/Applications/PyCharm.app/Contents/plugins/python/helpers/pydev/pydevd.py", line 1185, in do_wait_suspend
    self._do_wait_suspend(thread, frame, event, arg, suspend_type, from_this_thread)
  File "/Applications/PyCharm.app/Contents/plugins/python/helpers/pydev/pydevd.py", line 1200, in _do_wait_suspend
    time.sleep(0.01)
KeyboardInterrupt

During handling of the above exception, another exception occurred:

Traceback (most recent call last):
  File "/Users/juliankleutgens/opt/anaconda3/envs/tgdp/lib/python3.9/site-packages/wandb/sdk/lib/redirect.py", line 662, in _on_write
    cb(written_data)
  File "/Users/juliankleutgens/opt/anaconda3/envs/tgdp/lib/python3.9/site-packages/wandb/sdk/wandb_run.py", line 2500, in <lambda>
    lambda data: self._console_raw_callback("stderr", data),
  File "/Users/juliankleutgens/opt/anaconda3/envs/tgdp/lib/python3.9/site-packages/wandb/sdk/wandb_run.py", line 406, in wrapper
    return func(self, *args, **kwargs)
  File "/Users/juliankleutgens/opt/anaconda3/envs/tgdp/lib/python3.9/site-packages/wandb/sdk/wandb_run.py", line 464, in wrapper_fn
    return func(self, *args, **kwargs)
  File "/Users/juliankleutgens/opt/anaconda3/envs/tgdp/lib/python3.9/site-packages/wandb/sdk/wandb_run.py", line 1639, in _console_raw_callback
    self._backend.interface.publish_output_raw(name, data)
  File "/Users/juliankleutgens/opt/anaconda3/envs/tgdp/lib/python3.9/site-packages/wandb/sdk/interface/interface.py", line 762, in publish_output_raw
    self._publish_output_raw(o)
  File "/Users/juliankleutgens/opt/anaconda3/envs/tgdp/lib/python3.9/site-packages/wandb/sdk/interface/interface_shared.py", line 38, in _publish_output_raw
    self._publish(rec)
  File "/Users/juliankleutgens/opt/anaconda3/envs/tgdp/lib/python3.9/site-packages/wandb/sdk/interface/interface_sock.py", line 39, in _publish
    self._sock_client.send_record_publish(record)
  File "/Users/juliankleutgens/opt/anaconda3/envs/tgdp/lib/python3.9/site-packages/wandb/sdk/lib/sock_client.py", line 174, in send_record_publish
    self.send_server_request(server_req)
  File "/Users/juliankleutgens/opt/anaconda3/envs/tgdp/lib/python3.9/site-packages/wandb/sdk/lib/sock_client.py", line 154, in send_server_request
    self._send_message(msg)
  File "/Users/juliankleutgens/opt/anaconda3/envs/tgdp/lib/python3.9/site-packages/wandb/sdk/lib/sock_client.py", line 151, in _send_message
    self._sendall_with_error_handle(header + data)
  File "/Users/juliankleutgens/opt/anaconda3/envs/tgdp/lib/python3.9/site-packages/wandb/sdk/lib/sock_client.py", line 130, in _sendall_with_error_handle
    sent = self._sock.send(data)
BrokenPipeError: [Errno 32] Broken pipe
2025-05-27 10:58:08,384 ERROR   MainThread:63695 [redirect.py:_on_write():664] [no run ID] error in stderr callback
Traceback (most recent call last):
  File "/Users/juliankleutgens/PycharmProjects/ratio_estimation_synthetic/main2.py", line 463, in <module>
    if __name__ == "__main__":
  File "/Users/juliankleutgens/PycharmProjects/ratio_estimation_synthetic/main2.py", line 210, in main
    if not config.skip_ratio_estimator_on_clean_data or not config.unguided_sampling:
  File "/Users/juliankleutgens/PycharmProjects/ratio_estimation_synthetic/training.py", line 111, in train_domain_classifier
    optimizer.step()
  File "/Users/juliankleutgens/opt/anaconda3/envs/tgdp/lib/python3.9/site-packages/torch/optim/optimizer.py", line 487, in wrapper
    out = func(*args, **kwargs)
  File "/Users/juliankleutgens/opt/anaconda3/envs/tgdp/lib/python3.9/site-packages/torch/optim/optimizer.py", line 91, in _use_grad
    ret = func(self, *args, **kwargs)
  File "/Users/juliankleutgens/opt/anaconda3/envs/tgdp/lib/python3.9/site-packages/torch/optim/adam.py", line 223, in step
    adam(
  File "/Users/juliankleutgens/opt/anaconda3/envs/tgdp/lib/python3.9/site-packages/torch/optim/optimizer.py", line 154, in maybe_fallback
    return func(*args, **kwargs)
  File "/Users/juliankleutgens/opt/anaconda3/envs/tgdp/lib/python3.9/site-packages/torch/optim/adam.py", line 784, in adam
    func(
  File "/Users/juliankleutgens/opt/anaconda3/envs/tgdp/lib/python3.9/site-packages/torch/optim/adam.py", line 381, in _single_tensor_adam
    if capturable or differentiable:
  File "/Users/juliankleutgens/opt/anaconda3/envs/tgdp/lib/python3.9/site-packages/torch/optim/adam.py", line 381, in _single_tensor_adam
    if capturable or differentiable:
  File "/Applications/PyCharm.app/Contents/plugins/python/helpers/pydev/_pydevd_bundle/pydevd_trace_dispatch.py", line 89, in trace_dispatch
    def trace_dispatch(py_db, frame, event, arg):
  File "_pydevd_bundle/pydevd_cython_darwin_39_64.pyx", line 1337, in _pydevd_bundle.pydevd_cython_darwin_39_64.trace_dispatch
  File "_pydevd_bundle/pydevd_cython_darwin_39_64.pyx", line 1597, in _pydevd_bundle.pydevd_cython_darwin_39_64.ThreadTracer.__call__
  File "_pydevd_bundle/pydevd_cython_darwin_39_64.pyx", line 937, in _pydevd_bundle.pydevd_cython_darwin_39_64.PyDBFrame.trace_dispatch
  File "_pydevd_bundle/pydevd_cython_darwin_39_64.pyx", line 928, in _pydevd_bundle.pydevd_cython_darwin_39_64.PyDBFrame.trace_dispatch
  File "_pydevd_bundle/pydevd_cython_darwin_39_64.pyx", line 585, in _pydevd_bundle.pydevd_cython_darwin_39_64.PyDBFrame.do_wait_suspend
  File "/Applications/PyCharm.app/Contents/plugins/python/helpers/pydev/pydevd.py", line 1185, in do_wait_suspend
    self._do_wait_suspend(thread, frame, event, arg, suspend_type, from_this_thread)
  File "/Applications/PyCharm.app/Contents/plugins/python/helpers/pydev/pydevd.py", line 1200, in _do_wait_suspend
    time.sleep(0.01)
KeyboardInterrupt

During handling of the above exception, another exception occurred:

Traceback (most recent call last):
  File "/Users/juliankleutgens/opt/anaconda3/envs/tgdp/lib/python3.9/site-packages/wandb/sdk/lib/redirect.py", line 662, in _on_write
    cb(written_data)
  File "/Users/juliankleutgens/opt/anaconda3/envs/tgdp/lib/python3.9/site-packages/wandb/sdk/wandb_run.py", line 2500, in <lambda>
    lambda data: self._console_raw_callback("stderr", data),
  File "/Users/juliankleutgens/opt/anaconda3/envs/tgdp/lib/python3.9/site-packages/wandb/sdk/wandb_run.py", line 406, in wrapper
    return func(self, *args, **kwargs)
  File "/Users/juliankleutgens/opt/anaconda3/envs/tgdp/lib/python3.9/site-packages/wandb/sdk/wandb_run.py", line 464, in wrapper_fn
    return func(self, *args, **kwargs)
  File "/Users/juliankleutgens/opt/anaconda3/envs/tgdp/lib/python3.9/site-packages/wandb/sdk/wandb_run.py", line 1639, in _console_raw_callback
    self._backend.interface.publish_output_raw(name, data)
  File "/Users/juliankleutgens/opt/anaconda3/envs/tgdp/lib/python3.9/site-packages/wandb/sdk/interface/interface.py", line 762, in publish_output_raw
    self._publish_output_raw(o)
  File "/Users/juliankleutgens/opt/anaconda3/envs/tgdp/lib/python3.9/site-packages/wandb/sdk/interface/interface_shared.py", line 38, in _publish_output_raw
    self._publish(rec)
  File "/Users/juliankleutgens/opt/anaconda3/envs/tgdp/lib/python3.9/site-packages/wandb/sdk/interface/interface_sock.py", line 39, in _publish
    self._sock_client.send_record_publish(record)
  File "/Users/juliankleutgens/opt/anaconda3/envs/tgdp/lib/python3.9/site-packages/wandb/sdk/lib/sock_client.py", line 174, in send_record_publish
    self.send_server_request(server_req)
  File "/Users/juliankleutgens/opt/anaconda3/envs/tgdp/lib/python3.9/site-packages/wandb/sdk/lib/sock_client.py", line 154, in send_server_request
    self._send_message(msg)
  File "/Users/juliankleutgens/opt/anaconda3/envs/tgdp/lib/python3.9/site-packages/wandb/sdk/lib/sock_client.py", line 151, in _send_message
    self._sendall_with_error_handle(header + data)
  File "/Users/juliankleutgens/opt/anaconda3/envs/tgdp/lib/python3.9/site-packages/wandb/sdk/lib/sock_client.py", line 130, in _sendall_with_error_handle
    sent = self._sock.send(data)
BrokenPipeError: [Errno 32] Broken pipe
2025-05-27 10:58:08,384 ERROR   MainThread:63695 [redirect.py:_on_write():664] [no run ID] error in stderr callback
Traceback (most recent call last):
  File "/Users/juliankleutgens/PycharmProjects/ratio_estimation_synthetic/main2.py", line 463, in <module>
    if __name__ == "__main__":
  File "/Users/juliankleutgens/PycharmProjects/ratio_estimation_synthetic/main2.py", line 210, in main
    if not config.skip_ratio_estimator_on_clean_data or not config.unguided_sampling:
  File "/Users/juliankleutgens/PycharmProjects/ratio_estimation_synthetic/training.py", line 111, in train_domain_classifier
    optimizer.step()
  File "/Users/juliankleutgens/opt/anaconda3/envs/tgdp/lib/python3.9/site-packages/torch/optim/optimizer.py", line 487, in wrapper
    out = func(*args, **kwargs)
  File "/Users/juliankleutgens/opt/anaconda3/envs/tgdp/lib/python3.9/site-packages/torch/optim/optimizer.py", line 91, in _use_grad
    ret = func(self, *args, **kwargs)
  File "/Users/juliankleutgens/opt/anaconda3/envs/tgdp/lib/python3.9/site-packages/torch/optim/adam.py", line 223, in step
    adam(
  File "/Users/juliankleutgens/opt/anaconda3/envs/tgdp/lib/python3.9/site-packages/torch/optim/optimizer.py", line 154, in maybe_fallback
    return func(*args, **kwargs)
  File "/Users/juliankleutgens/opt/anaconda3/envs/tgdp/lib/python3.9/site-packages/torch/optim/adam.py", line 784, in adam
    func(
  File "/Users/juliankleutgens/opt/anaconda3/envs/tgdp/lib/python3.9/site-packages/torch/optim/adam.py", line 381, in _single_tensor_adam
    if capturable or differentiable:
  File "/Users/juliankleutgens/opt/anaconda3/envs/tgdp/lib/python3.9/site-packages/torch/optim/adam.py", line 381, in _single_tensor_adam
    if capturable or differentiable:
  File "/Applications/PyCharm.app/Contents/plugins/python/helpers/pydev/_pydevd_bundle/pydevd_trace_dispatch.py", line 89, in trace_dispatch
    def trace_dispatch(py_db, frame, event, arg):
  File "_pydevd_bundle/pydevd_cython_darwin_39_64.pyx", line 1337, in _pydevd_bundle.pydevd_cython_darwin_39_64.trace_dispatch
  File "_pydevd_bundle/pydevd_cython_darwin_39_64.pyx", line 1597, in _pydevd_bundle.pydevd_cython_darwin_39_64.ThreadTracer.__call__
  File "_pydevd_bundle/pydevd_cython_darwin_39_64.pyx", line 937, in _pydevd_bundle.pydevd_cython_darwin_39_64.PyDBFrame.trace_dispatch
  File "_pydevd_bundle/pydevd_cython_darwin_39_64.pyx", line 928, in _pydevd_bundle.pydevd_cython_darwin_39_64.PyDBFrame.trace_dispatch
  File "_pydevd_bundle/pydevd_cython_darwin_39_64.pyx", line 585, in _pydevd_bundle.pydevd_cython_darwin_39_64.PyDBFrame.do_wait_suspend
  File "/Applications/PyCharm.app/Contents/plugins/python/helpers/pydev/pydevd.py", line 1185, in do_wait_suspend
    self._do_wait_suspend(thread, frame, event, arg, suspend_type, from_this_thread)
  File "/Applications/PyCharm.app/Contents/plugins/python/helpers/pydev/pydevd.py", line 1200, in _do_wait_suspend
    time.sleep(0.01)
KeyboardInterrupt

During handling of the above exception, another exception occurred:

Traceback (most recent call last):
  File "/Users/juliankleutgens/opt/anaconda3/envs/tgdp/lib/python3.9/site-packages/wandb/sdk/lib/redirect.py", line 662, in _on_write
    cb(written_data)
  File "/Users/juliankleutgens/opt/anaconda3/envs/tgdp/lib/python3.9/site-packages/wandb/sdk/wandb_run.py", line 2500, in <lambda>
    lambda data: self._console_raw_callback("stderr", data),
  File "/Users/juliankleutgens/opt/anaconda3/envs/tgdp/lib/python3.9/site-packages/wandb/sdk/wandb_run.py", line 406, in wrapper
    return func(self, *args, **kwargs)
  File "/Users/juliankleutgens/opt/anaconda3/envs/tgdp/lib/python3.9/site-packages/wandb/sdk/wandb_run.py", line 464, in wrapper_fn
    return func(self, *args, **kwargs)
  File "/Users/juliankleutgens/opt/anaconda3/envs/tgdp/lib/python3.9/site-packages/wandb/sdk/wandb_run.py", line 1639, in _console_raw_callback
    self._backend.interface.publish_output_raw(name, data)
  File "/Users/juliankleutgens/opt/anaconda3/envs/tgdp/lib/python3.9/site-packages/wandb/sdk/interface/interface.py", line 762, in publish_output_raw
    self._publish_output_raw(o)
  File "/Users/juliankleutgens/opt/anaconda3/envs/tgdp/lib/python3.9/site-packages/wandb/sdk/interface/interface_shared.py", line 38, in _publish_output_raw
    self._publish(rec)
  File "/Users/juliankleutgens/opt/anaconda3/envs/tgdp/lib/python3.9/site-packages/wandb/sdk/interface/interface_sock.py", line 39, in _publish
    self._sock_client.send_record_publish(record)
  File "/Users/juliankleutgens/opt/anaconda3/envs/tgdp/lib/python3.9/site-packages/wandb/sdk/lib/sock_client.py", line 174, in send_record_publish
    self.send_server_request(server_req)
  File "/Users/juliankleutgens/opt/anaconda3/envs/tgdp/lib/python3.9/site-packages/wandb/sdk/lib/sock_client.py", line 154, in send_server_request
    self._send_message(msg)
  File "/Users/juliankleutgens/opt/anaconda3/envs/tgdp/lib/python3.9/site-packages/wandb/sdk/lib/sock_client.py", line 151, in _send_message
    self._sendall_with_error_handle(header + data)
  File "/Users/juliankleutgens/opt/anaconda3/envs/tgdp/lib/python3.9/site-packages/wandb/sdk/lib/sock_client.py", line 130, in _sendall_with_error_handle
    sent = self._sock.send(data)
BrokenPipeError: [Errno 32] Broken pipe
2025-05-27 10:58:08,384 ERROR   MainThread:63695 [redirect.py:_on_write():664] [no run ID] error in stderr callback
Traceback (most recent call last):
  File "/Users/juliankleutgens/PycharmProjects/ratio_estimation_synthetic/main2.py", line 463, in <module>
    if __name__ == "__main__":
  File "/Users/juliankleutgens/PycharmProjects/ratio_estimation_synthetic/main2.py", line 210, in main
    if not config.skip_ratio_estimator_on_clean_data or not config.unguided_sampling:
  File "/Users/juliankleutgens/PycharmProjects/ratio_estimation_synthetic/training.py", line 111, in train_domain_classifier
    optimizer.step()
  File "/Users/juliankleutgens/opt/anaconda3/envs/tgdp/lib/python3.9/site-packages/torch/optim/optimizer.py", line 487, in wrapper
    out = func(*args, **kwargs)
  File "/Users/juliankleutgens/opt/anaconda3/envs/tgdp/lib/python3.9/site-packages/torch/optim/optimizer.py", line 91, in _use_grad
    ret = func(self, *args, **kwargs)
  File "/Users/juliankleutgens/opt/anaconda3/envs/tgdp/lib/python3.9/site-packages/torch/optim/adam.py", line 223, in step
    adam(
  File "/Users/juliankleutgens/opt/anaconda3/envs/tgdp/lib/python3.9/site-packages/torch/optim/optimizer.py", line 154, in maybe_fallback
    return func(*args, **kwargs)
  File "/Users/juliankleutgens/opt/anaconda3/envs/tgdp/lib/python3.9/site-packages/torch/optim/adam.py", line 784, in adam
    func(
  File "/Users/juliankleutgens/opt/anaconda3/envs/tgdp/lib/python3.9/site-packages/torch/optim/adam.py", line 381, in _single_tensor_adam
    if capturable or differentiable:
  File "/Users/juliankleutgens/opt/anaconda3/envs/tgdp/lib/python3.9/site-packages/torch/optim/adam.py", line 381, in _single_tensor_adam
    if capturable or differentiable:
  File "/Applications/PyCharm.app/Contents/plugins/python/helpers/pydev/_pydevd_bundle/pydevd_trace_dispatch.py", line 89, in trace_dispatch
    def trace_dispatch(py_db, frame, event, arg):
  File "_pydevd_bundle/pydevd_cython_darwin_39_64.pyx", line 1337, in _pydevd_bundle.pydevd_cython_darwin_39_64.trace_dispatch
  File "_pydevd_bundle/pydevd_cython_darwin_39_64.pyx", line 1597, in _pydevd_bundle.pydevd_cython_darwin_39_64.ThreadTracer.__call__
  File "_pydevd_bundle/pydevd_cython_darwin_39_64.pyx", line 937, in _pydevd_bundle.pydevd_cython_darwin_39_64.PyDBFrame.trace_dispatch
  File "_pydevd_bundle/pydevd_cython_darwin_39_64.pyx", line 928, in _pydevd_bundle.pydevd_cython_darwin_39_64.PyDBFrame.trace_dispatch
  File "_pydevd_bundle/pydevd_cython_darwin_39_64.pyx", line 585, in _pydevd_bundle.pydevd_cython_darwin_39_64.PyDBFrame.do_wait_suspend
  File "/Applications/PyCharm.app/Contents/plugins/python/helpers/pydev/pydevd.py", line 1185, in do_wait_suspend
    self._do_wait_suspend(thread, frame, event, arg, suspend_type, from_this_thread)
  File "/Applications/PyCharm.app/Contents/plugins/python/helpers/pydev/pydevd.py", line 1200, in _do_wait_suspend
    time.sleep(0.01)
KeyboardInterrupt

During handling of the above exception, another exception occurred:

Traceback (most recent call last):
  File "/Users/juliankleutgens/opt/anaconda3/envs/tgdp/lib/python3.9/site-packages/wandb/sdk/lib/redirect.py", line 662, in _on_write
    cb(written_data)
  File "/Users/juliankleutgens/opt/anaconda3/envs/tgdp/lib/python3.9/site-packages/wandb/sdk/wandb_run.py", line 2500, in <lambda>
    lambda data: self._console_raw_callback("stderr", data),
  File "/Users/juliankleutgens/opt/anaconda3/envs/tgdp/lib/python3.9/site-packages/wandb/sdk/wandb_run.py", line 406, in wrapper
    return func(self, *args, **kwargs)
  File "/Users/juliankleutgens/opt/anaconda3/envs/tgdp/lib/python3.9/site-packages/wandb/sdk/wandb_run.py", line 464, in wrapper_fn
    return func(self, *args, **kwargs)
  File "/Users/juliankleutgens/opt/anaconda3/envs/tgdp/lib/python3.9/site-packages/wandb/sdk/wandb_run.py", line 1639, in _console_raw_callback
    self._backend.interface.publish_output_raw(name, data)
  File "/Users/juliankleutgens/opt/anaconda3/envs/tgdp/lib/python3.9/site-packages/wandb/sdk/interface/interface.py", line 762, in publish_output_raw
    self._publish_output_raw(o)
  File "/Users/juliankleutgens/opt/anaconda3/envs/tgdp/lib/python3.9/site-packages/wandb/sdk/interface/interface_shared.py", line 38, in _publish_output_raw
    self._publish(rec)
  File "/Users/juliankleutgens/opt/anaconda3/envs/tgdp/lib/python3.9/site-packages/wandb/sdk/interface/interface_sock.py", line 39, in _publish
    self._sock_client.send_record_publish(record)
  File "/Users/juliankleutgens/opt/anaconda3/envs/tgdp/lib/python3.9/site-packages/wandb/sdk/lib/sock_client.py", line 174, in send_record_publish
    self.send_server_request(server_req)
  File "/Users/juliankleutgens/opt/anaconda3/envs/tgdp/lib/python3.9/site-packages/wandb/sdk/lib/sock_client.py", line 154, in send_server_request
    self._send_message(msg)
  File "/Users/juliankleutgens/opt/anaconda3/envs/tgdp/lib/python3.9/site-packages/wandb/sdk/lib/sock_client.py", line 151, in _send_message
    self._sendall_with_error_handle(header + data)
  File "/Users/juliankleutgens/opt/anaconda3/envs/tgdp/lib/python3.9/site-packages/wandb/sdk/lib/sock_client.py", line 130, in _sendall_with_error_handle
    sent = self._sock.send(data)
BrokenPipeError: [Errno 32] Broken pipe
2025-05-27 10:58:08,385 ERROR   MainThread:63695 [redirect.py:_on_write():664] [no run ID] error in stderr callback
Traceback (most recent call last):
  File "/Users/juliankleutgens/PycharmProjects/ratio_estimation_synthetic/main2.py", line 463, in <module>
    if __name__ == "__main__":
  File "/Users/juliankleutgens/PycharmProjects/ratio_estimation_synthetic/main2.py", line 210, in main
    if not config.skip_ratio_estimator_on_clean_data or not config.unguided_sampling:
  File "/Users/juliankleutgens/PycharmProjects/ratio_estimation_synthetic/training.py", line 111, in train_domain_classifier
    optimizer.step()
  File "/Users/juliankleutgens/opt/anaconda3/envs/tgdp/lib/python3.9/site-packages/torch/optim/optimizer.py", line 487, in wrapper
    out = func(*args, **kwargs)
  File "/Users/juliankleutgens/opt/anaconda3/envs/tgdp/lib/python3.9/site-packages/torch/optim/optimizer.py", line 91, in _use_grad
    ret = func(self, *args, **kwargs)
  File "/Users/juliankleutgens/opt/anaconda3/envs/tgdp/lib/python3.9/site-packages/torch/optim/adam.py", line 223, in step
    adam(
  File "/Users/juliankleutgens/opt/anaconda3/envs/tgdp/lib/python3.9/site-packages/torch/optim/optimizer.py", line 154, in maybe_fallback
    return func(*args, **kwargs)
  File "/Users/juliankleutgens/opt/anaconda3/envs/tgdp/lib/python3.9/site-packages/torch/optim/adam.py", line 784, in adam
    func(
  File "/Users/juliankleutgens/opt/anaconda3/envs/tgdp/lib/python3.9/site-packages/torch/optim/adam.py", line 381, in _single_tensor_adam
    if capturable or differentiable:
  File "/Users/juliankleutgens/opt/anaconda3/envs/tgdp/lib/python3.9/site-packages/torch/optim/adam.py", line 381, in _single_tensor_adam
    if capturable or differentiable:
  File "/Applications/PyCharm.app/Contents/plugins/python/helpers/pydev/_pydevd_bundle/pydevd_trace_dispatch.py", line 89, in trace_dispatch
    def trace_dispatch(py_db, frame, event, arg):
  File "_pydevd_bundle/pydevd_cython_darwin_39_64.pyx", line 1337, in _pydevd_bundle.pydevd_cython_darwin_39_64.trace_dispatch
  File "_pydevd_bundle/pydevd_cython_darwin_39_64.pyx", line 1597, in _pydevd_bundle.pydevd_cython_darwin_39_64.ThreadTracer.__call__
  File "_pydevd_bundle/pydevd_cython_darwin_39_64.pyx", line 937, in _pydevd_bundle.pydevd_cython_darwin_39_64.PyDBFrame.trace_dispatch
  File "_pydevd_bundle/pydevd_cython_darwin_39_64.pyx", line 928, in _pydevd_bundle.pydevd_cython_darwin_39_64.PyDBFrame.trace_dispatch
  File "_pydevd_bundle/pydevd_cython_darwin_39_64.pyx", line 585, in _pydevd_bundle.pydevd_cython_darwin_39_64.PyDBFrame.do_wait_suspend
  File "/Applications/PyCharm.app/Contents/plugins/python/helpers/pydev/pydevd.py", line 1185, in do_wait_suspend
    self._do_wait_suspend(thread, frame, event, arg, suspend_type, from_this_thread)
  File "/Applications/PyCharm.app/Contents/plugins/python/helpers/pydev/pydevd.py", line 1200, in _do_wait_suspend
    time.sleep(0.01)
KeyboardInterrupt

During handling of the above exception, another exception occurred:

Traceback (most recent call last):
  File "/Users/juliankleutgens/opt/anaconda3/envs/tgdp/lib/python3.9/site-packages/wandb/sdk/lib/redirect.py", line 662, in _on_write
    cb(written_data)
  File "/Users/juliankleutgens/opt/anaconda3/envs/tgdp/lib/python3.9/site-packages/wandb/sdk/wandb_run.py", line 2500, in <lambda>
    lambda data: self._console_raw_callback("stderr", data),
  File "/Users/juliankleutgens/opt/anaconda3/envs/tgdp/lib/python3.9/site-packages/wandb/sdk/wandb_run.py", line 406, in wrapper
    return func(self, *args, **kwargs)
  File "/Users/juliankleutgens/opt/anaconda3/envs/tgdp/lib/python3.9/site-packages/wandb/sdk/wandb_run.py", line 464, in wrapper_fn
    return func(self, *args, **kwargs)
  File "/Users/juliankleutgens/opt/anaconda3/envs/tgdp/lib/python3.9/site-packages/wandb/sdk/wandb_run.py", line 1639, in _console_raw_callback
    self._backend.interface.publish_output_raw(name, data)
  File "/Users/juliankleutgens/opt/anaconda3/envs/tgdp/lib/python3.9/site-packages/wandb/sdk/interface/interface.py", line 762, in publish_output_raw
    self._publish_output_raw(o)
  File "/Users/juliankleutgens/opt/anaconda3/envs/tgdp/lib/python3.9/site-packages/wandb/sdk/interface/interface_shared.py", line 38, in _publish_output_raw
    self._publish(rec)
  File "/Users/juliankleutgens/opt/anaconda3/envs/tgdp/lib/python3.9/site-packages/wandb/sdk/interface/interface_sock.py", line 39, in _publish
    self._sock_client.send_record_publish(record)
  File "/Users/juliankleutgens/opt/anaconda3/envs/tgdp/lib/python3.9/site-packages/wandb/sdk/lib/sock_client.py", line 174, in send_record_publish
    self.send_server_request(server_req)
  File "/Users/juliankleutgens/opt/anaconda3/envs/tgdp/lib/python3.9/site-packages/wandb/sdk/lib/sock_client.py", line 154, in send_server_request
    self._send_message(msg)
  File "/Users/juliankleutgens/opt/anaconda3/envs/tgdp/lib/python3.9/site-packages/wandb/sdk/lib/sock_client.py", line 151, in _send_message
    self._sendall_with_error_handle(header + data)
  File "/Users/juliankleutgens/opt/anaconda3/envs/tgdp/lib/python3.9/site-packages/wandb/sdk/lib/sock_client.py", line 130, in _sendall_with_error_handle
    sent = self._sock.send(data)
BrokenPipeError: [Errno 32] Broken pipe
2025-05-27 10:58:08,385 ERROR   MainThread:63695 [redirect.py:_on_write():664] [no run ID] error in stderr callback
Traceback (most recent call last):
  File "/Users/juliankleutgens/PycharmProjects/ratio_estimation_synthetic/main2.py", line 463, in <module>
    if __name__ == "__main__":
  File "/Users/juliankleutgens/PycharmProjects/ratio_estimation_synthetic/main2.py", line 210, in main
    if not config.skip_ratio_estimator_on_clean_data or not config.unguided_sampling:
  File "/Users/juliankleutgens/PycharmProjects/ratio_estimation_synthetic/training.py", line 111, in train_domain_classifier
    optimizer.step()
  File "/Users/juliankleutgens/opt/anaconda3/envs/tgdp/lib/python3.9/site-packages/torch/optim/optimizer.py", line 487, in wrapper
    out = func(*args, **kwargs)
  File "/Users/juliankleutgens/opt/anaconda3/envs/tgdp/lib/python3.9/site-packages/torch/optim/optimizer.py", line 91, in _use_grad
    ret = func(self, *args, **kwargs)
  File "/Users/juliankleutgens/opt/anaconda3/envs/tgdp/lib/python3.9/site-packages/torch/optim/adam.py", line 223, in step
    adam(
  File "/Users/juliankleutgens/opt/anaconda3/envs/tgdp/lib/python3.9/site-packages/torch/optim/optimizer.py", line 154, in maybe_fallback
    return func(*args, **kwargs)
  File "/Users/juliankleutgens/opt/anaconda3/envs/tgdp/lib/python3.9/site-packages/torch/optim/adam.py", line 784, in adam
    func(
  File "/Users/juliankleutgens/opt/anaconda3/envs/tgdp/lib/python3.9/site-packages/torch/optim/adam.py", line 381, in _single_tensor_adam
    if capturable or differentiable:
  File "/Users/juliankleutgens/opt/anaconda3/envs/tgdp/lib/python3.9/site-packages/torch/optim/adam.py", line 381, in _single_tensor_adam
    if capturable or differentiable:
  File "/Applications/PyCharm.app/Contents/plugins/python/helpers/pydev/_pydevd_bundle/pydevd_trace_dispatch.py", line 89, in trace_dispatch
    def trace_dispatch(py_db, frame, event, arg):
  File "_pydevd_bundle/pydevd_cython_darwin_39_64.pyx", line 1337, in _pydevd_bundle.pydevd_cython_darwin_39_64.trace_dispatch
  File "_pydevd_bundle/pydevd_cython_darwin_39_64.pyx", line 1597, in _pydevd_bundle.pydevd_cython_darwin_39_64.ThreadTracer.__call__
  File "_pydevd_bundle/pydevd_cython_darwin_39_64.pyx", line 937, in _pydevd_bundle.pydevd_cython_darwin_39_64.PyDBFrame.trace_dispatch
  File "_pydevd_bundle/pydevd_cython_darwin_39_64.pyx", line 928, in _pydevd_bundle.pydevd_cython_darwin_39_64.PyDBFrame.trace_dispatch
  File "_pydevd_bundle/pydevd_cython_darwin_39_64.pyx", line 585, in _pydevd_bundle.pydevd_cython_darwin_39_64.PyDBFrame.do_wait_suspend
  File "/Applications/PyCharm.app/Contents/plugins/python/helpers/pydev/pydevd.py", line 1185, in do_wait_suspend
    self._do_wait_suspend(thread, frame, event, arg, suspend_type, from_this_thread)
  File "/Applications/PyCharm.app/Contents/plugins/python/helpers/pydev/pydevd.py", line 1200, in _do_wait_suspend
    time.sleep(0.01)
KeyboardInterrupt

During handling of the above exception, another exception occurred:

Traceback (most recent call last):
  File "/Users/juliankleutgens/opt/anaconda3/envs/tgdp/lib/python3.9/site-packages/wandb/sdk/lib/redirect.py", line 662, in _on_write
    cb(written_data)
  File "/Users/juliankleutgens/opt/anaconda3/envs/tgdp/lib/python3.9/site-packages/wandb/sdk/wandb_run.py", line 2500, in <lambda>
    lambda data: self._console_raw_callback("stderr", data),
  File "/Users/juliankleutgens/opt/anaconda3/envs/tgdp/lib/python3.9/site-packages/wandb/sdk/wandb_run.py", line 406, in wrapper
    return func(self, *args, **kwargs)
  File "/Users/juliankleutgens/opt/anaconda3/envs/tgdp/lib/python3.9/site-packages/wandb/sdk/wandb_run.py", line 464, in wrapper_fn
    return func(self, *args, **kwargs)
  File "/Users/juliankleutgens/opt/anaconda3/envs/tgdp/lib/python3.9/site-packages/wandb/sdk/wandb_run.py", line 1639, in _console_raw_callback
    self._backend.interface.publish_output_raw(name, data)
  File "/Users/juliankleutgens/opt/anaconda3/envs/tgdp/lib/python3.9/site-packages/wandb/sdk/interface/interface.py", line 762, in publish_output_raw
    self._publish_output_raw(o)
  File "/Users/juliankleutgens/opt/anaconda3/envs/tgdp/lib/python3.9/site-packages/wandb/sdk/interface/interface_shared.py", line 38, in _publish_output_raw
    self._publish(rec)
  File "/Users/juliankleutgens/opt/anaconda3/envs/tgdp/lib/python3.9/site-packages/wandb/sdk/interface/interface_sock.py", line 39, in _publish
    self._sock_client.send_record_publish(record)
  File "/Users/juliankleutgens/opt/anaconda3/envs/tgdp/lib/python3.9/site-packages/wandb/sdk/lib/sock_client.py", line 174, in send_record_publish
    self.send_server_request(server_req)
  File "/Users/juliankleutgens/opt/anaconda3/envs/tgdp/lib/python3.9/site-packages/wandb/sdk/lib/sock_client.py", line 154, in send_server_request
    self._send_message(msg)
  File "/Users/juliankleutgens/opt/anaconda3/envs/tgdp/lib/python3.9/site-packages/wandb/sdk/lib/sock_client.py", line 151, in _send_message
    self._sendall_with_error_handle(header + data)
  File "/Users/juliankleutgens/opt/anaconda3/envs/tgdp/lib/python3.9/site-packages/wandb/sdk/lib/sock_client.py", line 130, in _sendall_with_error_handle
    sent = self._sock.send(data)
BrokenPipeError: [Errno 32] Broken pipe
2025-05-27 10:58:08,385 ERROR   MainThread:63695 [redirect.py:_on_write():664] [no run ID] error in stderr callback
Traceback (most recent call last):
  File "/Users/juliankleutgens/PycharmProjects/ratio_estimation_synthetic/main2.py", line 463, in <module>
    if __name__ == "__main__":
  File "/Users/juliankleutgens/PycharmProjects/ratio_estimation_synthetic/main2.py", line 210, in main
    if not config.skip_ratio_estimator_on_clean_data or not config.unguided_sampling:
  File "/Users/juliankleutgens/PycharmProjects/ratio_estimation_synthetic/training.py", line 111, in train_domain_classifier
    optimizer.step()
  File "/Users/juliankleutgens/opt/anaconda3/envs/tgdp/lib/python3.9/site-packages/torch/optim/optimizer.py", line 487, in wrapper
    out = func(*args, **kwargs)
  File "/Users/juliankleutgens/opt/anaconda3/envs/tgdp/lib/python3.9/site-packages/torch/optim/optimizer.py", line 91, in _use_grad
    ret = func(self, *args, **kwargs)
  File "/Users/juliankleutgens/opt/anaconda3/envs/tgdp/lib/python3.9/site-packages/torch/optim/adam.py", line 223, in step
    adam(
  File "/Users/juliankleutgens/opt/anaconda3/envs/tgdp/lib/python3.9/site-packages/torch/optim/optimizer.py", line 154, in maybe_fallback
    return func(*args, **kwargs)
  File "/Users/juliankleutgens/opt/anaconda3/envs/tgdp/lib/python3.9/site-packages/torch/optim/adam.py", line 784, in adam
    func(
  File "/Users/juliankleutgens/opt/anaconda3/envs/tgdp/lib/python3.9/site-packages/torch/optim/adam.py", line 381, in _single_tensor_adam
    if capturable or differentiable:
  File "/Users/juliankleutgens/opt/anaconda3/envs/tgdp/lib/python3.9/site-packages/torch/optim/adam.py", line 381, in _single_tensor_adam
    if capturable or differentiable:
  File "/Applications/PyCharm.app/Contents/plugins/python/helpers/pydev/_pydevd_bundle/pydevd_trace_dispatch.py", line 89, in trace_dispatch
    def trace_dispatch(py_db, frame, event, arg):
  File "_pydevd_bundle/pydevd_cython_darwin_39_64.pyx", line 1337, in _pydevd_bundle.pydevd_cython_darwin_39_64.trace_dispatch
  File "_pydevd_bundle/pydevd_cython_darwin_39_64.pyx", line 1597, in _pydevd_bundle.pydevd_cython_darwin_39_64.ThreadTracer.__call__
  File "_pydevd_bundle/pydevd_cython_darwin_39_64.pyx", line 937, in _pydevd_bundle.pydevd_cython_darwin_39_64.PyDBFrame.trace_dispatch
  File "_pydevd_bundle/pydevd_cython_darwin_39_64.pyx", line 928, in _pydevd_bundle.pydevd_cython_darwin_39_64.PyDBFrame.trace_dispatch
  File "_pydevd_bundle/pydevd_cython_darwin_39_64.pyx", line 585, in _pydevd_bundle.pydevd_cython_darwin_39_64.PyDBFrame.do_wait_suspend
  File "/Applications/PyCharm.app/Contents/plugins/python/helpers/pydev/pydevd.py", line 1185, in do_wait_suspend
    self._do_wait_suspend(thread, frame, event, arg, suspend_type, from_this_thread)
  File "/Applications/PyCharm.app/Contents/plugins/python/helpers/pydev/pydevd.py", line 1200, in _do_wait_suspend
    time.sleep(0.01)
KeyboardInterrupt

During handling of the above exception, another exception occurred:

Traceback (most recent call last):
  File "/Users/juliankleutgens/opt/anaconda3/envs/tgdp/lib/python3.9/site-packages/wandb/sdk/lib/redirect.py", line 662, in _on_write
    cb(written_data)
  File "/Users/juliankleutgens/opt/anaconda3/envs/tgdp/lib/python3.9/site-packages/wandb/sdk/wandb_run.py", line 2500, in <lambda>
    lambda data: self._console_raw_callback("stderr", data),
  File "/Users/juliankleutgens/opt/anaconda3/envs/tgdp/lib/python3.9/site-packages/wandb/sdk/wandb_run.py", line 406, in wrapper
    return func(self, *args, **kwargs)
  File "/Users/juliankleutgens/opt/anaconda3/envs/tgdp/lib/python3.9/site-packages/wandb/sdk/wandb_run.py", line 464, in wrapper_fn
    return func(self, *args, **kwargs)
  File "/Users/juliankleutgens/opt/anaconda3/envs/tgdp/lib/python3.9/site-packages/wandb/sdk/wandb_run.py", line 1639, in _console_raw_callback
    self._backend.interface.publish_output_raw(name, data)
  File "/Users/juliankleutgens/opt/anaconda3/envs/tgdp/lib/python3.9/site-packages/wandb/sdk/interface/interface.py", line 762, in publish_output_raw
    self._publish_output_raw(o)
  File "/Users/juliankleutgens/opt/anaconda3/envs/tgdp/lib/python3.9/site-packages/wandb/sdk/interface/interface_shared.py", line 38, in _publish_output_raw
    self._publish(rec)
  File "/Users/juliankleutgens/opt/anaconda3/envs/tgdp/lib/python3.9/site-packages/wandb/sdk/interface/interface_sock.py", line 39, in _publish
    self._sock_client.send_record_publish(record)
  File "/Users/juliankleutgens/opt/anaconda3/envs/tgdp/lib/python3.9/site-packages/wandb/sdk/lib/sock_client.py", line 174, in send_record_publish
    self.send_server_request(server_req)
  File "/Users/juliankleutgens/opt/anaconda3/envs/tgdp/lib/python3.9/site-packages/wandb/sdk/lib/sock_client.py", line 154, in send_server_request
    self._send_message(msg)
  File "/Users/juliankleutgens/opt/anaconda3/envs/tgdp/lib/python3.9/site-packages/wandb/sdk/lib/sock_client.py", line 151, in _send_message
    self._sendall_with_error_handle(header + data)
  File "/Users/juliankleutgens/opt/anaconda3/envs/tgdp/lib/python3.9/site-packages/wandb/sdk/lib/sock_client.py", line 130, in _sendall_with_error_handle
    sent = self._sock.send(data)
BrokenPipeError: [Errno 32] Broken pipe
2025-05-27 10:58:08,385 ERROR   MainThread:63695 [redirect.py:_on_write():664] [no run ID] error in stderr callback
Traceback (most recent call last):
  File "/Users/juliankleutgens/PycharmProjects/ratio_estimation_synthetic/main2.py", line 463, in <module>
    if __name__ == "__main__":
  File "/Users/juliankleutgens/PycharmProjects/ratio_estimation_synthetic/main2.py", line 210, in main
    if not config.skip_ratio_estimator_on_clean_data or not config.unguided_sampling:
  File "/Users/juliankleutgens/PycharmProjects/ratio_estimation_synthetic/training.py", line 111, in train_domain_classifier
    optimizer.step()
  File "/Users/juliankleutgens/opt/anaconda3/envs/tgdp/lib/python3.9/site-packages/torch/optim/optimizer.py", line 487, in wrapper
    out = func(*args, **kwargs)
  File "/Users/juliankleutgens/opt/anaconda3/envs/tgdp/lib/python3.9/site-packages/torch/optim/optimizer.py", line 91, in _use_grad
    ret = func(self, *args, **kwargs)
  File "/Users/juliankleutgens/opt/anaconda3/envs/tgdp/lib/python3.9/site-packages/torch/optim/adam.py", line 223, in step
    adam(
  File "/Users/juliankleutgens/opt/anaconda3/envs/tgdp/lib/python3.9/site-packages/torch/optim/optimizer.py", line 154, in maybe_fallback
    return func(*args, **kwargs)
  File "/Users/juliankleutgens/opt/anaconda3/envs/tgdp/lib/python3.9/site-packages/torch/optim/adam.py", line 784, in adam
    func(
  File "/Users/juliankleutgens/opt/anaconda3/envs/tgdp/lib/python3.9/site-packages/torch/optim/adam.py", line 381, in _single_tensor_adam
    if capturable or differentiable:
  File "/Users/juliankleutgens/opt/anaconda3/envs/tgdp/lib/python3.9/site-packages/torch/optim/adam.py", line 381, in _single_tensor_adam
    if capturable or differentiable:
  File "/Applications/PyCharm.app/Contents/plugins/python/helpers/pydev/_pydevd_bundle/pydevd_trace_dispatch.py", line 89, in trace_dispatch
    def trace_dispatch(py_db, frame, event, arg):
  File "_pydevd_bundle/pydevd_cython_darwin_39_64.pyx", line 1337, in _pydevd_bundle.pydevd_cython_darwin_39_64.trace_dispatch
  File "_pydevd_bundle/pydevd_cython_darwin_39_64.pyx", line 1597, in _pydevd_bundle.pydevd_cython_darwin_39_64.ThreadTracer.__call__
  File "_pydevd_bundle/pydevd_cython_darwin_39_64.pyx", line 937, in _pydevd_bundle.pydevd_cython_darwin_39_64.PyDBFrame.trace_dispatch
  File "_pydevd_bundle/pydevd_cython_darwin_39_64.pyx", line 928, in _pydevd_bundle.pydevd_cython_darwin_39_64.PyDBFrame.trace_dispatch
  File "_pydevd_bundle/pydevd_cython_darwin_39_64.pyx", line 585, in _pydevd_bundle.pydevd_cython_darwin_39_64.PyDBFrame.do_wait_suspend
  File "/Applications/PyCharm.app/Contents/plugins/python/helpers/pydev/pydevd.py", line 1185, in do_wait_suspend
    self._do_wait_suspend(thread, frame, event, arg, suspend_type, from_this_thread)
  File "/Applications/PyCharm.app/Contents/plugins/python/helpers/pydev/pydevd.py", line 1200, in _do_wait_suspend
    time.sleep(0.01)
KeyboardInterrupt

During handling of the above exception, another exception occurred:

Traceback (most recent call last):
  File "/Users/juliankleutgens/opt/anaconda3/envs/tgdp/lib/python3.9/site-packages/wandb/sdk/lib/redirect.py", line 662, in _on_write
    cb(written_data)
  File "/Users/juliankleutgens/opt/anaconda3/envs/tgdp/lib/python3.9/site-packages/wandb/sdk/wandb_run.py", line 2500, in <lambda>
    lambda data: self._console_raw_callback("stderr", data),
  File "/Users/juliankleutgens/opt/anaconda3/envs/tgdp/lib/python3.9/site-packages/wandb/sdk/wandb_run.py", line 406, in wrapper
    return func(self, *args, **kwargs)
  File "/Users/juliankleutgens/opt/anaconda3/envs/tgdp/lib/python3.9/site-packages/wandb/sdk/wandb_run.py", line 464, in wrapper_fn
    return func(self, *args, **kwargs)
  File "/Users/juliankleutgens/opt/anaconda3/envs/tgdp/lib/python3.9/site-packages/wandb/sdk/wandb_run.py", line 1639, in _console_raw_callback
    self._backend.interface.publish_output_raw(name, data)
  File "/Users/juliankleutgens/opt/anaconda3/envs/tgdp/lib/python3.9/site-packages/wandb/sdk/interface/interface.py", line 762, in publish_output_raw
    self._publish_output_raw(o)
  File "/Users/juliankleutgens/opt/anaconda3/envs/tgdp/lib/python3.9/site-packages/wandb/sdk/interface/interface_shared.py", line 38, in _publish_output_raw
    self._publish(rec)
  File "/Users/juliankleutgens/opt/anaconda3/envs/tgdp/lib/python3.9/site-packages/wandb/sdk/interface/interface_sock.py", line 39, in _publish
    self._sock_client.send_record_publish(record)
  File "/Users/juliankleutgens/opt/anaconda3/envs/tgdp/lib/python3.9/site-packages/wandb/sdk/lib/sock_client.py", line 174, in send_record_publish
    self.send_server_request(server_req)
  File "/Users/juliankleutgens/opt/anaconda3/envs/tgdp/lib/python3.9/site-packages/wandb/sdk/lib/sock_client.py", line 154, in send_server_request
    self._send_message(msg)
  File "/Users/juliankleutgens/opt/anaconda3/envs/tgdp/lib/python3.9/site-packages/wandb/sdk/lib/sock_client.py", line 151, in _send_message
    self._sendall_with_error_handle(header + data)
  File "/Users/juliankleutgens/opt/anaconda3/envs/tgdp/lib/python3.9/site-packages/wandb/sdk/lib/sock_client.py", line 130, in _sendall_with_error_handle
    sent = self._sock.send(data)
BrokenPipeError: [Errno 32] Broken pipe
2025-05-27 10:58:08,386 ERROR   MainThread:63695 [redirect.py:_on_write():664] [no run ID] error in stderr callback
Traceback (most recent call last):
  File "/Users/juliankleutgens/PycharmProjects/ratio_estimation_synthetic/main2.py", line 463, in <module>
    if __name__ == "__main__":
  File "/Users/juliankleutgens/PycharmProjects/ratio_estimation_synthetic/main2.py", line 210, in main
    if not config.skip_ratio_estimator_on_clean_data or not config.unguided_sampling:
  File "/Users/juliankleutgens/PycharmProjects/ratio_estimation_synthetic/training.py", line 111, in train_domain_classifier
    optimizer.step()
  File "/Users/juliankleutgens/opt/anaconda3/envs/tgdp/lib/python3.9/site-packages/torch/optim/optimizer.py", line 487, in wrapper
    out = func(*args, **kwargs)
  File "/Users/juliankleutgens/opt/anaconda3/envs/tgdp/lib/python3.9/site-packages/torch/optim/optimizer.py", line 91, in _use_grad
    ret = func(self, *args, **kwargs)
  File "/Users/juliankleutgens/opt/anaconda3/envs/tgdp/lib/python3.9/site-packages/torch/optim/adam.py", line 223, in step
    adam(
  File "/Users/juliankleutgens/opt/anaconda3/envs/tgdp/lib/python3.9/site-packages/torch/optim/optimizer.py", line 154, in maybe_fallback
    return func(*args, **kwargs)
  File "/Users/juliankleutgens/opt/anaconda3/envs/tgdp/lib/python3.9/site-packages/torch/optim/adam.py", line 784, in adam
    func(
  File "/Users/juliankleutgens/opt/anaconda3/envs/tgdp/lib/python3.9/site-packages/torch/optim/adam.py", line 381, in _single_tensor_adam
    if capturable or differentiable:
  File "/Users/juliankleutgens/opt/anaconda3/envs/tgdp/lib/python3.9/site-packages/torch/optim/adam.py", line 381, in _single_tensor_adam
    if capturable or differentiable:
  File "/Applications/PyCharm.app/Contents/plugins/python/helpers/pydev/_pydevd_bundle/pydevd_trace_dispatch.py", line 89, in trace_dispatch
    def trace_dispatch(py_db, frame, event, arg):
  File "_pydevd_bundle/pydevd_cython_darwin_39_64.pyx", line 1337, in _pydevd_bundle.pydevd_cython_darwin_39_64.trace_dispatch
  File "_pydevd_bundle/pydevd_cython_darwin_39_64.pyx", line 1597, in _pydevd_bundle.pydevd_cython_darwin_39_64.ThreadTracer.__call__
  File "_pydevd_bundle/pydevd_cython_darwin_39_64.pyx", line 937, in _pydevd_bundle.pydevd_cython_darwin_39_64.PyDBFrame.trace_dispatch
  File "_pydevd_bundle/pydevd_cython_darwin_39_64.pyx", line 928, in _pydevd_bundle.pydevd_cython_darwin_39_64.PyDBFrame.trace_dispatch
  File "_pydevd_bundle/pydevd_cython_darwin_39_64.pyx", line 585, in _pydevd_bundle.pydevd_cython_darwin_39_64.PyDBFrame.do_wait_suspend
  File "/Applications/PyCharm.app/Contents/plugins/python/helpers/pydev/pydevd.py", line 1185, in do_wait_suspend
    self._do_wait_suspend(thread, frame, event, arg, suspend_type, from_this_thread)
  File "/Applications/PyCharm.app/Contents/plugins/python/helpers/pydev/pydevd.py", line 1200, in _do_wait_suspend
    time.sleep(0.01)
KeyboardInterrupt

During handling of the above exception, another exception occurred:

Traceback (most recent call last):
  File "/Users/juliankleutgens/opt/anaconda3/envs/tgdp/lib/python3.9/site-packages/wandb/sdk/lib/redirect.py", line 662, in _on_write
    cb(written_data)
  File "/Users/juliankleutgens/opt/anaconda3/envs/tgdp/lib/python3.9/site-packages/wandb/sdk/wandb_run.py", line 2500, in <lambda>
    lambda data: self._console_raw_callback("stderr", data),
  File "/Users/juliankleutgens/opt/anaconda3/envs/tgdp/lib/python3.9/site-packages/wandb/sdk/wandb_run.py", line 406, in wrapper
    return func(self, *args, **kwargs)
  File "/Users/juliankleutgens/opt/anaconda3/envs/tgdp/lib/python3.9/site-packages/wandb/sdk/wandb_run.py", line 464, in wrapper_fn
    return func(self, *args, **kwargs)
  File "/Users/juliankleutgens/opt/anaconda3/envs/tgdp/lib/python3.9/site-packages/wandb/sdk/wandb_run.py", line 1639, in _console_raw_callback
    self._backend.interface.publish_output_raw(name, data)
  File "/Users/juliankleutgens/opt/anaconda3/envs/tgdp/lib/python3.9/site-packages/wandb/sdk/interface/interface.py", line 762, in publish_output_raw
    self._publish_output_raw(o)
  File "/Users/juliankleutgens/opt/anaconda3/envs/tgdp/lib/python3.9/site-packages/wandb/sdk/interface/interface_shared.py", line 38, in _publish_output_raw
    self._publish(rec)
  File "/Users/juliankleutgens/opt/anaconda3/envs/tgdp/lib/python3.9/site-packages/wandb/sdk/interface/interface_sock.py", line 39, in _publish
    self._sock_client.send_record_publish(record)
  File "/Users/juliankleutgens/opt/anaconda3/envs/tgdp/lib/python3.9/site-packages/wandb/sdk/lib/sock_client.py", line 174, in send_record_publish
    self.send_server_request(server_req)
  File "/Users/juliankleutgens/opt/anaconda3/envs/tgdp/lib/python3.9/site-packages/wandb/sdk/lib/sock_client.py", line 154, in send_server_request
    self._send_message(msg)
  File "/Users/juliankleutgens/opt/anaconda3/envs/tgdp/lib/python3.9/site-packages/wandb/sdk/lib/sock_client.py", line 151, in _send_message
    self._sendall_with_error_handle(header + data)
  File "/Users/juliankleutgens/opt/anaconda3/envs/tgdp/lib/python3.9/site-packages/wandb/sdk/lib/sock_client.py", line 130, in _sendall_with_error_handle
    sent = self._sock.send(data)
BrokenPipeError: [Errno 32] Broken pipe
2025-05-27 10:58:08,386 ERROR   MainThread:63695 [redirect.py:_on_write():664] [no run ID] error in stderr callback
Traceback (most recent call last):
  File "/Users/juliankleutgens/PycharmProjects/ratio_estimation_synthetic/main2.py", line 463, in <module>
    if __name__ == "__main__":
  File "/Users/juliankleutgens/PycharmProjects/ratio_estimation_synthetic/main2.py", line 210, in main
    if not config.skip_ratio_estimator_on_clean_data or not config.unguided_sampling:
  File "/Users/juliankleutgens/PycharmProjects/ratio_estimation_synthetic/training.py", line 111, in train_domain_classifier
    optimizer.step()
  File "/Users/juliankleutgens/opt/anaconda3/envs/tgdp/lib/python3.9/site-packages/torch/optim/optimizer.py", line 487, in wrapper
    out = func(*args, **kwargs)
  File "/Users/juliankleutgens/opt/anaconda3/envs/tgdp/lib/python3.9/site-packages/torch/optim/optimizer.py", line 91, in _use_grad
    ret = func(self, *args, **kwargs)
  File "/Users/juliankleutgens/opt/anaconda3/envs/tgdp/lib/python3.9/site-packages/torch/optim/adam.py", line 223, in step
    adam(
  File "/Users/juliankleutgens/opt/anaconda3/envs/tgdp/lib/python3.9/site-packages/torch/optim/optimizer.py", line 154, in maybe_fallback
    return func(*args, **kwargs)
  File "/Users/juliankleutgens/opt/anaconda3/envs/tgdp/lib/python3.9/site-packages/torch/optim/adam.py", line 784, in adam
    func(
  File "/Users/juliankleutgens/opt/anaconda3/envs/tgdp/lib/python3.9/site-packages/torch/optim/adam.py", line 381, in _single_tensor_adam
    if capturable or differentiable:
  File "/Users/juliankleutgens/opt/anaconda3/envs/tgdp/lib/python3.9/site-packages/torch/optim/adam.py", line 381, in _single_tensor_adam
    if capturable or differentiable:
  File "/Applications/PyCharm.app/Contents/plugins/python/helpers/pydev/_pydevd_bundle/pydevd_trace_dispatch.py", line 89, in trace_dispatch
    def trace_dispatch(py_db, frame, event, arg):
  File "_pydevd_bundle/pydevd_cython_darwin_39_64.pyx", line 1337, in _pydevd_bundle.pydevd_cython_darwin_39_64.trace_dispatch
  File "_pydevd_bundle/pydevd_cython_darwin_39_64.pyx", line 1597, in _pydevd_bundle.pydevd_cython_darwin_39_64.ThreadTracer.__call__
  File "_pydevd_bundle/pydevd_cython_darwin_39_64.pyx", line 937, in _pydevd_bundle.pydevd_cython_darwin_39_64.PyDBFrame.trace_dispatch
  File "_pydevd_bundle/pydevd_cython_darwin_39_64.pyx", line 928, in _pydevd_bundle.pydevd_cython_darwin_39_64.PyDBFrame.trace_dispatch
  File "_pydevd_bundle/pydevd_cython_darwin_39_64.pyx", line 585, in _pydevd_bundle.pydevd_cython_darwin_39_64.PyDBFrame.do_wait_suspend
  File "/Applications/PyCharm.app/Contents/plugins/python/helpers/pydev/pydevd.py", line 1185, in do_wait_suspend
    self._do_wait_suspend(thread, frame, event, arg, suspend_type, from_this_thread)
  File "/Applications/PyCharm.app/Contents/plugins/python/helpers/pydev/pydevd.py", line 1200, in _do_wait_suspend
    time.sleep(0.01)
KeyboardInterrupt

During handling of the above exception, another exception occurred:

Traceback (most recent call last):
  File "/Users/juliankleutgens/opt/anaconda3/envs/tgdp/lib/python3.9/site-packages/wandb/sdk/lib/redirect.py", line 662, in _on_write
    cb(written_data)
  File "/Users/juliankleutgens/opt/anaconda3/envs/tgdp/lib/python3.9/site-packages/wandb/sdk/wandb_run.py", line 2500, in <lambda>
    lambda data: self._console_raw_callback("stderr", data),
  File "/Users/juliankleutgens/opt/anaconda3/envs/tgdp/lib/python3.9/site-packages/wandb/sdk/wandb_run.py", line 406, in wrapper
    return func(self, *args, **kwargs)
  File "/Users/juliankleutgens/opt/anaconda3/envs/tgdp/lib/python3.9/site-packages/wandb/sdk/wandb_run.py", line 464, in wrapper_fn
    return func(self, *args, **kwargs)
  File "/Users/juliankleutgens/opt/anaconda3/envs/tgdp/lib/python3.9/site-packages/wandb/sdk/wandb_run.py", line 1639, in _console_raw_callback
    self._backend.interface.publish_output_raw(name, data)
  File "/Users/juliankleutgens/opt/anaconda3/envs/tgdp/lib/python3.9/site-packages/wandb/sdk/interface/interface.py", line 762, in publish_output_raw
    self._publish_output_raw(o)
  File "/Users/juliankleutgens/opt/anaconda3/envs/tgdp/lib/python3.9/site-packages/wandb/sdk/interface/interface_shared.py", line 38, in _publish_output_raw
    self._publish(rec)
  File "/Users/juliankleutgens/opt/anaconda3/envs/tgdp/lib/python3.9/site-packages/wandb/sdk/interface/interface_sock.py", line 39, in _publish
    self._sock_client.send_record_publish(record)
  File "/Users/juliankleutgens/opt/anaconda3/envs/tgdp/lib/python3.9/site-packages/wandb/sdk/lib/sock_client.py", line 174, in send_record_publish
    self.send_server_request(server_req)
  File "/Users/juliankleutgens/opt/anaconda3/envs/tgdp/lib/python3.9/site-packages/wandb/sdk/lib/sock_client.py", line 154, in send_server_request
    self._send_message(msg)
  File "/Users/juliankleutgens/opt/anaconda3/envs/tgdp/lib/python3.9/site-packages/wandb/sdk/lib/sock_client.py", line 151, in _send_message
    self._sendall_with_error_handle(header + data)
  File "/Users/juliankleutgens/opt/anaconda3/envs/tgdp/lib/python3.9/site-packages/wandb/sdk/lib/sock_client.py", line 130, in _sendall_with_error_handle
    sent = self._sock.send(data)
BrokenPipeError: [Errno 32] Broken pipe
2025-05-27 10:58:08,386 ERROR   MainThread:63695 [redirect.py:_on_write():664] [no run ID] error in stderr callback
Traceback (most recent call last):
  File "/Users/juliankleutgens/PycharmProjects/ratio_estimation_synthetic/main2.py", line 463, in <module>
    if __name__ == "__main__":
  File "/Users/juliankleutgens/PycharmProjects/ratio_estimation_synthetic/main2.py", line 210, in main
    if not config.skip_ratio_estimator_on_clean_data or not config.unguided_sampling:
  File "/Users/juliankleutgens/PycharmProjects/ratio_estimation_synthetic/training.py", line 111, in train_domain_classifier
    optimizer.step()
  File "/Users/juliankleutgens/opt/anaconda3/envs/tgdp/lib/python3.9/site-packages/torch/optim/optimizer.py", line 487, in wrapper
    out = func(*args, **kwargs)
  File "/Users/juliankleutgens/opt/anaconda3/envs/tgdp/lib/python3.9/site-packages/torch/optim/optimizer.py", line 91, in _use_grad
    ret = func(self, *args, **kwargs)
  File "/Users/juliankleutgens/opt/anaconda3/envs/tgdp/lib/python3.9/site-packages/torch/optim/adam.py", line 223, in step
    adam(
  File "/Users/juliankleutgens/opt/anaconda3/envs/tgdp/lib/python3.9/site-packages/torch/optim/optimizer.py", line 154, in maybe_fallback
    return func(*args, **kwargs)
  File "/Users/juliankleutgens/opt/anaconda3/envs/tgdp/lib/python3.9/site-packages/torch/optim/adam.py", line 784, in adam
    func(
  File "/Users/juliankleutgens/opt/anaconda3/envs/tgdp/lib/python3.9/site-packages/torch/optim/adam.py", line 381, in _single_tensor_adam
    if capturable or differentiable:
  File "/Users/juliankleutgens/opt/anaconda3/envs/tgdp/lib/python3.9/site-packages/torch/optim/adam.py", line 381, in _single_tensor_adam
    if capturable or differentiable:
  File "/Applications/PyCharm.app/Contents/plugins/python/helpers/pydev/_pydevd_bundle/pydevd_trace_dispatch.py", line 89, in trace_dispatch
    def trace_dispatch(py_db, frame, event, arg):
  File "_pydevd_bundle/pydevd_cython_darwin_39_64.pyx", line 1337, in _pydevd_bundle.pydevd_cython_darwin_39_64.trace_dispatch
  File "_pydevd_bundle/pydevd_cython_darwin_39_64.pyx", line 1597, in _pydevd_bundle.pydevd_cython_darwin_39_64.ThreadTracer.__call__
  File "_pydevd_bundle/pydevd_cython_darwin_39_64.pyx", line 937, in _pydevd_bundle.pydevd_cython_darwin_39_64.PyDBFrame.trace_dispatch
  File "_pydevd_bundle/pydevd_cython_darwin_39_64.pyx", line 928, in _pydevd_bundle.pydevd_cython_darwin_39_64.PyDBFrame.trace_dispatch
  File "_pydevd_bundle/pydevd_cython_darwin_39_64.pyx", line 585, in _pydevd_bundle.pydevd_cython_darwin_39_64.PyDBFrame.do_wait_suspend
  File "/Applications/PyCharm.app/Contents/plugins/python/helpers/pydev/pydevd.py", line 1185, in do_wait_suspend
    self._do_wait_suspend(thread, frame, event, arg, suspend_type, from_this_thread)
  File "/Applications/PyCharm.app/Contents/plugins/python/helpers/pydev/pydevd.py", line 1200, in _do_wait_suspend
    time.sleep(0.01)
KeyboardInterrupt

During handling of the above exception, another exception occurred:

Traceback (most recent call last):
  File "/Users/juliankleutgens/opt/anaconda3/envs/tgdp/lib/python3.9/site-packages/wandb/sdk/lib/redirect.py", line 662, in _on_write
    cb(written_data)
  File "/Users/juliankleutgens/opt/anaconda3/envs/tgdp/lib/python3.9/site-packages/wandb/sdk/wandb_run.py", line 2500, in <lambda>
    lambda data: self._console_raw_callback("stderr", data),
  File "/Users/juliankleutgens/opt/anaconda3/envs/tgdp/lib/python3.9/site-packages/wandb/sdk/wandb_run.py", line 406, in wrapper
    return func(self, *args, **kwargs)
  File "/Users/juliankleutgens/opt/anaconda3/envs/tgdp/lib/python3.9/site-packages/wandb/sdk/wandb_run.py", line 464, in wrapper_fn
    return func(self, *args, **kwargs)
  File "/Users/juliankleutgens/opt/anaconda3/envs/tgdp/lib/python3.9/site-packages/wandb/sdk/wandb_run.py", line 1639, in _console_raw_callback
    self._backend.interface.publish_output_raw(name, data)
  File "/Users/juliankleutgens/opt/anaconda3/envs/tgdp/lib/python3.9/site-packages/wandb/sdk/interface/interface.py", line 762, in publish_output_raw
    self._publish_output_raw(o)
  File "/Users/juliankleutgens/opt/anaconda3/envs/tgdp/lib/python3.9/site-packages/wandb/sdk/interface/interface_shared.py", line 38, in _publish_output_raw
    self._publish(rec)
  File "/Users/juliankleutgens/opt/anaconda3/envs/tgdp/lib/python3.9/site-packages/wandb/sdk/interface/interface_sock.py", line 39, in _publish
    self._sock_client.send_record_publish(record)
  File "/Users/juliankleutgens/opt/anaconda3/envs/tgdp/lib/python3.9/site-packages/wandb/sdk/lib/sock_client.py", line 174, in send_record_publish
    self.send_server_request(server_req)
  File "/Users/juliankleutgens/opt/anaconda3/envs/tgdp/lib/python3.9/site-packages/wandb/sdk/lib/sock_client.py", line 154, in send_server_request
    self._send_message(msg)
  File "/Users/juliankleutgens/opt/anaconda3/envs/tgdp/lib/python3.9/site-packages/wandb/sdk/lib/sock_client.py", line 151, in _send_message
    self._sendall_with_error_handle(header + data)
  File "/Users/juliankleutgens/opt/anaconda3/envs/tgdp/lib/python3.9/site-packages/wandb/sdk/lib/sock_client.py", line 130, in _sendall_with_error_handle
    sent = self._sock.send(data)
BrokenPipeError: [Errno 32] Broken pipe
2025-05-27 10:58:08,386 ERROR   MainThread:63695 [redirect.py:_on_write():664] [no run ID] error in stderr callback
Traceback (most recent call last):
  File "/Users/juliankleutgens/PycharmProjects/ratio_estimation_synthetic/main2.py", line 463, in <module>
    if __name__ == "__main__":
  File "/Users/juliankleutgens/PycharmProjects/ratio_estimation_synthetic/main2.py", line 210, in main
    if not config.skip_ratio_estimator_on_clean_data or not config.unguided_sampling:
  File "/Users/juliankleutgens/PycharmProjects/ratio_estimation_synthetic/training.py", line 111, in train_domain_classifier
    optimizer.step()
  File "/Users/juliankleutgens/opt/anaconda3/envs/tgdp/lib/python3.9/site-packages/torch/optim/optimizer.py", line 487, in wrapper
    out = func(*args, **kwargs)
  File "/Users/juliankleutgens/opt/anaconda3/envs/tgdp/lib/python3.9/site-packages/torch/optim/optimizer.py", line 91, in _use_grad
    ret = func(self, *args, **kwargs)
  File "/Users/juliankleutgens/opt/anaconda3/envs/tgdp/lib/python3.9/site-packages/torch/optim/adam.py", line 223, in step
    adam(
  File "/Users/juliankleutgens/opt/anaconda3/envs/tgdp/lib/python3.9/site-packages/torch/optim/optimizer.py", line 154, in maybe_fallback
    return func(*args, **kwargs)
  File "/Users/juliankleutgens/opt/anaconda3/envs/tgdp/lib/python3.9/site-packages/torch/optim/adam.py", line 784, in adam
    func(
  File "/Users/juliankleutgens/opt/anaconda3/envs/tgdp/lib/python3.9/site-packages/torch/optim/adam.py", line 381, in _single_tensor_adam
    if capturable or differentiable:
  File "/Users/juliankleutgens/opt/anaconda3/envs/tgdp/lib/python3.9/site-packages/torch/optim/adam.py", line 381, in _single_tensor_adam
    if capturable or differentiable:
  File "/Applications/PyCharm.app/Contents/plugins/python/helpers/pydev/_pydevd_bundle/pydevd_trace_dispatch.py", line 89, in trace_dispatch
    def trace_dispatch(py_db, frame, event, arg):
  File "_pydevd_bundle/pydevd_cython_darwin_39_64.pyx", line 1337, in _pydevd_bundle.pydevd_cython_darwin_39_64.trace_dispatch
  File "_pydevd_bundle/pydevd_cython_darwin_39_64.pyx", line 1597, in _pydevd_bundle.pydevd_cython_darwin_39_64.ThreadTracer.__call__
  File "_pydevd_bundle/pydevd_cython_darwin_39_64.pyx", line 937, in _pydevd_bundle.pydevd_cython_darwin_39_64.PyDBFrame.trace_dispatch
  File "_pydevd_bundle/pydevd_cython_darwin_39_64.pyx", line 928, in _pydevd_bundle.pydevd_cython_darwin_39_64.PyDBFrame.trace_dispatch
  File "_pydevd_bundle/pydevd_cython_darwin_39_64.pyx", line 585, in _pydevd_bundle.pydevd_cython_darwin_39_64.PyDBFrame.do_wait_suspend
  File "/Applications/PyCharm.app/Contents/plugins/python/helpers/pydev/pydevd.py", line 1185, in do_wait_suspend
    self._do_wait_suspend(thread, frame, event, arg, suspend_type, from_this_thread)
  File "/Applications/PyCharm.app/Contents/plugins/python/helpers/pydev/pydevd.py", line 1200, in _do_wait_suspend
    time.sleep(0.01)
KeyboardInterrupt

During handling of the above exception, another exception occurred:

Traceback (most recent call last):
  File "/Users/juliankleutgens/opt/anaconda3/envs/tgdp/lib/python3.9/site-packages/wandb/sdk/lib/redirect.py", line 662, in _on_write
    cb(written_data)
  File "/Users/juliankleutgens/opt/anaconda3/envs/tgdp/lib/python3.9/site-packages/wandb/sdk/wandb_run.py", line 2500, in <lambda>
    lambda data: self._console_raw_callback("stderr", data),
  File "/Users/juliankleutgens/opt/anaconda3/envs/tgdp/lib/python3.9/site-packages/wandb/sdk/wandb_run.py", line 406, in wrapper
    return func(self, *args, **kwargs)
  File "/Users/juliankleutgens/opt/anaconda3/envs/tgdp/lib/python3.9/site-packages/wandb/sdk/wandb_run.py", line 464, in wrapper_fn
    return func(self, *args, **kwargs)
  File "/Users/juliankleutgens/opt/anaconda3/envs/tgdp/lib/python3.9/site-packages/wandb/sdk/wandb_run.py", line 1639, in _console_raw_callback
    self._backend.interface.publish_output_raw(name, data)
  File "/Users/juliankleutgens/opt/anaconda3/envs/tgdp/lib/python3.9/site-packages/wandb/sdk/interface/interface.py", line 762, in publish_output_raw
    self._publish_output_raw(o)
  File "/Users/juliankleutgens/opt/anaconda3/envs/tgdp/lib/python3.9/site-packages/wandb/sdk/interface/interface_shared.py", line 38, in _publish_output_raw
    self._publish(rec)
  File "/Users/juliankleutgens/opt/anaconda3/envs/tgdp/lib/python3.9/site-packages/wandb/sdk/interface/interface_sock.py", line 39, in _publish
    self._sock_client.send_record_publish(record)
  File "/Users/juliankleutgens/opt/anaconda3/envs/tgdp/lib/python3.9/site-packages/wandb/sdk/lib/sock_client.py", line 174, in send_record_publish
    self.send_server_request(server_req)
  File "/Users/juliankleutgens/opt/anaconda3/envs/tgdp/lib/python3.9/site-packages/wandb/sdk/lib/sock_client.py", line 154, in send_server_request
    self._send_message(msg)
  File "/Users/juliankleutgens/opt/anaconda3/envs/tgdp/lib/python3.9/site-packages/wandb/sdk/lib/sock_client.py", line 151, in _send_message
    self._sendall_with_error_handle(header + data)
  File "/Users/juliankleutgens/opt/anaconda3/envs/tgdp/lib/python3.9/site-packages/wandb/sdk/lib/sock_client.py", line 130, in _sendall_with_error_handle
    sent = self._sock.send(data)
BrokenPipeError: [Errno 32] Broken pipe
2025-05-27 10:58:08,387 ERROR   MainThread:63695 [redirect.py:_on_write():664] [no run ID] error in stderr callback
Traceback (most recent call last):
  File "/Users/juliankleutgens/PycharmProjects/ratio_estimation_synthetic/main2.py", line 463, in <module>
    if __name__ == "__main__":
  File "/Users/juliankleutgens/PycharmProjects/ratio_estimation_synthetic/main2.py", line 210, in main
    if not config.skip_ratio_estimator_on_clean_data or not config.unguided_sampling:
  File "/Users/juliankleutgens/PycharmProjects/ratio_estimation_synthetic/training.py", line 111, in train_domain_classifier
    optimizer.step()
  File "/Users/juliankleutgens/opt/anaconda3/envs/tgdp/lib/python3.9/site-packages/torch/optim/optimizer.py", line 487, in wrapper
    out = func(*args, **kwargs)
  File "/Users/juliankleutgens/opt/anaconda3/envs/tgdp/lib/python3.9/site-packages/torch/optim/optimizer.py", line 91, in _use_grad
    ret = func(self, *args, **kwargs)
  File "/Users/juliankleutgens/opt/anaconda3/envs/tgdp/lib/python3.9/site-packages/torch/optim/adam.py", line 223, in step
    adam(
  File "/Users/juliankleutgens/opt/anaconda3/envs/tgdp/lib/python3.9/site-packages/torch/optim/optimizer.py", line 154, in maybe_fallback
    return func(*args, **kwargs)
  File "/Users/juliankleutgens/opt/anaconda3/envs/tgdp/lib/python3.9/site-packages/torch/optim/adam.py", line 784, in adam
    func(
  File "/Users/juliankleutgens/opt/anaconda3/envs/tgdp/lib/python3.9/site-packages/torch/optim/adam.py", line 381, in _single_tensor_adam
    if capturable or differentiable:
  File "/Users/juliankleutgens/opt/anaconda3/envs/tgdp/lib/python3.9/site-packages/torch/optim/adam.py", line 381, in _single_tensor_adam
    if capturable or differentiable:
  File "/Applications/PyCharm.app/Contents/plugins/python/helpers/pydev/_pydevd_bundle/pydevd_trace_dispatch.py", line 89, in trace_dispatch
    def trace_dispatch(py_db, frame, event, arg):
  File "_pydevd_bundle/pydevd_cython_darwin_39_64.pyx", line 1337, in _pydevd_bundle.pydevd_cython_darwin_39_64.trace_dispatch
  File "_pydevd_bundle/pydevd_cython_darwin_39_64.pyx", line 1597, in _pydevd_bundle.pydevd_cython_darwin_39_64.ThreadTracer.__call__
  File "_pydevd_bundle/pydevd_cython_darwin_39_64.pyx", line 937, in _pydevd_bundle.pydevd_cython_darwin_39_64.PyDBFrame.trace_dispatch
  File "_pydevd_bundle/pydevd_cython_darwin_39_64.pyx", line 928, in _pydevd_bundle.pydevd_cython_darwin_39_64.PyDBFrame.trace_dispatch
  File "_pydevd_bundle/pydevd_cython_darwin_39_64.pyx", line 585, in _pydevd_bundle.pydevd_cython_darwin_39_64.PyDBFrame.do_wait_suspend
  File "/Applications/PyCharm.app/Contents/plugins/python/helpers/pydev/pydevd.py", line 1185, in do_wait_suspend
    self._do_wait_suspend(thread, frame, event, arg, suspend_type, from_this_thread)
  File "/Applications/PyCharm.app/Contents/plugins/python/helpers/pydev/pydevd.py", line 1200, in _do_wait_suspend
    time.sleep(0.01)
KeyboardInterrupt

During handling of the above exception, another exception occurred:

Traceback (most recent call last):
  File "/Users/juliankleutgens/opt/anaconda3/envs/tgdp/lib/python3.9/site-packages/wandb/sdk/lib/redirect.py", line 662, in _on_write
    cb(written_data)
  File "/Users/juliankleutgens/opt/anaconda3/envs/tgdp/lib/python3.9/site-packages/wandb/sdk/wandb_run.py", line 2500, in <lambda>
    lambda data: self._console_raw_callback("stderr", data),
  File "/Users/juliankleutgens/opt/anaconda3/envs/tgdp/lib/python3.9/site-packages/wandb/sdk/wandb_run.py", line 406, in wrapper
    return func(self, *args, **kwargs)
  File "/Users/juliankleutgens/opt/anaconda3/envs/tgdp/lib/python3.9/site-packages/wandb/sdk/wandb_run.py", line 464, in wrapper_fn
    return func(self, *args, **kwargs)
  File "/Users/juliankleutgens/opt/anaconda3/envs/tgdp/lib/python3.9/site-packages/wandb/sdk/wandb_run.py", line 1639, in _console_raw_callback
    self._backend.interface.publish_output_raw(name, data)
  File "/Users/juliankleutgens/opt/anaconda3/envs/tgdp/lib/python3.9/site-packages/wandb/sdk/interface/interface.py", line 762, in publish_output_raw
    self._publish_output_raw(o)
  File "/Users/juliankleutgens/opt/anaconda3/envs/tgdp/lib/python3.9/site-packages/wandb/sdk/interface/interface_shared.py", line 38, in _publish_output_raw
    self._publish(rec)
  File "/Users/juliankleutgens/opt/anaconda3/envs/tgdp/lib/python3.9/site-packages/wandb/sdk/interface/interface_sock.py", line 39, in _publish
    self._sock_client.send_record_publish(record)
  File "/Users/juliankleutgens/opt/anaconda3/envs/tgdp/lib/python3.9/site-packages/wandb/sdk/lib/sock_client.py", line 174, in send_record_publish
    self.send_server_request(server_req)
  File "/Users/juliankleutgens/opt/anaconda3/envs/tgdp/lib/python3.9/site-packages/wandb/sdk/lib/sock_client.py", line 154, in send_server_request
    self._send_message(msg)
  File "/Users/juliankleutgens/opt/anaconda3/envs/tgdp/lib/python3.9/site-packages/wandb/sdk/lib/sock_client.py", line 151, in _send_message
    self._sendall_with_error_handle(header + data)
  File "/Users/juliankleutgens/opt/anaconda3/envs/tgdp/lib/python3.9/site-packages/wandb/sdk/lib/sock_client.py", line 130, in _sendall_with_error_handle
    sent = self._sock.send(data)
BrokenPipeError: [Errno 32] Broken pipe
2025-05-27 10:58:08,387 ERROR   MainThread:63695 [redirect.py:_on_write():664] [no run ID] error in stderr callback
Traceback (most recent call last):
  File "/Users/juliankleutgens/PycharmProjects/ratio_estimation_synthetic/main2.py", line 463, in <module>
    if __name__ == "__main__":
  File "/Users/juliankleutgens/PycharmProjects/ratio_estimation_synthetic/main2.py", line 210, in main
    if not config.skip_ratio_estimator_on_clean_data or not config.unguided_sampling:
  File "/Users/juliankleutgens/PycharmProjects/ratio_estimation_synthetic/training.py", line 111, in train_domain_classifier
    optimizer.step()
  File "/Users/juliankleutgens/opt/anaconda3/envs/tgdp/lib/python3.9/site-packages/torch/optim/optimizer.py", line 487, in wrapper
    out = func(*args, **kwargs)
  File "/Users/juliankleutgens/opt/anaconda3/envs/tgdp/lib/python3.9/site-packages/torch/optim/optimizer.py", line 91, in _use_grad
    ret = func(self, *args, **kwargs)
  File "/Users/juliankleutgens/opt/anaconda3/envs/tgdp/lib/python3.9/site-packages/torch/optim/adam.py", line 223, in step
    adam(
  File "/Users/juliankleutgens/opt/anaconda3/envs/tgdp/lib/python3.9/site-packages/torch/optim/optimizer.py", line 154, in maybe_fallback
    return func(*args, **kwargs)
  File "/Users/juliankleutgens/opt/anaconda3/envs/tgdp/lib/python3.9/site-packages/torch/optim/adam.py", line 784, in adam
    func(
  File "/Users/juliankleutgens/opt/anaconda3/envs/tgdp/lib/python3.9/site-packages/torch/optim/adam.py", line 381, in _single_tensor_adam
    if capturable or differentiable:
  File "/Users/juliankleutgens/opt/anaconda3/envs/tgdp/lib/python3.9/site-packages/torch/optim/adam.py", line 381, in _single_tensor_adam
    if capturable or differentiable:
  File "/Applications/PyCharm.app/Contents/plugins/python/helpers/pydev/_pydevd_bundle/pydevd_trace_dispatch.py", line 89, in trace_dispatch
    def trace_dispatch(py_db, frame, event, arg):
  File "_pydevd_bundle/pydevd_cython_darwin_39_64.pyx", line 1337, in _pydevd_bundle.pydevd_cython_darwin_39_64.trace_dispatch
  File "_pydevd_bundle/pydevd_cython_darwin_39_64.pyx", line 1597, in _pydevd_bundle.pydevd_cython_darwin_39_64.ThreadTracer.__call__
  File "_pydevd_bundle/pydevd_cython_darwin_39_64.pyx", line 937, in _pydevd_bundle.pydevd_cython_darwin_39_64.PyDBFrame.trace_dispatch
  File "_pydevd_bundle/pydevd_cython_darwin_39_64.pyx", line 928, in _pydevd_bundle.pydevd_cython_darwin_39_64.PyDBFrame.trace_dispatch
  File "_pydevd_bundle/pydevd_cython_darwin_39_64.pyx", line 585, in _pydevd_bundle.pydevd_cython_darwin_39_64.PyDBFrame.do_wait_suspend
  File "/Applications/PyCharm.app/Contents/plugins/python/helpers/pydev/pydevd.py", line 1185, in do_wait_suspend
    self._do_wait_suspend(thread, frame, event, arg, suspend_type, from_this_thread)
  File "/Applications/PyCharm.app/Contents/plugins/python/helpers/pydev/pydevd.py", line 1200, in _do_wait_suspend
    time.sleep(0.01)
KeyboardInterrupt

During handling of the above exception, another exception occurred:

Traceback (most recent call last):
  File "/Users/juliankleutgens/opt/anaconda3/envs/tgdp/lib/python3.9/site-packages/wandb/sdk/lib/redirect.py", line 662, in _on_write
    cb(written_data)
  File "/Users/juliankleutgens/opt/anaconda3/envs/tgdp/lib/python3.9/site-packages/wandb/sdk/wandb_run.py", line 2500, in <lambda>
    lambda data: self._console_raw_callback("stderr", data),
  File "/Users/juliankleutgens/opt/anaconda3/envs/tgdp/lib/python3.9/site-packages/wandb/sdk/wandb_run.py", line 406, in wrapper
    return func(self, *args, **kwargs)
  File "/Users/juliankleutgens/opt/anaconda3/envs/tgdp/lib/python3.9/site-packages/wandb/sdk/wandb_run.py", line 464, in wrapper_fn
    return func(self, *args, **kwargs)
  File "/Users/juliankleutgens/opt/anaconda3/envs/tgdp/lib/python3.9/site-packages/wandb/sdk/wandb_run.py", line 1639, in _console_raw_callback
    self._backend.interface.publish_output_raw(name, data)
  File "/Users/juliankleutgens/opt/anaconda3/envs/tgdp/lib/python3.9/site-packages/wandb/sdk/interface/interface.py", line 762, in publish_output_raw
    self._publish_output_raw(o)
  File "/Users/juliankleutgens/opt/anaconda3/envs/tgdp/lib/python3.9/site-packages/wandb/sdk/interface/interface_shared.py", line 38, in _publish_output_raw
    self._publish(rec)
  File "/Users/juliankleutgens/opt/anaconda3/envs/tgdp/lib/python3.9/site-packages/wandb/sdk/interface/interface_sock.py", line 39, in _publish
    self._sock_client.send_record_publish(record)
  File "/Users/juliankleutgens/opt/anaconda3/envs/tgdp/lib/python3.9/site-packages/wandb/sdk/lib/sock_client.py", line 174, in send_record_publish
    self.send_server_request(server_req)
  File "/Users/juliankleutgens/opt/anaconda3/envs/tgdp/lib/python3.9/site-packages/wandb/sdk/lib/sock_client.py", line 154, in send_server_request
    self._send_message(msg)
  File "/Users/juliankleutgens/opt/anaconda3/envs/tgdp/lib/python3.9/site-packages/wandb/sdk/lib/sock_client.py", line 151, in _send_message
    self._sendall_with_error_handle(header + data)
  File "/Users/juliankleutgens/opt/anaconda3/envs/tgdp/lib/python3.9/site-packages/wandb/sdk/lib/sock_client.py", line 130, in _sendall_with_error_handle
    sent = self._sock.send(data)
BrokenPipeError: [Errno 32] Broken pipe
2025-05-27 10:58:08,387 ERROR   MainThread:63695 [redirect.py:_on_write():664] [no run ID] error in stderr callback
Traceback (most recent call last):
  File "/Users/juliankleutgens/PycharmProjects/ratio_estimation_synthetic/main2.py", line 463, in <module>
    if __name__ == "__main__":
  File "/Users/juliankleutgens/PycharmProjects/ratio_estimation_synthetic/main2.py", line 210, in main
    if not config.skip_ratio_estimator_on_clean_data or not config.unguided_sampling:
  File "/Users/juliankleutgens/PycharmProjects/ratio_estimation_synthetic/training.py", line 111, in train_domain_classifier
    optimizer.step()
  File "/Users/juliankleutgens/opt/anaconda3/envs/tgdp/lib/python3.9/site-packages/torch/optim/optimizer.py", line 487, in wrapper
    out = func(*args, **kwargs)
  File "/Users/juliankleutgens/opt/anaconda3/envs/tgdp/lib/python3.9/site-packages/torch/optim/optimizer.py", line 91, in _use_grad
    ret = func(self, *args, **kwargs)
  File "/Users/juliankleutgens/opt/anaconda3/envs/tgdp/lib/python3.9/site-packages/torch/optim/adam.py", line 223, in step
    adam(
  File "/Users/juliankleutgens/opt/anaconda3/envs/tgdp/lib/python3.9/site-packages/torch/optim/optimizer.py", line 154, in maybe_fallback
    return func(*args, **kwargs)
  File "/Users/juliankleutgens/opt/anaconda3/envs/tgdp/lib/python3.9/site-packages/torch/optim/adam.py", line 784, in adam
    func(
  File "/Users/juliankleutgens/opt/anaconda3/envs/tgdp/lib/python3.9/site-packages/torch/optim/adam.py", line 381, in _single_tensor_adam
    if capturable or differentiable:
  File "/Users/juliankleutgens/opt/anaconda3/envs/tgdp/lib/python3.9/site-packages/torch/optim/adam.py", line 381, in _single_tensor_adam
    if capturable or differentiable:
  File "/Applications/PyCharm.app/Contents/plugins/python/helpers/pydev/_pydevd_bundle/pydevd_trace_dispatch.py", line 89, in trace_dispatch
    def trace_dispatch(py_db, frame, event, arg):
  File "_pydevd_bundle/pydevd_cython_darwin_39_64.pyx", line 1337, in _pydevd_bundle.pydevd_cython_darwin_39_64.trace_dispatch
  File "_pydevd_bundle/pydevd_cython_darwin_39_64.pyx", line 1597, in _pydevd_bundle.pydevd_cython_darwin_39_64.ThreadTracer.__call__
  File "_pydevd_bundle/pydevd_cython_darwin_39_64.pyx", line 937, in _pydevd_bundle.pydevd_cython_darwin_39_64.PyDBFrame.trace_dispatch
  File "_pydevd_bundle/pydevd_cython_darwin_39_64.pyx", line 928, in _pydevd_bundle.pydevd_cython_darwin_39_64.PyDBFrame.trace_dispatch
  File "_pydevd_bundle/pydevd_cython_darwin_39_64.pyx", line 585, in _pydevd_bundle.pydevd_cython_darwin_39_64.PyDBFrame.do_wait_suspend
  File "/Applications/PyCharm.app/Contents/plugins/python/helpers/pydev/pydevd.py", line 1185, in do_wait_suspend
    self._do_wait_suspend(thread, frame, event, arg, suspend_type, from_this_thread)
  File "/Applications/PyCharm.app/Contents/plugins/python/helpers/pydev/pydevd.py", line 1200, in _do_wait_suspend
    time.sleep(0.01)
KeyboardInterrupt

During handling of the above exception, another exception occurred:

Traceback (most recent call last):
  File "/Users/juliankleutgens/opt/anaconda3/envs/tgdp/lib/python3.9/site-packages/wandb/sdk/lib/redirect.py", line 662, in _on_write
    cb(written_data)
  File "/Users/juliankleutgens/opt/anaconda3/envs/tgdp/lib/python3.9/site-packages/wandb/sdk/wandb_run.py", line 2500, in <lambda>
    lambda data: self._console_raw_callback("stderr", data),
  File "/Users/juliankleutgens/opt/anaconda3/envs/tgdp/lib/python3.9/site-packages/wandb/sdk/wandb_run.py", line 406, in wrapper
    return func(self, *args, **kwargs)
  File "/Users/juliankleutgens/opt/anaconda3/envs/tgdp/lib/python3.9/site-packages/wandb/sdk/wandb_run.py", line 464, in wrapper_fn
    return func(self, *args, **kwargs)
  File "/Users/juliankleutgens/opt/anaconda3/envs/tgdp/lib/python3.9/site-packages/wandb/sdk/wandb_run.py", line 1639, in _console_raw_callback
    self._backend.interface.publish_output_raw(name, data)
  File "/Users/juliankleutgens/opt/anaconda3/envs/tgdp/lib/python3.9/site-packages/wandb/sdk/interface/interface.py", line 762, in publish_output_raw
    self._publish_output_raw(o)
  File "/Users/juliankleutgens/opt/anaconda3/envs/tgdp/lib/python3.9/site-packages/wandb/sdk/interface/interface_shared.py", line 38, in _publish_output_raw
    self._publish(rec)
  File "/Users/juliankleutgens/opt/anaconda3/envs/tgdp/lib/python3.9/site-packages/wandb/sdk/interface/interface_sock.py", line 39, in _publish
    self._sock_client.send_record_publish(record)
  File "/Users/juliankleutgens/opt/anaconda3/envs/tgdp/lib/python3.9/site-packages/wandb/sdk/lib/sock_client.py", line 174, in send_record_publish
    self.send_server_request(server_req)
  File "/Users/juliankleutgens/opt/anaconda3/envs/tgdp/lib/python3.9/site-packages/wandb/sdk/lib/sock_client.py", line 154, in send_server_request
    self._send_message(msg)
  File "/Users/juliankleutgens/opt/anaconda3/envs/tgdp/lib/python3.9/site-packages/wandb/sdk/lib/sock_client.py", line 151, in _send_message
    self._sendall_with_error_handle(header + data)
  File "/Users/juliankleutgens/opt/anaconda3/envs/tgdp/lib/python3.9/site-packages/wandb/sdk/lib/sock_client.py", line 130, in _sendall_with_error_handle
    sent = self._sock.send(data)
BrokenPipeError: [Errno 32] Broken pipe
2025-05-27 10:58:08,387 ERROR   MainThread:63695 [redirect.py:_on_write():664] [no run ID] error in stderr callback
Traceback (most recent call last):
  File "/Users/juliankleutgens/PycharmProjects/ratio_estimation_synthetic/main2.py", line 463, in <module>
    if __name__ == "__main__":
  File "/Users/juliankleutgens/PycharmProjects/ratio_estimation_synthetic/main2.py", line 210, in main
    if not config.skip_ratio_estimator_on_clean_data or not config.unguided_sampling:
  File "/Users/juliankleutgens/PycharmProjects/ratio_estimation_synthetic/training.py", line 111, in train_domain_classifier
    optimizer.step()
  File "/Users/juliankleutgens/opt/anaconda3/envs/tgdp/lib/python3.9/site-packages/torch/optim/optimizer.py", line 487, in wrapper
    out = func(*args, **kwargs)
  File "/Users/juliankleutgens/opt/anaconda3/envs/tgdp/lib/python3.9/site-packages/torch/optim/optimizer.py", line 91, in _use_grad
    ret = func(self, *args, **kwargs)
  File "/Users/juliankleutgens/opt/anaconda3/envs/tgdp/lib/python3.9/site-packages/torch/optim/adam.py", line 223, in step
    adam(
  File "/Users/juliankleutgens/opt/anaconda3/envs/tgdp/lib/python3.9/site-packages/torch/optim/optimizer.py", line 154, in maybe_fallback
    return func(*args, **kwargs)
  File "/Users/juliankleutgens/opt/anaconda3/envs/tgdp/lib/python3.9/site-packages/torch/optim/adam.py", line 784, in adam
    func(
  File "/Users/juliankleutgens/opt/anaconda3/envs/tgdp/lib/python3.9/site-packages/torch/optim/adam.py", line 381, in _single_tensor_adam
    if capturable or differentiable:
  File "/Users/juliankleutgens/opt/anaconda3/envs/tgdp/lib/python3.9/site-packages/torch/optim/adam.py", line 381, in _single_tensor_adam
    if capturable or differentiable:
  File "/Applications/PyCharm.app/Contents/plugins/python/helpers/pydev/_pydevd_bundle/pydevd_trace_dispatch.py", line 89, in trace_dispatch
    def trace_dispatch(py_db, frame, event, arg):
  File "_pydevd_bundle/pydevd_cython_darwin_39_64.pyx", line 1337, in _pydevd_bundle.pydevd_cython_darwin_39_64.trace_dispatch
  File "_pydevd_bundle/pydevd_cython_darwin_39_64.pyx", line 1597, in _pydevd_bundle.pydevd_cython_darwin_39_64.ThreadTracer.__call__
  File "_pydevd_bundle/pydevd_cython_darwin_39_64.pyx", line 937, in _pydevd_bundle.pydevd_cython_darwin_39_64.PyDBFrame.trace_dispatch
  File "_pydevd_bundle/pydevd_cython_darwin_39_64.pyx", line 928, in _pydevd_bundle.pydevd_cython_darwin_39_64.PyDBFrame.trace_dispatch
  File "_pydevd_bundle/pydevd_cython_darwin_39_64.pyx", line 585, in _pydevd_bundle.pydevd_cython_darwin_39_64.PyDBFrame.do_wait_suspend
  File "/Applications/PyCharm.app/Contents/plugins/python/helpers/pydev/pydevd.py", line 1185, in do_wait_suspend
    self._do_wait_suspend(thread, frame, event, arg, suspend_type, from_this_thread)
  File "/Applications/PyCharm.app/Contents/plugins/python/helpers/pydev/pydevd.py", line 1200, in _do_wait_suspend
    time.sleep(0.01)
KeyboardInterrupt

During handling of the above exception, another exception occurred:

Traceback (most recent call last):
  File "/Users/juliankleutgens/opt/anaconda3/envs/tgdp/lib/python3.9/site-packages/wandb/sdk/lib/redirect.py", line 662, in _on_write
    cb(written_data)
  File "/Users/juliankleutgens/opt/anaconda3/envs/tgdp/lib/python3.9/site-packages/wandb/sdk/wandb_run.py", line 2500, in <lambda>
    lambda data: self._console_raw_callback("stderr", data),
  File "/Users/juliankleutgens/opt/anaconda3/envs/tgdp/lib/python3.9/site-packages/wandb/sdk/wandb_run.py", line 406, in wrapper
    return func(self, *args, **kwargs)
  File "/Users/juliankleutgens/opt/anaconda3/envs/tgdp/lib/python3.9/site-packages/wandb/sdk/wandb_run.py", line 464, in wrapper_fn
    return func(self, *args, **kwargs)
  File "/Users/juliankleutgens/opt/anaconda3/envs/tgdp/lib/python3.9/site-packages/wandb/sdk/wandb_run.py", line 1639, in _console_raw_callback
    self._backend.interface.publish_output_raw(name, data)
  File "/Users/juliankleutgens/opt/anaconda3/envs/tgdp/lib/python3.9/site-packages/wandb/sdk/interface/interface.py", line 762, in publish_output_raw
    self._publish_output_raw(o)
  File "/Users/juliankleutgens/opt/anaconda3/envs/tgdp/lib/python3.9/site-packages/wandb/sdk/interface/interface_shared.py", line 38, in _publish_output_raw
    self._publish(rec)
  File "/Users/juliankleutgens/opt/anaconda3/envs/tgdp/lib/python3.9/site-packages/wandb/sdk/interface/interface_sock.py", line 39, in _publish
    self._sock_client.send_record_publish(record)
  File "/Users/juliankleutgens/opt/anaconda3/envs/tgdp/lib/python3.9/site-packages/wandb/sdk/lib/sock_client.py", line 174, in send_record_publish
    self.send_server_request(server_req)
  File "/Users/juliankleutgens/opt/anaconda3/envs/tgdp/lib/python3.9/site-packages/wandb/sdk/lib/sock_client.py", line 154, in send_server_request
    self._send_message(msg)
  File "/Users/juliankleutgens/opt/anaconda3/envs/tgdp/lib/python3.9/site-packages/wandb/sdk/lib/sock_client.py", line 151, in _send_message
    self._sendall_with_error_handle(header + data)
  File "/Users/juliankleutgens/opt/anaconda3/envs/tgdp/lib/python3.9/site-packages/wandb/sdk/lib/sock_client.py", line 130, in _sendall_with_error_handle
    sent = self._sock.send(data)
BrokenPipeError: [Errno 32] Broken pipe
2025-05-27 10:58:08,387 ERROR   MainThread:63695 [redirect.py:_on_write():664] [no run ID] error in stderr callback
Traceback (most recent call last):
  File "/Users/juliankleutgens/PycharmProjects/ratio_estimation_synthetic/main2.py", line 463, in <module>
    if __name__ == "__main__":
  File "/Users/juliankleutgens/PycharmProjects/ratio_estimation_synthetic/main2.py", line 210, in main
    if not config.skip_ratio_estimator_on_clean_data or not config.unguided_sampling:
  File "/Users/juliankleutgens/PycharmProjects/ratio_estimation_synthetic/training.py", line 111, in train_domain_classifier
    optimizer.step()
  File "/Users/juliankleutgens/opt/anaconda3/envs/tgdp/lib/python3.9/site-packages/torch/optim/optimizer.py", line 487, in wrapper
    out = func(*args, **kwargs)
  File "/Users/juliankleutgens/opt/anaconda3/envs/tgdp/lib/python3.9/site-packages/torch/optim/optimizer.py", line 91, in _use_grad
    ret = func(self, *args, **kwargs)
  File "/Users/juliankleutgens/opt/anaconda3/envs/tgdp/lib/python3.9/site-packages/torch/optim/adam.py", line 223, in step
    adam(
  File "/Users/juliankleutgens/opt/anaconda3/envs/tgdp/lib/python3.9/site-packages/torch/optim/optimizer.py", line 154, in maybe_fallback
    return func(*args, **kwargs)
  File "/Users/juliankleutgens/opt/anaconda3/envs/tgdp/lib/python3.9/site-packages/torch/optim/adam.py", line 784, in adam
    func(
  File "/Users/juliankleutgens/opt/anaconda3/envs/tgdp/lib/python3.9/site-packages/torch/optim/adam.py", line 381, in _single_tensor_adam
    if capturable or differentiable:
  File "/Users/juliankleutgens/opt/anaconda3/envs/tgdp/lib/python3.9/site-packages/torch/optim/adam.py", line 381, in _single_tensor_adam
    if capturable or differentiable:
  File "/Applications/PyCharm.app/Contents/plugins/python/helpers/pydev/_pydevd_bundle/pydevd_trace_dispatch.py", line 89, in trace_dispatch
    def trace_dispatch(py_db, frame, event, arg):
  File "_pydevd_bundle/pydevd_cython_darwin_39_64.pyx", line 1337, in _pydevd_bundle.pydevd_cython_darwin_39_64.trace_dispatch
  File "_pydevd_bundle/pydevd_cython_darwin_39_64.pyx", line 1597, in _pydevd_bundle.pydevd_cython_darwin_39_64.ThreadTracer.__call__
  File "_pydevd_bundle/pydevd_cython_darwin_39_64.pyx", line 937, in _pydevd_bundle.pydevd_cython_darwin_39_64.PyDBFrame.trace_dispatch
  File "_pydevd_bundle/pydevd_cython_darwin_39_64.pyx", line 928, in _pydevd_bundle.pydevd_cython_darwin_39_64.PyDBFrame.trace_dispatch
  File "_pydevd_bundle/pydevd_cython_darwin_39_64.pyx", line 585, in _pydevd_bundle.pydevd_cython_darwin_39_64.PyDBFrame.do_wait_suspend
  File "/Applications/PyCharm.app/Contents/plugins/python/helpers/pydev/pydevd.py", line 1185, in do_wait_suspend
    self._do_wait_suspend(thread, frame, event, arg, suspend_type, from_this_thread)
  File "/Applications/PyCharm.app/Contents/plugins/python/helpers/pydev/pydevd.py", line 1200, in _do_wait_suspend
    time.sleep(0.01)
KeyboardInterrupt

During handling of the above exception, another exception occurred:

Traceback (most recent call last):
  File "/Users/juliankleutgens/opt/anaconda3/envs/tgdp/lib/python3.9/site-packages/wandb/sdk/lib/redirect.py", line 662, in _on_write
    cb(written_data)
  File "/Users/juliankleutgens/opt/anaconda3/envs/tgdp/lib/python3.9/site-packages/wandb/sdk/wandb_run.py", line 2500, in <lambda>
    lambda data: self._console_raw_callback("stderr", data),
  File "/Users/juliankleutgens/opt/anaconda3/envs/tgdp/lib/python3.9/site-packages/wandb/sdk/wandb_run.py", line 406, in wrapper
    return func(self, *args, **kwargs)
  File "/Users/juliankleutgens/opt/anaconda3/envs/tgdp/lib/python3.9/site-packages/wandb/sdk/wandb_run.py", line 464, in wrapper_fn
    return func(self, *args, **kwargs)
  File "/Users/juliankleutgens/opt/anaconda3/envs/tgdp/lib/python3.9/site-packages/wandb/sdk/wandb_run.py", line 1639, in _console_raw_callback
    self._backend.interface.publish_output_raw(name, data)
  File "/Users/juliankleutgens/opt/anaconda3/envs/tgdp/lib/python3.9/site-packages/wandb/sdk/interface/interface.py", line 762, in publish_output_raw
    self._publish_output_raw(o)
  File "/Users/juliankleutgens/opt/anaconda3/envs/tgdp/lib/python3.9/site-packages/wandb/sdk/interface/interface_shared.py", line 38, in _publish_output_raw
    self._publish(rec)
  File "/Users/juliankleutgens/opt/anaconda3/envs/tgdp/lib/python3.9/site-packages/wandb/sdk/interface/interface_sock.py", line 39, in _publish
    self._sock_client.send_record_publish(record)
  File "/Users/juliankleutgens/opt/anaconda3/envs/tgdp/lib/python3.9/site-packages/wandb/sdk/lib/sock_client.py", line 174, in send_record_publish
    self.send_server_request(server_req)
  File "/Users/juliankleutgens/opt/anaconda3/envs/tgdp/lib/python3.9/site-packages/wandb/sdk/lib/sock_client.py", line 154, in send_server_request
    self._send_message(msg)
  File "/Users/juliankleutgens/opt/anaconda3/envs/tgdp/lib/python3.9/site-packages/wandb/sdk/lib/sock_client.py", line 151, in _send_message
    self._sendall_with_error_handle(header + data)
  File "/Users/juliankleutgens/opt/anaconda3/envs/tgdp/lib/python3.9/site-packages/wandb/sdk/lib/sock_client.py", line 130, in _sendall_with_error_handle
    sent = self._sock.send(data)
BrokenPipeError: [Errno 32] Broken pipe
2025-05-27 10:58:08,388 ERROR   MainThread:63695 [redirect.py:_on_write():664] [no run ID] error in stderr callback
Traceback (most recent call last):
  File "/Users/juliankleutgens/PycharmProjects/ratio_estimation_synthetic/main2.py", line 463, in <module>
    if __name__ == "__main__":
  File "/Users/juliankleutgens/PycharmProjects/ratio_estimation_synthetic/main2.py", line 210, in main
    if not config.skip_ratio_estimator_on_clean_data or not config.unguided_sampling:
  File "/Users/juliankleutgens/PycharmProjects/ratio_estimation_synthetic/training.py", line 111, in train_domain_classifier
    optimizer.step()
  File "/Users/juliankleutgens/opt/anaconda3/envs/tgdp/lib/python3.9/site-packages/torch/optim/optimizer.py", line 487, in wrapper
    out = func(*args, **kwargs)
  File "/Users/juliankleutgens/opt/anaconda3/envs/tgdp/lib/python3.9/site-packages/torch/optim/optimizer.py", line 91, in _use_grad
    ret = func(self, *args, **kwargs)
  File "/Users/juliankleutgens/opt/anaconda3/envs/tgdp/lib/python3.9/site-packages/torch/optim/adam.py", line 223, in step
    adam(
  File "/Users/juliankleutgens/opt/anaconda3/envs/tgdp/lib/python3.9/site-packages/torch/optim/optimizer.py", line 154, in maybe_fallback
    return func(*args, **kwargs)
  File "/Users/juliankleutgens/opt/anaconda3/envs/tgdp/lib/python3.9/site-packages/torch/optim/adam.py", line 784, in adam
    func(
  File "/Users/juliankleutgens/opt/anaconda3/envs/tgdp/lib/python3.9/site-packages/torch/optim/adam.py", line 381, in _single_tensor_adam
    if capturable or differentiable:
  File "/Users/juliankleutgens/opt/anaconda3/envs/tgdp/lib/python3.9/site-packages/torch/optim/adam.py", line 381, in _single_tensor_adam
    if capturable or differentiable:
  File "/Applications/PyCharm.app/Contents/plugins/python/helpers/pydev/_pydevd_bundle/pydevd_trace_dispatch.py", line 89, in trace_dispatch
    def trace_dispatch(py_db, frame, event, arg):
  File "_pydevd_bundle/pydevd_cython_darwin_39_64.pyx", line 1337, in _pydevd_bundle.pydevd_cython_darwin_39_64.trace_dispatch
  File "_pydevd_bundle/pydevd_cython_darwin_39_64.pyx", line 1597, in _pydevd_bundle.pydevd_cython_darwin_39_64.ThreadTracer.__call__
  File "_pydevd_bundle/pydevd_cython_darwin_39_64.pyx", line 937, in _pydevd_bundle.pydevd_cython_darwin_39_64.PyDBFrame.trace_dispatch
  File "_pydevd_bundle/pydevd_cython_darwin_39_64.pyx", line 928, in _pydevd_bundle.pydevd_cython_darwin_39_64.PyDBFrame.trace_dispatch
  File "_pydevd_bundle/pydevd_cython_darwin_39_64.pyx", line 585, in _pydevd_bundle.pydevd_cython_darwin_39_64.PyDBFrame.do_wait_suspend
  File "/Applications/PyCharm.app/Contents/plugins/python/helpers/pydev/pydevd.py", line 1185, in do_wait_suspend
    self._do_wait_suspend(thread, frame, event, arg, suspend_type, from_this_thread)
  File "/Applications/PyCharm.app/Contents/plugins/python/helpers/pydev/pydevd.py", line 1200, in _do_wait_suspend
    time.sleep(0.01)
KeyboardInterrupt

During handling of the above exception, another exception occurred:

Traceback (most recent call last):
  File "/Users/juliankleutgens/opt/anaconda3/envs/tgdp/lib/python3.9/site-packages/wandb/sdk/lib/redirect.py", line 662, in _on_write
    cb(written_data)
  File "/Users/juliankleutgens/opt/anaconda3/envs/tgdp/lib/python3.9/site-packages/wandb/sdk/wandb_run.py", line 2500, in <lambda>
    lambda data: self._console_raw_callback("stderr", data),
  File "/Users/juliankleutgens/opt/anaconda3/envs/tgdp/lib/python3.9/site-packages/wandb/sdk/wandb_run.py", line 406, in wrapper
    return func(self, *args, **kwargs)
  File "/Users/juliankleutgens/opt/anaconda3/envs/tgdp/lib/python3.9/site-packages/wandb/sdk/wandb_run.py", line 464, in wrapper_fn
    return func(self, *args, **kwargs)
  File "/Users/juliankleutgens/opt/anaconda3/envs/tgdp/lib/python3.9/site-packages/wandb/sdk/wandb_run.py", line 1639, in _console_raw_callback
    self._backend.interface.publish_output_raw(name, data)
  File "/Users/juliankleutgens/opt/anaconda3/envs/tgdp/lib/python3.9/site-packages/wandb/sdk/interface/interface.py", line 762, in publish_output_raw
    self._publish_output_raw(o)
  File "/Users/juliankleutgens/opt/anaconda3/envs/tgdp/lib/python3.9/site-packages/wandb/sdk/interface/interface_shared.py", line 38, in _publish_output_raw
    self._publish(rec)
  File "/Users/juliankleutgens/opt/anaconda3/envs/tgdp/lib/python3.9/site-packages/wandb/sdk/interface/interface_sock.py", line 39, in _publish
    self._sock_client.send_record_publish(record)
  File "/Users/juliankleutgens/opt/anaconda3/envs/tgdp/lib/python3.9/site-packages/wandb/sdk/lib/sock_client.py", line 174, in send_record_publish
    self.send_server_request(server_req)
  File "/Users/juliankleutgens/opt/anaconda3/envs/tgdp/lib/python3.9/site-packages/wandb/sdk/lib/sock_client.py", line 154, in send_server_request
    self._send_message(msg)
  File "/Users/juliankleutgens/opt/anaconda3/envs/tgdp/lib/python3.9/site-packages/wandb/sdk/lib/sock_client.py", line 151, in _send_message
    self._sendall_with_error_handle(header + data)
  File "/Users/juliankleutgens/opt/anaconda3/envs/tgdp/lib/python3.9/site-packages/wandb/sdk/lib/sock_client.py", line 130, in _sendall_with_error_handle
    sent = self._sock.send(data)
BrokenPipeError: [Errno 32] Broken pipe
2025-05-27 10:58:08,388 ERROR   MainThread:63695 [redirect.py:_on_write():664] [no run ID] error in stderr callback
Traceback (most recent call last):
  File "/Users/juliankleutgens/PycharmProjects/ratio_estimation_synthetic/main2.py", line 463, in <module>
    if __name__ == "__main__":
  File "/Users/juliankleutgens/PycharmProjects/ratio_estimation_synthetic/main2.py", line 210, in main
    if not config.skip_ratio_estimator_on_clean_data or not config.unguided_sampling:
  File "/Users/juliankleutgens/PycharmProjects/ratio_estimation_synthetic/training.py", line 111, in train_domain_classifier
    optimizer.step()
  File "/Users/juliankleutgens/opt/anaconda3/envs/tgdp/lib/python3.9/site-packages/torch/optim/optimizer.py", line 487, in wrapper
    out = func(*args, **kwargs)
  File "/Users/juliankleutgens/opt/anaconda3/envs/tgdp/lib/python3.9/site-packages/torch/optim/optimizer.py", line 91, in _use_grad
    ret = func(self, *args, **kwargs)
  File "/Users/juliankleutgens/opt/anaconda3/envs/tgdp/lib/python3.9/site-packages/torch/optim/adam.py", line 223, in step
    adam(
  File "/Users/juliankleutgens/opt/anaconda3/envs/tgdp/lib/python3.9/site-packages/torch/optim/optimizer.py", line 154, in maybe_fallback
    return func(*args, **kwargs)
  File "/Users/juliankleutgens/opt/anaconda3/envs/tgdp/lib/python3.9/site-packages/torch/optim/adam.py", line 784, in adam
    func(
  File "/Users/juliankleutgens/opt/anaconda3/envs/tgdp/lib/python3.9/site-packages/torch/optim/adam.py", line 381, in _single_tensor_adam
    if capturable or differentiable:
  File "/Users/juliankleutgens/opt/anaconda3/envs/tgdp/lib/python3.9/site-packages/torch/optim/adam.py", line 381, in _single_tensor_adam
    if capturable or differentiable:
  File "/Applications/PyCharm.app/Contents/plugins/python/helpers/pydev/_pydevd_bundle/pydevd_trace_dispatch.py", line 89, in trace_dispatch
    def trace_dispatch(py_db, frame, event, arg):
  File "_pydevd_bundle/pydevd_cython_darwin_39_64.pyx", line 1337, in _pydevd_bundle.pydevd_cython_darwin_39_64.trace_dispatch
  File "_pydevd_bundle/pydevd_cython_darwin_39_64.pyx", line 1597, in _pydevd_bundle.pydevd_cython_darwin_39_64.ThreadTracer.__call__
  File "_pydevd_bundle/pydevd_cython_darwin_39_64.pyx", line 937, in _pydevd_bundle.pydevd_cython_darwin_39_64.PyDBFrame.trace_dispatch
  File "_pydevd_bundle/pydevd_cython_darwin_39_64.pyx", line 928, in _pydevd_bundle.pydevd_cython_darwin_39_64.PyDBFrame.trace_dispatch
  File "_pydevd_bundle/pydevd_cython_darwin_39_64.pyx", line 585, in _pydevd_bundle.pydevd_cython_darwin_39_64.PyDBFrame.do_wait_suspend
  File "/Applications/PyCharm.app/Contents/plugins/python/helpers/pydev/pydevd.py", line 1185, in do_wait_suspend
    self._do_wait_suspend(thread, frame, event, arg, suspend_type, from_this_thread)
  File "/Applications/PyCharm.app/Contents/plugins/python/helpers/pydev/pydevd.py", line 1200, in _do_wait_suspend
    time.sleep(0.01)
KeyboardInterrupt

During handling of the above exception, another exception occurred:

Traceback (most recent call last):
  File "/Users/juliankleutgens/opt/anaconda3/envs/tgdp/lib/python3.9/site-packages/wandb/sdk/lib/redirect.py", line 662, in _on_write
    cb(written_data)
  File "/Users/juliankleutgens/opt/anaconda3/envs/tgdp/lib/python3.9/site-packages/wandb/sdk/wandb_run.py", line 2500, in <lambda>
    lambda data: self._console_raw_callback("stderr", data),
  File "/Users/juliankleutgens/opt/anaconda3/envs/tgdp/lib/python3.9/site-packages/wandb/sdk/wandb_run.py", line 406, in wrapper
    return func(self, *args, **kwargs)
  File "/Users/juliankleutgens/opt/anaconda3/envs/tgdp/lib/python3.9/site-packages/wandb/sdk/wandb_run.py", line 464, in wrapper_fn
    return func(self, *args, **kwargs)
  File "/Users/juliankleutgens/opt/anaconda3/envs/tgdp/lib/python3.9/site-packages/wandb/sdk/wandb_run.py", line 1639, in _console_raw_callback
    self._backend.interface.publish_output_raw(name, data)
  File "/Users/juliankleutgens/opt/anaconda3/envs/tgdp/lib/python3.9/site-packages/wandb/sdk/interface/interface.py", line 762, in publish_output_raw
    self._publish_output_raw(o)
  File "/Users/juliankleutgens/opt/anaconda3/envs/tgdp/lib/python3.9/site-packages/wandb/sdk/interface/interface_shared.py", line 38, in _publish_output_raw
    self._publish(rec)
  File "/Users/juliankleutgens/opt/anaconda3/envs/tgdp/lib/python3.9/site-packages/wandb/sdk/interface/interface_sock.py", line 39, in _publish
    self._sock_client.send_record_publish(record)
  File "/Users/juliankleutgens/opt/anaconda3/envs/tgdp/lib/python3.9/site-packages/wandb/sdk/lib/sock_client.py", line 174, in send_record_publish
    self.send_server_request(server_req)
  File "/Users/juliankleutgens/opt/anaconda3/envs/tgdp/lib/python3.9/site-packages/wandb/sdk/lib/sock_client.py", line 154, in send_server_request
    self._send_message(msg)
  File "/Users/juliankleutgens/opt/anaconda3/envs/tgdp/lib/python3.9/site-packages/wandb/sdk/lib/sock_client.py", line 151, in _send_message
    self._sendall_with_error_handle(header + data)
  File "/Users/juliankleutgens/opt/anaconda3/envs/tgdp/lib/python3.9/site-packages/wandb/sdk/lib/sock_client.py", line 130, in _sendall_with_error_handle
    sent = self._sock.send(data)
BrokenPipeError: [Errno 32] Broken pipe
2025-05-27 10:58:08,388 ERROR   MainThread:63695 [redirect.py:_on_write():664] [no run ID] error in stderr callback
Traceback (most recent call last):
  File "/Users/juliankleutgens/PycharmProjects/ratio_estimation_synthetic/main2.py", line 463, in <module>
    if __name__ == "__main__":
  File "/Users/juliankleutgens/PycharmProjects/ratio_estimation_synthetic/main2.py", line 210, in main
    if not config.skip_ratio_estimator_on_clean_data or not config.unguided_sampling:
  File "/Users/juliankleutgens/PycharmProjects/ratio_estimation_synthetic/training.py", line 111, in train_domain_classifier
    optimizer.step()
  File "/Users/juliankleutgens/opt/anaconda3/envs/tgdp/lib/python3.9/site-packages/torch/optim/optimizer.py", line 487, in wrapper
    out = func(*args, **kwargs)
  File "/Users/juliankleutgens/opt/anaconda3/envs/tgdp/lib/python3.9/site-packages/torch/optim/optimizer.py", line 91, in _use_grad
    ret = func(self, *args, **kwargs)
  File "/Users/juliankleutgens/opt/anaconda3/envs/tgdp/lib/python3.9/site-packages/torch/optim/adam.py", line 223, in step
    adam(
  File "/Users/juliankleutgens/opt/anaconda3/envs/tgdp/lib/python3.9/site-packages/torch/optim/optimizer.py", line 154, in maybe_fallback
    return func(*args, **kwargs)
  File "/Users/juliankleutgens/opt/anaconda3/envs/tgdp/lib/python3.9/site-packages/torch/optim/adam.py", line 784, in adam
    func(
  File "/Users/juliankleutgens/opt/anaconda3/envs/tgdp/lib/python3.9/site-packages/torch/optim/adam.py", line 381, in _single_tensor_adam
    if capturable or differentiable:
  File "/Users/juliankleutgens/opt/anaconda3/envs/tgdp/lib/python3.9/site-packages/torch/optim/adam.py", line 381, in _single_tensor_adam
    if capturable or differentiable:
  File "/Applications/PyCharm.app/Contents/plugins/python/helpers/pydev/_pydevd_bundle/pydevd_trace_dispatch.py", line 89, in trace_dispatch
    def trace_dispatch(py_db, frame, event, arg):
  File "_pydevd_bundle/pydevd_cython_darwin_39_64.pyx", line 1337, in _pydevd_bundle.pydevd_cython_darwin_39_64.trace_dispatch
  File "_pydevd_bundle/pydevd_cython_darwin_39_64.pyx", line 1597, in _pydevd_bundle.pydevd_cython_darwin_39_64.ThreadTracer.__call__
  File "_pydevd_bundle/pydevd_cython_darwin_39_64.pyx", line 937, in _pydevd_bundle.pydevd_cython_darwin_39_64.PyDBFrame.trace_dispatch
  File "_pydevd_bundle/pydevd_cython_darwin_39_64.pyx", line 928, in _pydevd_bundle.pydevd_cython_darwin_39_64.PyDBFrame.trace_dispatch
  File "_pydevd_bundle/pydevd_cython_darwin_39_64.pyx", line 585, in _pydevd_bundle.pydevd_cython_darwin_39_64.PyDBFrame.do_wait_suspend
  File "/Applications/PyCharm.app/Contents/plugins/python/helpers/pydev/pydevd.py", line 1185, in do_wait_suspend
    self._do_wait_suspend(thread, frame, event, arg, suspend_type, from_this_thread)
  File "/Applications/PyCharm.app/Contents/plugins/python/helpers/pydev/pydevd.py", line 1200, in _do_wait_suspend
    time.sleep(0.01)
KeyboardInterrupt

During handling of the above exception, another exception occurred:

Traceback (most recent call last):
  File "/Users/juliankleutgens/opt/anaconda3/envs/tgdp/lib/python3.9/site-packages/wandb/sdk/lib/redirect.py", line 662, in _on_write
    cb(written_data)
  File "/Users/juliankleutgens/opt/anaconda3/envs/tgdp/lib/python3.9/site-packages/wandb/sdk/wandb_run.py", line 2500, in <lambda>
    lambda data: self._console_raw_callback("stderr", data),
  File "/Users/juliankleutgens/opt/anaconda3/envs/tgdp/lib/python3.9/site-packages/wandb/sdk/wandb_run.py", line 406, in wrapper
    return func(self, *args, **kwargs)
  File "/Users/juliankleutgens/opt/anaconda3/envs/tgdp/lib/python3.9/site-packages/wandb/sdk/wandb_run.py", line 464, in wrapper_fn
    return func(self, *args, **kwargs)
  File "/Users/juliankleutgens/opt/anaconda3/envs/tgdp/lib/python3.9/site-packages/wandb/sdk/wandb_run.py", line 1639, in _console_raw_callback
    self._backend.interface.publish_output_raw(name, data)
  File "/Users/juliankleutgens/opt/anaconda3/envs/tgdp/lib/python3.9/site-packages/wandb/sdk/interface/interface.py", line 762, in publish_output_raw
    self._publish_output_raw(o)
  File "/Users/juliankleutgens/opt/anaconda3/envs/tgdp/lib/python3.9/site-packages/wandb/sdk/interface/interface_shared.py", line 38, in _publish_output_raw
    self._publish(rec)
  File "/Users/juliankleutgens/opt/anaconda3/envs/tgdp/lib/python3.9/site-packages/wandb/sdk/interface/interface_sock.py", line 39, in _publish
    self._sock_client.send_record_publish(record)
  File "/Users/juliankleutgens/opt/anaconda3/envs/tgdp/lib/python3.9/site-packages/wandb/sdk/lib/sock_client.py", line 174, in send_record_publish
    self.send_server_request(server_req)
  File "/Users/juliankleutgens/opt/anaconda3/envs/tgdp/lib/python3.9/site-packages/wandb/sdk/lib/sock_client.py", line 154, in send_server_request
    self._send_message(msg)
  File "/Users/juliankleutgens/opt/anaconda3/envs/tgdp/lib/python3.9/site-packages/wandb/sdk/lib/sock_client.py", line 151, in _send_message
    self._sendall_with_error_handle(header + data)
  File "/Users/juliankleutgens/opt/anaconda3/envs/tgdp/lib/python3.9/site-packages/wandb/sdk/lib/sock_client.py", line 130, in _sendall_with_error_handle
    sent = self._sock.send(data)
BrokenPipeError: [Errno 32] Broken pipe
